INFO 2025-07-21 15:56:48,730 autoreload 667 Watching for file changes with StatReloader
INFO 2025-07-21 15:58:38,955 autoreload 667 Watching for file changes with StatReloader
INFO 2025-07-21 15:59:24,531 autoreload 265 C:\Users\∞„∞„Àß\Desktop\mall\mall\apps\users\urls.py changed, reloading.
INFO 2025-07-21 16:00:28,330 autoreload 667 Watching for file changes with StatReloader
INFO 2025-07-21 16:02:33,236 autoreload 265 C:\Users\∞„∞„Àß\Desktop\mall\mall\mall\settings.py changed, reloading.
INFO 2025-07-21 16:02:34,554 autoreload 667 Watching for file changes with StatReloader
INFO 2025-07-21 16:03:55,041 autoreload 265 C:\Users\∞„∞„Àß\Desktop\mall\mall\mall\settings.py changed, reloading.
INFO 2025-07-21 16:03:56,200 autoreload 667 Watching for file changes with StatReloader
INFO 2025-07-21 16:04:01,355 autoreload 667 Watching for file changes with StatReloader
INFO 2025-07-21 16:06:16,311 autoreload 667 Watching for file changes with StatReloader
INFO 2025-07-21 16:18:28,306 autoreload 667 Watching for file changes with StatReloader
INFO 2025-07-21 16:45:40,096 autoreload 667 Watching for file changes with StatReloader
ERROR 2025-07-21 16:50:50,412 log 246 Internal Server Error: /user/register
Traceback (most recent call last):
  File "C:\Users\∞„∞„Àß\Desktop\mall\.venv\lib\site-packages\django\core\handlers\exception.py", line 55, in inner
    response = get_response(request)
  File "C:\Users\∞„∞„Àß\Desktop\mall\.venv\lib\site-packages\django\utils\deprecation.py", line 136, in __call__
    response = self.process_response(request, response)
  File "C:\Users\∞„∞„Àß\Desktop\mall\.venv\lib\site-packages\django\middleware\common.py", line 108, in process_response
    return self.response_redirect_class(self.get_full_path_with_slash(request))
  File "C:\Users\∞„∞„Àß\Desktop\mall\.venv\lib\site-packages\django\middleware\common.py", line 87, in get_full_path_with_slash
    raise RuntimeError(
RuntimeError: You called this URL via POST, but the URL doesn't end in a slash and you have APPEND_SLASH set. Django can't redirect to the slash URL while maintaining POST data. Change your form to point to 127.0.0.1:8000/user/register/ (note the trailing slash), or set APPEND_SLASH=False in your Django settings.
ERROR 2025-07-21 16:50:50,426 basehttp 212 "POST /user/register HTTP/1.1" 500 70706
WARNING 2025-07-21 16:52:20,562 log 246 Forbidden (CSRF cookie not set.): /user/register/
WARNING 2025-07-21 16:52:20,564 basehttp 212 "POST /user/register/ HTTP/1.1" 403 2870
INFO 2025-07-21 16:53:58,384 autoreload 265 C:\Users\∞„∞„Àß\Desktop\mall\mall\mall\settings.py changed, reloading.
INFO 2025-07-21 16:54:02,507 autoreload 667 Watching for file changes with StatReloader
ERROR 2025-07-21 16:54:06,467 log 246 Internal Server Error: /user/register/
Traceback (most recent call last):
  File "C:\Users\∞„∞„Àß\Desktop\mall\.venv\lib\site-packages\django\db\backends\utils.py", line 89, in _execute
    return self.cursor.execute(sql, params)
  File "C:\Users\∞„∞„Àß\Desktop\mall\.venv\lib\site-packages\django\db\backends\mysql\base.py", line 75, in execute
    return self.cursor.execute(query, args)
  File "C:\Users\∞„∞„Àß\Desktop\mall\.venv\lib\site-packages\MySQLdb\cursors.py", line 179, in execute
    res = self._query(mogrified_query)
  File "C:\Users\∞„∞„Àß\Desktop\mall\.venv\lib\site-packages\MySQLdb\cursors.py", line 330, in _query
    db.query(q)
  File "C:\Users\∞„∞„Àß\Desktop\mall\.venv\lib\site-packages\MySQLdb\connections.py", line 280, in query
    _mysql.connection.query(self, query)
MySQLdb.ProgrammingError: (1146, "Table 'django.tb_users' doesn't exist")

The above exception was the direct cause of the following exception:

Traceback (most recent call last):
  File "C:\Users\∞„∞„Àß\Desktop\mall\.venv\lib\site-packages\django\core\handlers\exception.py", line 55, in inner
    response = get_response(request)
  File "C:\Users\∞„∞„Àß\Desktop\mall\.venv\lib\site-packages\django\core\handlers\base.py", line 197, in _get_response
    response = wrapped_callback(request, *callback_args, **callback_kwargs)
  File "C:\Users\∞„∞„Àß\Desktop\mall\.venv\lib\site-packages\django\views\generic\base.py", line 105, in view
    return self.dispatch(request, *args, **kwargs)
  File "C:\Users\∞„∞„Àß\Desktop\mall\.venv\lib\site-packages\django\views\generic\base.py", line 144, in dispatch
    return handler(request, *args, **kwargs)
  File "C:\Users\∞„∞„Àß\Desktop\mall\mall\apps\users\views.py", line 35, in post
    user = User.objects.get(username=username)
  File "C:\Users\∞„∞„Àß\Desktop\mall\.venv\lib\site-packages\django\db\models\manager.py", line 87, in manager_method
    return getattr(self.get_queryset(), name)(*args, **kwargs)
  File "C:\Users\∞„∞„Àß\Desktop\mall\.venv\lib\site-packages\django\db\models\query.py", line 633, in get
    num = len(clone)
  File "C:\Users\∞„∞„Àß\Desktop\mall\.venv\lib\site-packages\django\db\models\query.py", line 380, in __len__
    self._fetch_all()
  File "C:\Users\∞„∞„Àß\Desktop\mall\.venv\lib\site-packages\django\db\models\query.py", line 1881, in _fetch_all
    self._result_cache = list(self._iterable_class(self))
  File "C:\Users\∞„∞„Àß\Desktop\mall\.venv\lib\site-packages\django\db\models\query.py", line 91, in __iter__
    results = compiler.execute_sql(
  File "C:\Users\∞„∞„Àß\Desktop\mall\.venv\lib\site-packages\django\db\models\sql\compiler.py", line 1562, in execute_sql
    cursor.execute(sql, params)
  File "C:\Users\∞„∞„Àß\Desktop\mall\.venv\lib\site-packages\django\db\backends\utils.py", line 102, in execute
    return super().execute(sql, params)
  File "C:\Users\∞„∞„Àß\Desktop\mall\.venv\lib\site-packages\django\db\backends\utils.py", line 67, in execute
    return self._execute_with_wrappers(
  File "C:\Users\∞„∞„Àß\Desktop\mall\.venv\lib\site-packages\django\db\backends\utils.py", line 80, in _execute_with_wrappers
    return executor(sql, params, many, context)
  File "C:\Users\∞„∞„Àß\Desktop\mall\.venv\lib\site-packages\django\db\backends\utils.py", line 89, in _execute
    return self.cursor.execute(sql, params)
  File "C:\Users\∞„∞„Àß\Desktop\mall\.venv\lib\site-packages\django\db\utils.py", line 91, in __exit__
    raise dj_exc_value.with_traceback(traceback) from exc_value
  File "C:\Users\∞„∞„Àß\Desktop\mall\.venv\lib\site-packages\django\db\backends\utils.py", line 89, in _execute
    return self.cursor.execute(sql, params)
  File "C:\Users\∞„∞„Àß\Desktop\mall\.venv\lib\site-packages\django\db\backends\mysql\base.py", line 75, in execute
    return self.cursor.execute(query, args)
  File "C:\Users\∞„∞„Àß\Desktop\mall\.venv\lib\site-packages\MySQLdb\cursors.py", line 179, in execute
    res = self._query(mogrified_query)
  File "C:\Users\∞„∞„Àß\Desktop\mall\.venv\lib\site-packages\MySQLdb\cursors.py", line 330, in _query
    db.query(q)
  File "C:\Users\∞„∞„Àß\Desktop\mall\.venv\lib\site-packages\MySQLdb\connections.py", line 280, in query
    _mysql.connection.query(self, query)
django.db.utils.ProgrammingError: (1146, "Table 'django.tb_users' doesn't exist")
ERROR 2025-07-21 16:54:06,479 basehttp 212 "POST /user/register/ HTTP/1.1" 500 172094
INFO 2025-07-21 17:05:42,229 autoreload 667 Watching for file changes with StatReloader
ERROR 2025-07-21 17:05:49,431 log 246 Internal Server Error: /user/register/
Traceback (most recent call last):
  File "C:\Users\∞„∞„Àß\Desktop\mall\.venv\lib\site-packages\django\core\handlers\exception.py", line 55, in inner
    response = get_response(request)
  File "C:\Users\∞„∞„Àß\Desktop\mall\.venv\lib\site-packages\django\core\handlers\base.py", line 197, in _get_response
    response = wrapped_callback(request, *callback_args, **callback_kwargs)
  File "C:\Users\∞„∞„Àß\Desktop\mall\.venv\lib\site-packages\django\views\generic\base.py", line 105, in view
    return self.dispatch(request, *args, **kwargs)
  File "C:\Users\∞„∞„Àß\Desktop\mall\.venv\lib\site-packages\django\views\generic\base.py", line 144, in dispatch
    return handler(request, *args, **kwargs)
  File "C:\Users\∞„∞„Àß\Desktop\mall\mall\apps\users\views.py", line 35, in post
    user = User.objects.get(username=username)
  File "C:\Users\∞„∞„Àß\Desktop\mall\.venv\lib\site-packages\django\db\models\manager.py", line 87, in manager_method
    return getattr(self.get_queryset(), name)(*args, **kwargs)
  File "C:\Users\∞„∞„Àß\Desktop\mall\.venv\lib\site-packages\django\db\models\query.py", line 637, in get
    raise self.model.DoesNotExist(
apps.users.models.User.DoesNotExist: User matching query does not exist.
ERROR 2025-07-21 17:05:49,437 basehttp 212 "POST /user/register/ HTTP/1.1" 500 85337
INFO 2025-07-21 17:06:52,493 autoreload 265 C:\Users\∞„∞„Àß\Desktop\mall\mall\apps\users\views.py changed, reloading.
INFO 2025-07-21 17:06:53,393 autoreload 667 Watching for file changes with StatReloader
ERROR 2025-07-21 17:06:58,376 log 246 Internal Server Error: /user/register/
Traceback (most recent call last):
  File "C:\Users\∞„∞„Àß\Desktop\mall\mall\apps\users\views.py", line 40, in post
    User.objects.create_user(username=username, password=password, mobile=mobile, sms_code=sms_code)
  File "C:\Users\∞„∞„Àß\Desktop\mall\.venv\lib\site-packages\django\contrib\auth\models.py", line 161, in create_user
    return self._create_user(username, email, password, **extra_fields)
  File "C:\Users\∞„∞„Àß\Desktop\mall\.venv\lib\site-packages\django\contrib\auth\models.py", line 153, in _create_user
    user = self.model(username=username, email=email, **extra_fields)
  File "C:\Users\∞„∞„Àß\Desktop\mall\.venv\lib\site-packages\django\db\models\base.py", line 567, in __init__
    raise TypeError(
TypeError: User() got unexpected keyword arguments: 'sms_code'

During handling of the above exception, another exception occurred:

Traceback (most recent call last):
  File "C:\Users\∞„∞„Àß\Desktop\mall\.venv\lib\site-packages\django\core\handlers\exception.py", line 55, in inner
    response = get_response(request)
  File "C:\Users\∞„∞„Àß\Desktop\mall\.venv\lib\site-packages\django\core\handlers\base.py", line 197, in _get_response
    response = wrapped_callback(request, *callback_args, **callback_kwargs)
  File "C:\Users\∞„∞„Àß\Desktop\mall\.venv\lib\site-packages\django\views\generic\base.py", line 105, in view
    return self.dispatch(request, *args, **kwargs)
  File "C:\Users\∞„∞„Àß\Desktop\mall\.venv\lib\site-packages\django\views\generic\base.py", line 144, in dispatch
    return handler(request, *args, **kwargs)
  File "C:\Users\∞„∞„Àß\Desktop\mall\mall\apps\users\views.py", line 42, in post
    return JsonResponse({'code':400, 'errmsg':e})
  File "C:\Users\∞„∞„Àß\Desktop\mall\.venv\lib\site-packages\django\http\response.py", line 731, in __init__
    data = json.dumps(data, cls=encoder, **json_dumps_params)
  File "C:\Users\∞„∞„Àß\AppData\Local\Programs\Python\Python39\lib\json\__init__.py", line 234, in dumps
    return cls(
  File "C:\Users\∞„∞„Àß\AppData\Local\Programs\Python\Python39\lib\json\encoder.py", line 199, in encode
    chunks = self.iterencode(o, _one_shot=True)
  File "C:\Users\∞„∞„Àß\AppData\Local\Programs\Python\Python39\lib\json\encoder.py", line 257, in iterencode
    return _iterencode(o, 0)
  File "C:\Users\∞„∞„Àß\Desktop\mall\.venv\lib\site-packages\django\core\serializers\json.py", line 106, in default
    return super().default(o)
  File "C:\Users\∞„∞„Àß\AppData\Local\Programs\Python\Python39\lib\json\encoder.py", line 179, in default
    raise TypeError(f'Object of type {o.__class__.__name__} '
TypeError: Object of type TypeError is not JSON serializable
ERROR 2025-07-21 17:06:58,388 basehttp 212 "POST /user/register/ HTTP/1.1" 500 124683
INFO 2025-07-21 17:07:58,335 autoreload 265 C:\Users\∞„∞„Àß\Desktop\mall\mall\apps\users\views.py changed, reloading.
INFO 2025-07-21 17:07:59,122 autoreload 667 Watching for file changes with StatReloader
INFO 2025-07-21 17:08:02,733 basehttp 212 "POST /user/register/ HTTP/1.1" 200 78
INFO 2025-07-21 17:10:48,959 autoreload 265 C:\Users\∞„∞„Àß\Desktop\mall\mall\apps\users\views.py changed, reloading.
INFO 2025-07-21 17:10:50,035 autoreload 667 Watching for file changes with StatReloader
INFO 2025-07-21 17:11:00,155 basehttp 212 "POST /user/register/ HTTP/1.1" 200 27
INFO 2025-07-21 17:19:03,847 autoreload 265 C:\Users\∞„∞„Àß\Desktop\mall\mall\apps\users\views.py changed, reloading.
INFO 2025-07-21 17:19:05,042 autoreload 667 Watching for file changes with StatReloader
INFO 2025-07-21 17:23:29,479 autoreload 265 C:\Users\∞„∞„Àß\Desktop\mall\mall\apps\users\views.py changed, reloading.
INFO 2025-07-21 17:23:30,924 autoreload 667 Watching for file changes with StatReloader
INFO 2025-07-21 17:32:21,039 autoreload 265 C:\Users\∞„∞„Àß\Desktop\mall\mall\mall\settings.py changed, reloading.
INFO 2025-07-21 17:32:22,174 autoreload 667 Watching for file changes with StatReloader
INFO 2025-07-21 18:03:56,093 autoreload 265 C:\Users\∞„∞„Àß\Desktop\mall\mall\mall\settings.py changed, reloading.
INFO 2025-07-21 18:04:03,134 autoreload 667 Watching for file changes with StatReloader
INFO 2025-08-05 18:37:51,210 autoreload 667 Watching for file changes with StatReloader
INFO 2025-08-05 18:45:02,793 autoreload 667 Watching for file changes with StatReloader
INFO 2025-08-05 18:47:02,572 autoreload 265 C:\Users\∞„∞„Àß\Desktop\mall\mall\mall\urls.py changed, reloading.
INFO 2025-08-05 18:47:05,276 autoreload 667 Watching for file changes with StatReloader
INFO 2025-08-05 18:51:59,527 autoreload 667 Watching for file changes with StatReloader
INFO 2025-08-05 18:53:02,962 basehttp 212 "POST /user/register/ HTTP/1.1" 200 57
WARNING 2025-08-05 18:53:20,898 log 246 Not Found: /user/register/verification/image/1223
WARNING 2025-08-05 18:53:20,901 basehttp 212 "GET /user/register/verification/image/1223 HTTP/1.1" 404 2477
WARNING 2025-08-05 18:53:32,484 log 246 Not Found: /verification/image/1223
WARNING 2025-08-05 18:53:32,489 basehttp 212 "GET /verification/image/1223 HTTP/1.1" 404 2452
INFO 2025-08-05 18:58:41,988 autoreload 667 Watching for file changes with StatReloader
WARNING 2025-08-05 18:59:22,270 log 246 Not Found: /verification/image/1223
WARNING 2025-08-05 18:59:22,281 basehttp 212 "GET /verification/image/1223 HTTP/1.1" 404 2452
INFO 2025-08-05 19:03:43,441 autoreload 265 C:\Users\∞„∞„Àß\Desktop\mall\mall\apps\verifications\urls.py changed, reloading.
INFO 2025-08-05 19:03:46,396 autoreload 667 Watching for file changes with StatReloader
WARNING 2025-08-05 19:03:51,084 log 246 Not Found: /verification/image/1223
WARNING 2025-08-05 19:03:51,087 basehttp 212 "GET /verification/image/1223 HTTP/1.1" 404 2453
INFO 2025-08-05 19:04:02,129 autoreload 667 Watching for file changes with StatReloader
WARNING 2025-08-05 19:04:10,162 log 246 Not Found: /verification/image/1223
WARNING 2025-08-05 19:04:10,167 basehttp 212 "GET /verification/image/1223 HTTP/1.1" 404 2453
INFO 2025-08-05 19:04:54,511 autoreload 265 C:\Users\∞„∞„Àß\Desktop\mall\mall\apps\verifications\urls.py changed, reloading.
INFO 2025-08-05 19:04:59,789 autoreload 667 Watching for file changes with StatReloader
INFO 2025-08-05 19:05:06,635 basehttp 212 "GET /verification/image/1223 HTTP/1.1" 301 0
ERROR 2025-08-05 19:05:06,780 log 246 Internal Server Error: /verification/image/1223/
Traceback (most recent call last):
  File "C:\Users\∞„∞„Àß\Desktop\mall\.venv\lib\site-packages\django\core\handlers\exception.py", line 55, in inner
    response = get_response(request)
  File "C:\Users\∞„∞„Àß\Desktop\mall\.venv\lib\site-packages\django\core\handlers\base.py", line 197, in _get_response
    response = wrapped_callback(request, *callback_args, **callback_kwargs)
  File "C:\Users\∞„∞„Àß\Desktop\mall\.venv\lib\site-packages\django\views\generic\base.py", line 105, in view
    return self.dispatch(request, *args, **kwargs)
  File "C:\Users\∞„∞„Àß\Desktop\mall\.venv\lib\site-packages\django\views\generic\base.py", line 144, in dispatch
    return handler(request, *args, **kwargs)
  File "C:\Users\∞„∞„Àß\Desktop\mall\mall\apps\verifications\views.py", line 13, in get
    text, image = captcha.generate_captcha()
  File "C:\Users\∞„∞„Àß\Desktop\mall\mall\libs\captcha\captcha.py", line 215, in generate_captcha
    return self.captcha("")
  File "C:\Users\∞„∞„Àß\Desktop\mall\mall\libs\captcha\captcha.py", line 204, in captcha
    image = self.text(image, self.fonts, drawings=['warp', 'rotate', 'offset'])
  File "C:\Users\∞„∞„Àß\Desktop\mall\mall\libs\captcha\captcha.py", line 132, in text
    c_width, c_height = draw.textsize(c, font=font)
AttributeError: 'ImageDraw' object has no attribute 'textsize'
ERROR 2025-08-05 19:05:06,807 basehttp 212 "GET /verification/image/1223/ HTTP/1.1" 500 89310
INFO 2025-08-05 19:05:21,534 autoreload 265 C:\Users\∞„∞„Àß\Desktop\mall\mall\apps\verifications\urls.py changed, reloading.
INFO 2025-08-05 19:05:26,708 autoreload 667 Watching for file changes with StatReloader
INFO 2025-08-05 19:06:17,316 basehttp 212 "GET /verification/image/550e8400-e29b-41d4-a716-446655440000 HTTP/1.1" 301 0
ERROR 2025-08-05 19:06:18,065 log 246 Internal Server Error: /verification/image/550e8400-e29b-41d4-a716-446655440000/
Traceback (most recent call last):
  File "C:\Users\∞„∞„Àß\Desktop\mall\.venv\lib\site-packages\django\core\handlers\exception.py", line 55, in inner
    response = get_response(request)
  File "C:\Users\∞„∞„Àß\Desktop\mall\.venv\lib\site-packages\django\core\handlers\base.py", line 197, in _get_response
    response = wrapped_callback(request, *callback_args, **callback_kwargs)
  File "C:\Users\∞„∞„Àß\Desktop\mall\.venv\lib\site-packages\django\views\generic\base.py", line 105, in view
    return self.dispatch(request, *args, **kwargs)
  File "C:\Users\∞„∞„Àß\Desktop\mall\.venv\lib\site-packages\django\views\generic\base.py", line 144, in dispatch
    return handler(request, *args, **kwargs)
  File "C:\Users\∞„∞„Àß\Desktop\mall\mall\apps\verifications\views.py", line 13, in get
    text, image = captcha.generate_captcha()
  File "C:\Users\∞„∞„Àß\Desktop\mall\mall\libs\captcha\captcha.py", line 215, in generate_captcha
    return self.captcha("")
  File "C:\Users\∞„∞„Àß\Desktop\mall\mall\libs\captcha\captcha.py", line 204, in captcha
    image = self.text(image, self.fonts, drawings=['warp', 'rotate', 'offset'])
  File "C:\Users\∞„∞„Àß\Desktop\mall\mall\libs\captcha\captcha.py", line 132, in text
    c_width, c_height = draw.textsize(c, font=font)
AttributeError: 'ImageDraw' object has no attribute 'textsize'
ERROR 2025-08-05 19:06:18,085 basehttp 212 "GET /verification/image/550e8400-e29b-41d4-a716-446655440000/ HTTP/1.1" 500 89878
INFO 2025-08-05 19:12:33,788 autoreload 265 C:\Users\∞„∞„Àß\Desktop\mall\mall\apps\verifications\views.py changed, reloading.
INFO 2025-08-05 19:12:37,492 autoreload 667 Watching for file changes with StatReloader
INFO 2025-08-05 19:15:00,982 autoreload 265 C:\Users\∞„∞„Àß\Desktop\mall\mall\apps\verifications\views.py changed, reloading.
INFO 2025-08-05 19:15:09,188 autoreload 667 Watching for file changes with StatReloader
INFO 2025-08-05 19:15:13,299 basehttp 212 "GET /verification/image/550e8400-e29b-41d4-a716-446655440000 HTTP/1.1" 301 0
ERROR 2025-08-05 19:15:13,384 log 246 Internal Server Error: /verification/image/550e8400-e29b-41d4-a716-446655440000/
Traceback (most recent call last):
  File "C:\Users\∞„∞„Àß\Desktop\mall\.venv\lib\site-packages\django\core\handlers\exception.py", line 55, in inner
    response = get_response(request)
  File "C:\Users\∞„∞„Àß\Desktop\mall\.venv\lib\site-packages\django\core\handlers\base.py", line 197, in _get_response
    response = wrapped_callback(request, *callback_args, **callback_kwargs)
  File "C:\Users\∞„∞„Àß\Desktop\mall\.venv\lib\site-packages\django\views\generic\base.py", line 105, in view
    return self.dispatch(request, *args, **kwargs)
  File "C:\Users\∞„∞„Àß\Desktop\mall\.venv\lib\site-packages\django\views\generic\base.py", line 144, in dispatch
    return handler(request, *args, **kwargs)
  File "C:\Users\∞„∞„Àß\Desktop\mall\mall\apps\verifications\views.py", line 40, in get
    text, image = self.generate_captcha()
  File "C:\Users\∞„∞„Àß\Desktop\mall\mall\apps\verifications\views.py", line 16, in generate_captcha
    text = ''.join(random.choices('ABCDEFGHJKLMNPQRSTUVWXYZ23456789', k=4))
AttributeError: 'builtin_function_or_method' object has no attribute 'choices'
ERROR 2025-08-05 19:15:13,398 basehttp 212 "GET /verification/image/550e8400-e29b-41d4-a716-446655440000/ HTTP/1.1" 500 79854
INFO 2025-08-05 19:15:27,659 autoreload 667 Watching for file changes with StatReloader
INFO 2025-08-05 19:15:32,431 basehttp 212 "GET /verification/image/550e8400-e29b-41d4-a716-446655440000 HTTP/1.1" 301 0
ERROR 2025-08-05 19:15:32,503 log 246 Internal Server Error: /verification/image/550e8400-e29b-41d4-a716-446655440000/
Traceback (most recent call last):
  File "C:\Users\∞„∞„Àß\Desktop\mall\.venv\lib\site-packages\django\core\handlers\exception.py", line 55, in inner
    response = get_response(request)
  File "C:\Users\∞„∞„Àß\Desktop\mall\.venv\lib\site-packages\django\core\handlers\base.py", line 197, in _get_response
    response = wrapped_callback(request, *callback_args, **callback_kwargs)
  File "C:\Users\∞„∞„Àß\Desktop\mall\.venv\lib\site-packages\django\views\generic\base.py", line 105, in view
    return self.dispatch(request, *args, **kwargs)
  File "C:\Users\∞„∞„Àß\Desktop\mall\.venv\lib\site-packages\django\views\generic\base.py", line 144, in dispatch
    return handler(request, *args, **kwargs)
  File "C:\Users\∞„∞„Àß\Desktop\mall\mall\apps\verifications\views.py", line 40, in get
    text, image = self.generate_captcha()
  File "C:\Users\∞„∞„Àß\Desktop\mall\mall\apps\verifications\views.py", line 16, in generate_captcha
    text = ''.join(random.choices('ABCDEFGHJKLMNPQRSTUVWXYZ23456789', k=4))
AttributeError: 'builtin_function_or_method' object has no attribute 'choices'
ERROR 2025-08-05 19:15:32,512 basehttp 212 "GET /verification/image/550e8400-e29b-41d4-a716-446655440000/ HTTP/1.1" 500 79854
