INFO 2025-08-05 19:34:32,948 autoreload 667 Watching for file changes with StatReloader
INFO 2025-08-05 19:34:59,379 autoreload 265 C:\Users\∞„∞„Àß\Desktop\mall\mall\apps\verifications\views.py changed, reloading.
INFO 2025-08-05 19:35:03,487 autoreload 667 Watching for file changes with StatReloader
ERROR 2025-08-05 19:35:08,663 log 246 Internal Server Error: /verification/image/550e8400-e29b-41d4-a716-446655440000/
Traceback (most recent call last):
  File "C:\Users\∞„∞„Àß\Desktop\mall\.venv\lib\site-packages\redis\connection.py", line 385, in connect_check_health
    sock = self.retry.call_with_retry(
  File "C:\Users\∞„∞„Àß\Desktop\mall\.venv\lib\site-packages\redis\retry.py", line 87, in call_with_retry
    return do()
  File "C:\Users\∞„∞„Àß\Desktop\mall\.venv\lib\site-packages\redis\connection.py", line 386, in <lambda>
    lambda: self._connect(), lambda error: self.disconnect(error)
  File "C:\Users\∞„∞„Àß\Desktop\mall\.venv\lib\site-packages\redis\connection.py", line 797, in _connect
    raise err
  File "C:\Users\∞„∞„Àß\Desktop\mall\.venv\lib\site-packages\redis\connection.py", line 781, in _connect
    sock.connect(socket_address)
ConnectionRefusedError: [WinError 10061] ”…”⁄ƒø±Íº∆À„ª˙ª˝º´æ‹æ¯£¨Œﬁ∑®¡¨Ω”°£

During handling of the above exception, another exception occurred:

Traceback (most recent call last):
  File "C:\Users\∞„∞„Àß\Desktop\mall\.venv\lib\site-packages\django\core\handlers\exception.py", line 55, in inner
    response = get_response(request)
  File "C:\Users\∞„∞„Àß\Desktop\mall\.venv\lib\site-packages\django\core\handlers\base.py", line 197, in _get_response
    response = wrapped_callback(request, *callback_args, **callback_kwargs)
  File "C:\Users\∞„∞„Àß\Desktop\mall\.venv\lib\site-packages\django\views\generic\base.py", line 105, in view
    return self.dispatch(request, *args, **kwargs)
  File "C:\Users\∞„∞„Àß\Desktop\mall\.venv\lib\site-packages\django\views\generic\base.py", line 144, in dispatch
    return handler(request, *args, **kwargs)
  File "C:\Users\∞„∞„Àß\Desktop\mall\mall\apps\verifications\views.py", line 17, in get
    redis_cli.setex(code, 100, text)
  File "C:\Users\∞„∞„Àß\Desktop\mall\.venv\lib\site-packages\redis\commands\core.py", line 2330, in setex
    return self.execute_command("SETEX", name, time, value)
  File "C:\Users\∞„∞„Àß\Desktop\mall\.venv\lib\site-packages\redis\client.py", line 623, in execute_command
    return self._execute_command(*args, **options)
  File "C:\Users\∞„∞„Àß\Desktop\mall\.venv\lib\site-packages\redis\client.py", line 629, in _execute_command
    conn = self.connection or pool.get_connection()
  File "C:\Users\∞„∞„Àß\Desktop\mall\.venv\lib\site-packages\redis\utils.py", line 191, in wrapper
    return func(*args, **kwargs)
  File "C:\Users\∞„∞„Àß\Desktop\mall\.venv\lib\site-packages\redis\connection.py", line 1530, in get_connection
    connection.connect()
  File "C:\Users\∞„∞„Àß\Desktop\mall\.venv\lib\site-packages\redis\connection.py", line 379, in connect
    self.connect_check_health(check_health=True)
  File "C:\Users\∞„∞„Àß\Desktop\mall\.venv\lib\site-packages\redis\connection.py", line 391, in connect_check_health
    raise ConnectionError(self._error_message(e))
redis.exceptions.ConnectionError: Error 10061 connecting to 192.168.31.128:6379. ”…”⁄ƒø±Íº∆À„ª˙ª˝º´æ‹æ¯£¨Œﬁ∑®¡¨Ω”°£.
ERROR 2025-08-05 19:35:08,684 basehttp 212 "GET /verification/image/550e8400-e29b-41d4-a716-446655440000/ HTTP/1.1" 500 134521
ERROR 2025-08-05 19:37:14,689 log 246 Internal Server Error: /verification/image/550e8400-e29b-41d4-a716-446655440000/
Traceback (most recent call last):
  File "C:\Users\∞„∞„Àß\Desktop\mall\.venv\lib\site-packages\redis\connection.py", line 586, in send_packed_command
    self._sock.sendall(item)
ConnectionResetError: [WinError 10054] ‘∂≥Ã÷˜ª˙«ø∆»πÿ±’¡À“ª∏ˆœ÷”–µƒ¡¨Ω”°£

During handling of the above exception, another exception occurred:

Traceback (most recent call last):
  File "C:\Users\∞„∞„Àß\Desktop\mall\.venv\lib\site-packages\django\core\handlers\exception.py", line 55, in inner
    response = get_response(request)
  File "C:\Users\∞„∞„Àß\Desktop\mall\.venv\lib\site-packages\django\core\handlers\base.py", line 197, in _get_response
    response = wrapped_callback(request, *callback_args, **callback_kwargs)
  File "C:\Users\∞„∞„Àß\Desktop\mall\.venv\lib\site-packages\django\views\generic\base.py", line 105, in view
    return self.dispatch(request, *args, **kwargs)
  File "C:\Users\∞„∞„Àß\Desktop\mall\.venv\lib\site-packages\django\views\generic\base.py", line 144, in dispatch
    return handler(request, *args, **kwargs)
  File "C:\Users\∞„∞„Àß\Desktop\mall\mall\apps\verifications\views.py", line 17, in get
    redis_cli.setex(code, 100, text)
  File "C:\Users\∞„∞„Àß\Desktop\mall\.venv\lib\site-packages\redis\commands\core.py", line 2330, in setex
    return self.execute_command("SETEX", name, time, value)
  File "C:\Users\∞„∞„Àß\Desktop\mall\.venv\lib\site-packages\redis\client.py", line 623, in execute_command
    return self._execute_command(*args, **options)
  File "C:\Users\∞„∞„Àß\Desktop\mall\.venv\lib\site-packages\redis\client.py", line 629, in _execute_command
    conn = self.connection or pool.get_connection()
  File "C:\Users\∞„∞„Àß\Desktop\mall\.venv\lib\site-packages\redis\utils.py", line 191, in wrapper
    return func(*args, **kwargs)
  File "C:\Users\∞„∞„Àß\Desktop\mall\.venv\lib\site-packages\redis\connection.py", line 1530, in get_connection
    connection.connect()
  File "C:\Users\∞„∞„Àß\Desktop\mall\.venv\lib\site-packages\redis\connection.py", line 379, in connect
    self.connect_check_health(check_health=True)
  File "C:\Users\∞„∞„Àß\Desktop\mall\.venv\lib\site-packages\redis\connection.py", line 397, in connect_check_health
    self.on_connect_check_health(check_health=check_health)
  File "C:\Users\∞„∞„Àß\Desktop\mall\.venv\lib\site-packages\redis\connection.py", line 523, in on_connect_check_health
    self.send_command(
  File "C:\Users\∞„∞„Àß\Desktop\mall\.venv\lib\site-packages\redis\connection.py", line 608, in send_command
    self.send_packed_command(
  File "C:\Users\∞„∞„Àß\Desktop\mall\.venv\lib\site-packages\redis\connection.py", line 597, in send_packed_command
    raise ConnectionError(f"Error {errno} while writing to socket. {errmsg}.")
redis.exceptions.ConnectionError: Error 10054 while writing to socket. ‘∂≥Ã÷˜ª˙«ø∆»πÿ±’¡À“ª∏ˆœ÷”–µƒ¡¨Ω”°£.
ERROR 2025-08-05 19:37:14,789 basehttp 212 "GET /verification/image/550e8400-e29b-41d4-a716-446655440000/ HTTP/1.1" 500 130261
INFO 2025-08-05 19:38:41,555 autoreload 667 Watching for file changes with StatReloader
ERROR 2025-08-05 19:38:52,697 log 246 Internal Server Error: /verification/image/550e8400-e29b-41d4-a716-446655440000/
Traceback (most recent call last):
  File "C:\Users\∞„∞„Àß\Desktop\mall\.venv\lib\site-packages\redis\connection.py", line 644, in read_response
    response = self._parser.read_response(disable_decoding=disable_decoding)
  File "C:\Users\∞„∞„Àß\Desktop\mall\.venv\lib\site-packages\redis\_parsers\resp2.py", line 15, in read_response
    result = self._read_response(disable_decoding=disable_decoding)
  File "C:\Users\∞„∞„Àß\Desktop\mall\.venv\lib\site-packages\redis\_parsers\resp2.py", line 25, in _read_response
    raw = self._buffer.readline()
  File "C:\Users\∞„∞„Àß\Desktop\mall\.venv\lib\site-packages\redis\_parsers\socket.py", line 115, in readline
    self._read_from_socket()
  File "C:\Users\∞„∞„Àß\Desktop\mall\.venv\lib\site-packages\redis\_parsers\socket.py", line 65, in _read_from_socket
    data = self._sock.recv(socket_read_size)
ConnectionResetError: [WinError 10054] ‘∂≥Ã÷˜ª˙«ø∆»πÿ±’¡À“ª∏ˆœ÷”–µƒ¡¨Ω”°£

During handling of the above exception, another exception occurred:

Traceback (most recent call last):
  File "C:\Users\∞„∞„Àß\Desktop\mall\.venv\lib\site-packages\django\core\handlers\exception.py", line 55, in inner
    response = get_response(request)
  File "C:\Users\∞„∞„Àß\Desktop\mall\.venv\lib\site-packages\django\core\handlers\base.py", line 197, in _get_response
    response = wrapped_callback(request, *callback_args, **callback_kwargs)
  File "C:\Users\∞„∞„Àß\Desktop\mall\.venv\lib\site-packages\django\views\generic\base.py", line 105, in view
    return self.dispatch(request, *args, **kwargs)
  File "C:\Users\∞„∞„Àß\Desktop\mall\.venv\lib\site-packages\django\views\generic\base.py", line 144, in dispatch
    return handler(request, *args, **kwargs)
  File "C:\Users\∞„∞„Àß\Desktop\mall\mall\apps\verifications\views.py", line 17, in get
    redis_cli.setex(code, 100, text)
  File "C:\Users\∞„∞„Àß\Desktop\mall\.venv\lib\site-packages\redis\commands\core.py", line 2330, in setex
    return self.execute_command("SETEX", name, time, value)
  File "C:\Users\∞„∞„Àß\Desktop\mall\.venv\lib\site-packages\redis\client.py", line 623, in execute_command
    return self._execute_command(*args, **options)
  File "C:\Users\∞„∞„Àß\Desktop\mall\.venv\lib\site-packages\redis\client.py", line 629, in _execute_command
    conn = self.connection or pool.get_connection()
  File "C:\Users\∞„∞„Àß\Desktop\mall\.venv\lib\site-packages\redis\utils.py", line 191, in wrapper
    return func(*args, **kwargs)
  File "C:\Users\∞„∞„Àß\Desktop\mall\.venv\lib\site-packages\redis\connection.py", line 1530, in get_connection
    connection.connect()
  File "C:\Users\∞„∞„Àß\Desktop\mall\.venv\lib\site-packages\redis\connection.py", line 379, in connect
    self.connect_check_health(check_health=True)
  File "C:\Users\∞„∞„Àß\Desktop\mall\.venv\lib\site-packages\redis\connection.py", line 397, in connect_check_health
    self.on_connect_check_health(check_health=check_health)
  File "C:\Users\∞„∞„Àß\Desktop\mall\.venv\lib\site-packages\redis\connection.py", line 530, in on_connect_check_health
    self.read_response()
  File "C:\Users\∞„∞„Àß\Desktop\mall\.venv\lib\site-packages\redis\connection.py", line 652, in read_response
    raise ConnectionError(f"Error while reading from {host_error} : {e.args}")
redis.exceptions.ConnectionError: Error while reading from 192.168.31.128:6379 : (10054, '‘∂≥Ã÷˜ª˙«ø∆»πÿ±’¡À“ª∏ˆœ÷”–µƒ¡¨Ω”°£', None, 10054, None)
ERROR 2025-08-05 19:38:52,756 basehttp 212 "GET /verification/image/550e8400-e29b-41d4-a716-446655440000/ HTTP/1.1" 500 142520
