INFO 2025-08-05 19:34:32,948 autoreload 667 Watching for file changes with StatReloader
INFO 2025-08-05 19:34:59,379 autoreload 265 C:\Users\∞„∞„Àß\Desktop\mall\mall\apps\verifications\views.py changed, reloading.
INFO 2025-08-05 19:35:03,487 autoreload 667 Watching for file changes with StatReloader
ERROR 2025-08-05 19:35:08,663 log 246 Internal Server Error: /verification/image/550e8400-e29b-41d4-a716-446655440000/
Traceback (most recent call last):
  File "C:\Users\∞„∞„Àß\Desktop\mall\.venv\lib\site-packages\redis\connection.py", line 385, in connect_check_health
    sock = self.retry.call_with_retry(
  File "C:\Users\∞„∞„Àß\Desktop\mall\.venv\lib\site-packages\redis\retry.py", line 87, in call_with_retry
    return do()
  File "C:\Users\∞„∞„Àß\Desktop\mall\.venv\lib\site-packages\redis\connection.py", line 386, in <lambda>
    lambda: self._connect(), lambda error: self.disconnect(error)
  File "C:\Users\∞„∞„Àß\Desktop\mall\.venv\lib\site-packages\redis\connection.py", line 797, in _connect
    raise err
  File "C:\Users\∞„∞„Àß\Desktop\mall\.venv\lib\site-packages\redis\connection.py", line 781, in _connect
    sock.connect(socket_address)
ConnectionRefusedError: [WinError 10061] ”…”⁄ƒø±Íº∆À„ª˙ª˝º´æ‹æ¯£¨Œﬁ∑®¡¨Ω”°£

During handling of the above exception, another exception occurred:

Traceback (most recent call last):
  File "C:\Users\∞„∞„Àß\Desktop\mall\.venv\lib\site-packages\django\core\handlers\exception.py", line 55, in inner
    response = get_response(request)
  File "C:\Users\∞„∞„Àß\Desktop\mall\.venv\lib\site-packages\django\core\handlers\base.py", line 197, in _get_response
    response = wrapped_callback(request, *callback_args, **callback_kwargs)
  File "C:\Users\∞„∞„Àß\Desktop\mall\.venv\lib\site-packages\django\views\generic\base.py", line 105, in view
    return self.dispatch(request, *args, **kwargs)
  File "C:\Users\∞„∞„Àß\Desktop\mall\.venv\lib\site-packages\django\views\generic\base.py", line 144, in dispatch
    return handler(request, *args, **kwargs)
  File "C:\Users\∞„∞„Àß\Desktop\mall\mall\apps\verifications\views.py", line 17, in get
    redis_cli.setex(code, 100, text)
  File "C:\Users\∞„∞„Àß\Desktop\mall\.venv\lib\site-packages\redis\commands\core.py", line 2330, in setex
    return self.execute_command("SETEX", name, time, value)
  File "C:\Users\∞„∞„Àß\Desktop\mall\.venv\lib\site-packages\redis\client.py", line 623, in execute_command
    return self._execute_command(*args, **options)
  File "C:\Users\∞„∞„Àß\Desktop\mall\.venv\lib\site-packages\redis\client.py", line 629, in _execute_command
    conn = self.connection or pool.get_connection()
  File "C:\Users\∞„∞„Àß\Desktop\mall\.venv\lib\site-packages\redis\utils.py", line 191, in wrapper
    return func(*args, **kwargs)
  File "C:\Users\∞„∞„Àß\Desktop\mall\.venv\lib\site-packages\redis\connection.py", line 1530, in get_connection
    connection.connect()
  File "C:\Users\∞„∞„Àß\Desktop\mall\.venv\lib\site-packages\redis\connection.py", line 379, in connect
    self.connect_check_health(check_health=True)
  File "C:\Users\∞„∞„Àß\Desktop\mall\.venv\lib\site-packages\redis\connection.py", line 391, in connect_check_health
    raise ConnectionError(self._error_message(e))
redis.exceptions.ConnectionError: Error 10061 connecting to 192.168.31.128:6379. ”…”⁄ƒø±Íº∆À„ª˙ª˝º´æ‹æ¯£¨Œﬁ∑®¡¨Ω”°£.
ERROR 2025-08-05 19:35:08,684 basehttp 212 "GET /verification/image/550e8400-e29b-41d4-a716-446655440000/ HTTP/1.1" 500 134521
ERROR 2025-08-05 19:37:14,689 log 246 Internal Server Error: /verification/image/550e8400-e29b-41d4-a716-446655440000/
Traceback (most recent call last):
  File "C:\Users\∞„∞„Àß\Desktop\mall\.venv\lib\site-packages\redis\connection.py", line 586, in send_packed_command
    self._sock.sendall(item)
ConnectionResetError: [WinError 10054] ‘∂≥Ã÷˜ª˙«ø∆»πÿ±’¡À“ª∏ˆœ÷”–µƒ¡¨Ω”°£

During handling of the above exception, another exception occurred:

Traceback (most recent call last):
  File "C:\Users\∞„∞„Àß\Desktop\mall\.venv\lib\site-packages\django\core\handlers\exception.py", line 55, in inner
    response = get_response(request)
  File "C:\Users\∞„∞„Àß\Desktop\mall\.venv\lib\site-packages\django\core\handlers\base.py", line 197, in _get_response
    response = wrapped_callback(request, *callback_args, **callback_kwargs)
  File "C:\Users\∞„∞„Àß\Desktop\mall\.venv\lib\site-packages\django\views\generic\base.py", line 105, in view
    return self.dispatch(request, *args, **kwargs)
  File "C:\Users\∞„∞„Àß\Desktop\mall\.venv\lib\site-packages\django\views\generic\base.py", line 144, in dispatch
    return handler(request, *args, **kwargs)
  File "C:\Users\∞„∞„Àß\Desktop\mall\mall\apps\verifications\views.py", line 17, in get
    redis_cli.setex(code, 100, text)
  File "C:\Users\∞„∞„Àß\Desktop\mall\.venv\lib\site-packages\redis\commands\core.py", line 2330, in setex
    return self.execute_command("SETEX", name, time, value)
  File "C:\Users\∞„∞„Àß\Desktop\mall\.venv\lib\site-packages\redis\client.py", line 623, in execute_command
    return self._execute_command(*args, **options)
  File "C:\Users\∞„∞„Àß\Desktop\mall\.venv\lib\site-packages\redis\client.py", line 629, in _execute_command
    conn = self.connection or pool.get_connection()
  File "C:\Users\∞„∞„Àß\Desktop\mall\.venv\lib\site-packages\redis\utils.py", line 191, in wrapper
    return func(*args, **kwargs)
  File "C:\Users\∞„∞„Àß\Desktop\mall\.venv\lib\site-packages\redis\connection.py", line 1530, in get_connection
    connection.connect()
  File "C:\Users\∞„∞„Àß\Desktop\mall\.venv\lib\site-packages\redis\connection.py", line 379, in connect
    self.connect_check_health(check_health=True)
  File "C:\Users\∞„∞„Àß\Desktop\mall\.venv\lib\site-packages\redis\connection.py", line 397, in connect_check_health
    self.on_connect_check_health(check_health=check_health)
  File "C:\Users\∞„∞„Àß\Desktop\mall\.venv\lib\site-packages\redis\connection.py", line 523, in on_connect_check_health
    self.send_command(
  File "C:\Users\∞„∞„Àß\Desktop\mall\.venv\lib\site-packages\redis\connection.py", line 608, in send_command
    self.send_packed_command(
  File "C:\Users\∞„∞„Àß\Desktop\mall\.venv\lib\site-packages\redis\connection.py", line 597, in send_packed_command
    raise ConnectionError(f"Error {errno} while writing to socket. {errmsg}.")
redis.exceptions.ConnectionError: Error 10054 while writing to socket. ‘∂≥Ã÷˜ª˙«ø∆»πÿ±’¡À“ª∏ˆœ÷”–µƒ¡¨Ω”°£.
ERROR 2025-08-05 19:37:14,789 basehttp 212 "GET /verification/image/550e8400-e29b-41d4-a716-446655440000/ HTTP/1.1" 500 130261
INFO 2025-08-05 19:38:41,555 autoreload 667 Watching for file changes with StatReloader
ERROR 2025-08-05 19:38:52,697 log 246 Internal Server Error: /verification/image/550e8400-e29b-41d4-a716-446655440000/
Traceback (most recent call last):
  File "C:\Users\∞„∞„Àß\Desktop\mall\.venv\lib\site-packages\redis\connection.py", line 644, in read_response
    response = self._parser.read_response(disable_decoding=disable_decoding)
  File "C:\Users\∞„∞„Àß\Desktop\mall\.venv\lib\site-packages\redis\_parsers\resp2.py", line 15, in read_response
    result = self._read_response(disable_decoding=disable_decoding)
  File "C:\Users\∞„∞„Àß\Desktop\mall\.venv\lib\site-packages\redis\_parsers\resp2.py", line 25, in _read_response
    raw = self._buffer.readline()
  File "C:\Users\∞„∞„Àß\Desktop\mall\.venv\lib\site-packages\redis\_parsers\socket.py", line 115, in readline
    self._read_from_socket()
  File "C:\Users\∞„∞„Àß\Desktop\mall\.venv\lib\site-packages\redis\_parsers\socket.py", line 65, in _read_from_socket
    data = self._sock.recv(socket_read_size)
ConnectionResetError: [WinError 10054] ‘∂≥Ã÷˜ª˙«ø∆»πÿ±’¡À“ª∏ˆœ÷”–µƒ¡¨Ω”°£

During handling of the above exception, another exception occurred:

Traceback (most recent call last):
  File "C:\Users\∞„∞„Àß\Desktop\mall\.venv\lib\site-packages\django\core\handlers\exception.py", line 55, in inner
    response = get_response(request)
  File "C:\Users\∞„∞„Àß\Desktop\mall\.venv\lib\site-packages\django\core\handlers\base.py", line 197, in _get_response
    response = wrapped_callback(request, *callback_args, **callback_kwargs)
  File "C:\Users\∞„∞„Àß\Desktop\mall\.venv\lib\site-packages\django\views\generic\base.py", line 105, in view
    return self.dispatch(request, *args, **kwargs)
  File "C:\Users\∞„∞„Àß\Desktop\mall\.venv\lib\site-packages\django\views\generic\base.py", line 144, in dispatch
    return handler(request, *args, **kwargs)
  File "C:\Users\∞„∞„Àß\Desktop\mall\mall\apps\verifications\views.py", line 17, in get
    redis_cli.setex(code, 100, text)
  File "C:\Users\∞„∞„Àß\Desktop\mall\.venv\lib\site-packages\redis\commands\core.py", line 2330, in setex
    return self.execute_command("SETEX", name, time, value)
  File "C:\Users\∞„∞„Àß\Desktop\mall\.venv\lib\site-packages\redis\client.py", line 623, in execute_command
    return self._execute_command(*args, **options)
  File "C:\Users\∞„∞„Àß\Desktop\mall\.venv\lib\site-packages\redis\client.py", line 629, in _execute_command
    conn = self.connection or pool.get_connection()
  File "C:\Users\∞„∞„Àß\Desktop\mall\.venv\lib\site-packages\redis\utils.py", line 191, in wrapper
    return func(*args, **kwargs)
  File "C:\Users\∞„∞„Àß\Desktop\mall\.venv\lib\site-packages\redis\connection.py", line 1530, in get_connection
    connection.connect()
  File "C:\Users\∞„∞„Àß\Desktop\mall\.venv\lib\site-packages\redis\connection.py", line 379, in connect
    self.connect_check_health(check_health=True)
  File "C:\Users\∞„∞„Àß\Desktop\mall\.venv\lib\site-packages\redis\connection.py", line 397, in connect_check_health
    self.on_connect_check_health(check_health=check_health)
  File "C:\Users\∞„∞„Àß\Desktop\mall\.venv\lib\site-packages\redis\connection.py", line 530, in on_connect_check_health
    self.read_response()
  File "C:\Users\∞„∞„Àß\Desktop\mall\.venv\lib\site-packages\redis\connection.py", line 652, in read_response
    raise ConnectionError(f"Error while reading from {host_error} : {e.args}")
redis.exceptions.ConnectionError: Error while reading from 192.168.31.128:6379 : (10054, '‘∂≥Ã÷˜ª˙«ø∆»πÿ±’¡À“ª∏ˆœ÷”–µƒ¡¨Ω”°£', None, 10054, None)
ERROR 2025-08-05 19:38:52,756 basehttp 212 "GET /verification/image/550e8400-e29b-41d4-a716-446655440000/ HTTP/1.1" 500 142520
INFO 2025-08-06 19:22:40,695 autoreload 667 Watching for file changes with StatReloader
INFO 2025-08-06 19:23:26,764 basehttp 212 "POST /user/register/ HTTP/1.1" 200 57
ERROR 2025-08-06 19:27:51,565 log 246 Internal Server Error: /verification/image/3fa85f64-5717-4562-b3fc-2c963f66afa6/
Traceback (most recent call last):
  File "C:\Users\∞„∞„Àß\Desktop\mall\.venv\lib\site-packages\django\core\handlers\exception.py", line 55, in inner
    response = get_response(request)
  File "C:\Users\∞„∞„Àß\Desktop\mall\.venv\lib\site-packages\django\core\handlers\base.py", line 197, in _get_response
    response = wrapped_callback(request, *callback_args, **callback_kwargs)
  File "C:\Users\∞„∞„Àß\Desktop\mall\.venv\lib\site-packages\django\views\generic\base.py", line 105, in view
    return self.dispatch(request, *args, **kwargs)
  File "C:\Users\∞„∞„Àß\Desktop\mall\.venv\lib\site-packages\django\views\generic\base.py", line 144, in dispatch
    return handler(request, *args, **kwargs)
  File "C:\Users\∞„∞„Àß\Desktop\mall\mall\apps\verifications\views.py", line 17, in get
    redis_cli.setex(code, 100, text)
  File "C:\Users\∞„∞„Àß\Desktop\mall\.venv\lib\site-packages\redis\commands\core.py", line 2330, in setex
    return self.execute_command("SETEX", name, time, value)
  File "C:\Users\∞„∞„Àß\Desktop\mall\.venv\lib\site-packages\redis\client.py", line 623, in execute_command
    return self._execute_command(*args, **options)
  File "C:\Users\∞„∞„Àß\Desktop\mall\.venv\lib\site-packages\redis\client.py", line 629, in _execute_command
    conn = self.connection or pool.get_connection()
  File "C:\Users\∞„∞„Àß\Desktop\mall\.venv\lib\site-packages\redis\utils.py", line 191, in wrapper
    return func(*args, **kwargs)
  File "C:\Users\∞„∞„Àß\Desktop\mall\.venv\lib\site-packages\redis\connection.py", line 1530, in get_connection
    connection.connect()
  File "C:\Users\∞„∞„Àß\Desktop\mall\.venv\lib\site-packages\redis\connection.py", line 379, in connect
    self.connect_check_health(check_health=True)
  File "C:\Users\∞„∞„Àß\Desktop\mall\.venv\lib\site-packages\redis\connection.py", line 397, in connect_check_health
    self.on_connect_check_health(check_health=check_health)
  File "C:\Users\∞„∞„Àß\Desktop\mall\.venv\lib\site-packages\redis\connection.py", line 469, in on_connect_check_health
    auth_response = self.read_response()
  File "C:\Users\∞„∞„Àß\Desktop\mall\.venv\lib\site-packages\redis\connection.py", line 666, in read_response
    raise response
redis.exceptions.ResponseError: DENIED Redis is running in protected mode because protected mode is enabled, no bind address was specified, no authentication password is requested to clients. In this mode connections are only accepted from the loopback interface. If you want to connect from external computers to Redis you may adopt one of the following solutions: 1) Just disable protected mode sending the command 'CONFIG SET protected-mode no' from the loopback interface by connecting to Redis from the same host the server is running, however MAKE SURE Redis is not publicly accessible from internet if you do so. Use CONFIG REWRITE to make this change permanent. 2) Alternatively you can just disable the protected mode by editing the Redis configuration file, and setting the protected mode option to 'no', and then restarting the server. 3) If you started the server manually just for testing, restart it with the '--protected-mode no' option. 4) Setup a bind address or an authentication password. NOTE: You only need to do one of the above things in order for the server to start accepting connections from the outside.
ERROR 2025-08-06 19:27:51,620 basehttp 212 "GET /verification/image/3fa85f64-5717-4562-b3fc-2c963f66afa6/ HTTP/1.1" 500 125374
ERROR 2025-08-06 19:42:03,502 log 246 Internal Server Error: /verification/image/3fa85f64-5717-4562-b3fc-2c963f66afa6/
Traceback (most recent call last):
  File "C:\Users\∞„∞„Àß\Desktop\mall\.venv\lib\site-packages\redis\connection.py", line 644, in read_response
    response = self._parser.read_response(disable_decoding=disable_decoding)
  File "C:\Users\∞„∞„Àß\Desktop\mall\.venv\lib\site-packages\redis\_parsers\resp2.py", line 15, in read_response
    result = self._read_response(disable_decoding=disable_decoding)
  File "C:\Users\∞„∞„Àß\Desktop\mall\.venv\lib\site-packages\redis\_parsers\resp2.py", line 25, in _read_response
    raw = self._buffer.readline()
  File "C:\Users\∞„∞„Àß\Desktop\mall\.venv\lib\site-packages\redis\_parsers\socket.py", line 115, in readline
    self._read_from_socket()
  File "C:\Users\∞„∞„Àß\Desktop\mall\.venv\lib\site-packages\redis\_parsers\socket.py", line 65, in _read_from_socket
    data = self._sock.recv(socket_read_size)
ConnectionResetError: [WinError 10054] ‘∂≥Ã÷˜ª˙«ø∆»πÿ±’¡À“ª∏ˆœ÷”–µƒ¡¨Ω”°£

During handling of the above exception, another exception occurred:

Traceback (most recent call last):
  File "C:\Users\∞„∞„Àß\Desktop\mall\.venv\lib\site-packages\django\core\handlers\exception.py", line 55, in inner
    response = get_response(request)
  File "C:\Users\∞„∞„Àß\Desktop\mall\.venv\lib\site-packages\django\core\handlers\base.py", line 197, in _get_response
    response = wrapped_callback(request, *callback_args, **callback_kwargs)
  File "C:\Users\∞„∞„Àß\Desktop\mall\.venv\lib\site-packages\django\views\generic\base.py", line 105, in view
    return self.dispatch(request, *args, **kwargs)
  File "C:\Users\∞„∞„Àß\Desktop\mall\.venv\lib\site-packages\django\views\generic\base.py", line 144, in dispatch
    return handler(request, *args, **kwargs)
  File "C:\Users\∞„∞„Àß\Desktop\mall\mall\apps\verifications\views.py", line 17, in get
    redis_cli.setex(code, 100, text)
  File "C:\Users\∞„∞„Àß\Desktop\mall\.venv\lib\site-packages\redis\commands\core.py", line 2330, in setex
    return self.execute_command("SETEX", name, time, value)
  File "C:\Users\∞„∞„Àß\Desktop\mall\.venv\lib\site-packages\redis\client.py", line 623, in execute_command
    return self._execute_command(*args, **options)
  File "C:\Users\∞„∞„Àß\Desktop\mall\.venv\lib\site-packages\redis\client.py", line 629, in _execute_command
    conn = self.connection or pool.get_connection()
  File "C:\Users\∞„∞„Àß\Desktop\mall\.venv\lib\site-packages\redis\utils.py", line 191, in wrapper
    return func(*args, **kwargs)
  File "C:\Users\∞„∞„Àß\Desktop\mall\.venv\lib\site-packages\redis\connection.py", line 1530, in get_connection
    connection.connect()
  File "C:\Users\∞„∞„Àß\Desktop\mall\.venv\lib\site-packages\redis\connection.py", line 379, in connect
    self.connect_check_health(check_health=True)
  File "C:\Users\∞„∞„Àß\Desktop\mall\.venv\lib\site-packages\redis\connection.py", line 397, in connect_check_health
    self.on_connect_check_health(check_health=check_health)
  File "C:\Users\∞„∞„Àß\Desktop\mall\.venv\lib\site-packages\redis\connection.py", line 469, in on_connect_check_health
    auth_response = self.read_response()
  File "C:\Users\∞„∞„Àß\Desktop\mall\.venv\lib\site-packages\redis\connection.py", line 652, in read_response
    raise ConnectionError(f"Error while reading from {host_error} : {e.args}")
redis.exceptions.ConnectionError: Error while reading from 192.168.31.128:6379 : (10054, '‘∂≥Ã÷˜ª˙«ø∆»πÿ±’¡À“ª∏ˆœ÷”–µƒ¡¨Ω”°£', None, 10054, None)
ERROR 2025-08-06 19:42:03,552 basehttp 212 "GET /verification/image/3fa85f64-5717-4562-b3fc-2c963f66afa6/ HTTP/1.1" 500 143230
INFO 2025-08-06 19:42:20,519 autoreload 667 Watching for file changes with StatReloader
ERROR 2025-08-06 19:42:24,890 log 246 Internal Server Error: /verification/image/3fa85f64-5717-4562-b3fc-2c963f66afa6/
Traceback (most recent call last):
  File "C:\Users\∞„∞„Àß\Desktop\mall\.venv\lib\site-packages\django\core\handlers\exception.py", line 55, in inner
    response = get_response(request)
  File "C:\Users\∞„∞„Àß\Desktop\mall\.venv\lib\site-packages\django\core\handlers\base.py", line 197, in _get_response
    response = wrapped_callback(request, *callback_args, **callback_kwargs)
  File "C:\Users\∞„∞„Àß\Desktop\mall\.venv\lib\site-packages\django\views\generic\base.py", line 105, in view
    return self.dispatch(request, *args, **kwargs)
  File "C:\Users\∞„∞„Àß\Desktop\mall\.venv\lib\site-packages\django\views\generic\base.py", line 144, in dispatch
    return handler(request, *args, **kwargs)
  File "C:\Users\∞„∞„Àß\Desktop\mall\mall\apps\verifications\views.py", line 17, in get
    redis_cli.setex(code, 100, text)
  File "C:\Users\∞„∞„Àß\Desktop\mall\.venv\lib\site-packages\redis\commands\core.py", line 2330, in setex
    return self.execute_command("SETEX", name, time, value)
  File "C:\Users\∞„∞„Àß\Desktop\mall\.venv\lib\site-packages\redis\client.py", line 623, in execute_command
    return self._execute_command(*args, **options)
  File "C:\Users\∞„∞„Àß\Desktop\mall\.venv\lib\site-packages\redis\client.py", line 629, in _execute_command
    conn = self.connection or pool.get_connection()
  File "C:\Users\∞„∞„Àß\Desktop\mall\.venv\lib\site-packages\redis\utils.py", line 191, in wrapper
    return func(*args, **kwargs)
  File "C:\Users\∞„∞„Àß\Desktop\mall\.venv\lib\site-packages\redis\connection.py", line 1530, in get_connection
    connection.connect()
  File "C:\Users\∞„∞„Àß\Desktop\mall\.venv\lib\site-packages\redis\connection.py", line 379, in connect
    self.connect_check_health(check_health=True)
  File "C:\Users\∞„∞„Àß\Desktop\mall\.venv\lib\site-packages\redis\connection.py", line 397, in connect_check_health
    self.on_connect_check_health(check_health=check_health)
  File "C:\Users\∞„∞„Àß\Desktop\mall\.venv\lib\site-packages\redis\connection.py", line 469, in on_connect_check_health
    auth_response = self.read_response()
  File "C:\Users\∞„∞„Àß\Desktop\mall\.venv\lib\site-packages\redis\connection.py", line 666, in read_response
    raise response
redis.exceptions.ResponseError: DENIED Redis is running in protected mode because protected mode is enabled, no bind address was specified, no authentication password is requested to clients. In this mode connections are only accepted from the loopback interface. If you want to connect from external computers to Redis you may adopt one of the following solutions: 1) Just disable protected mode sending the command 'CONFIG SET protected-mode no' from the loopback interface by connecting to Redis from the same host the server is running, however MAKE SURE Redis is not publicly accessible from internet if you do so. Use CONFIG REWRITE to make this change permanent. 2) Alternatively you can just disable the protected mode by editing the Redis configuration file, and setting the protected mode option to 'no', and then restarting the server. 3) If you started the server manually just for testing, restart it with the '--protected-mode no' option. 4) Setup a bind address or an authentication password. NOTE: You only need to do one of the above things in order for the server to start accepting connections from the outside.
ERROR 2025-08-06 19:42:24,911 basehttp 212 "GET /verification/image/3fa85f64-5717-4562-b3fc-2c963f66afa6/ HTTP/1.1" 500 125374
INFO 2025-08-06 19:48:51,695 autoreload 667 Watching for file changes with StatReloader
ERROR 2025-08-06 19:48:58,452 log 246 Internal Server Error: /verification/image/3fa85f64-5717-4562-b3fc-2c963f66afa6/
Traceback (most recent call last):
  File "C:\Users\∞„∞„Àß\Desktop\mall\.venv\lib\site-packages\django\core\handlers\exception.py", line 55, in inner
    response = get_response(request)
  File "C:\Users\∞„∞„Àß\Desktop\mall\.venv\lib\site-packages\django\core\handlers\base.py", line 197, in _get_response
    response = wrapped_callback(request, *callback_args, **callback_kwargs)
  File "C:\Users\∞„∞„Àß\Desktop\mall\.venv\lib\site-packages\django\views\generic\base.py", line 105, in view
    return self.dispatch(request, *args, **kwargs)
  File "C:\Users\∞„∞„Àß\Desktop\mall\.venv\lib\site-packages\django\views\generic\base.py", line 144, in dispatch
    return handler(request, *args, **kwargs)
  File "C:\Users\∞„∞„Àß\Desktop\mall\mall\apps\verifications\views.py", line 17, in get
    redis_cli.setex(code, 100, text)
  File "C:\Users\∞„∞„Àß\Desktop\mall\.venv\lib\site-packages\redis\commands\core.py", line 2330, in setex
    return self.execute_command("SETEX", name, time, value)
  File "C:\Users\∞„∞„Àß\Desktop\mall\.venv\lib\site-packages\redis\client.py", line 623, in execute_command
    return self._execute_command(*args, **options)
  File "C:\Users\∞„∞„Àß\Desktop\mall\.venv\lib\site-packages\redis\client.py", line 629, in _execute_command
    conn = self.connection or pool.get_connection()
  File "C:\Users\∞„∞„Àß\Desktop\mall\.venv\lib\site-packages\redis\utils.py", line 191, in wrapper
    return func(*args, **kwargs)
  File "C:\Users\∞„∞„Àß\Desktop\mall\.venv\lib\site-packages\redis\connection.py", line 1530, in get_connection
    connection.connect()
  File "C:\Users\∞„∞„Àß\Desktop\mall\.venv\lib\site-packages\redis\connection.py", line 379, in connect
    self.connect_check_health(check_health=True)
  File "C:\Users\∞„∞„Àß\Desktop\mall\.venv\lib\site-packages\redis\connection.py", line 397, in connect_check_health
    self.on_connect_check_health(check_health=check_health)
  File "C:\Users\∞„∞„Àß\Desktop\mall\.venv\lib\site-packages\redis\connection.py", line 469, in on_connect_check_health
    auth_response = self.read_response()
  File "C:\Users\∞„∞„Àß\Desktop\mall\.venv\lib\site-packages\redis\connection.py", line 666, in read_response
    raise response
redis.exceptions.ResponseError: DENIED Redis is running in protected mode because protected mode is enabled, no bind address was specified, no authentication password is requested to clients. In this mode connections are only accepted from the loopback interface. If you want to connect from external computers to Redis you may adopt one of the following solutions: 1) Just disable protected mode sending the command 'CONFIG SET protected-mode no' from the loopback interface by connecting to Redis from the same host the server is running, however MAKE SURE Redis is not publicly accessible from internet if you do so. Use CONFIG REWRITE to make this change permanent. 2) Alternatively you can just disable the protected mode by editing the Redis configuration file, and setting the protected mode option to 'no', and then restarting the server. 3) If you started the server manually just for testing, restart it with the '--protected-mode no' option. 4) Setup a bind address or an authentication password. NOTE: You only need to do one of the above things in order for the server to start accepting connections from the outside.
ERROR 2025-08-06 19:48:58,479 basehttp 212 "GET /verification/image/3fa85f64-5717-4562-b3fc-2c963f66afa6/ HTTP/1.1" 500 125386
INFO 2025-08-06 19:50:55,996 autoreload 265 C:\Users\∞„∞„Àß\Desktop\mall\mall\mall\settings.py changed, reloading.
INFO 2025-08-06 19:50:58,194 autoreload 667 Watching for file changes with StatReloader
ERROR 2025-08-06 19:51:04,745 log 246 Internal Server Error: /verification/image/3fa85f64-5717-4562-b3fc-2c963f66afa6/
Traceback (most recent call last):
  File "C:\Users\∞„∞„Àß\Desktop\mall\.venv\lib\site-packages\redis\connection.py", line 644, in read_response
    response = self._parser.read_response(disable_decoding=disable_decoding)
  File "C:\Users\∞„∞„Àß\Desktop\mall\.venv\lib\site-packages\redis\_parsers\resp2.py", line 15, in read_response
    result = self._read_response(disable_decoding=disable_decoding)
  File "C:\Users\∞„∞„Àß\Desktop\mall\.venv\lib\site-packages\redis\_parsers\resp2.py", line 25, in _read_response
    raw = self._buffer.readline()
  File "C:\Users\∞„∞„Àß\Desktop\mall\.venv\lib\site-packages\redis\_parsers\socket.py", line 115, in readline
    self._read_from_socket()
  File "C:\Users\∞„∞„Àß\Desktop\mall\.venv\lib\site-packages\redis\_parsers\socket.py", line 65, in _read_from_socket
    data = self._sock.recv(socket_read_size)
ConnectionResetError: [WinError 10054] ‘∂≥Ã÷˜ª˙«ø∆»πÿ±’¡À“ª∏ˆœ÷”–µƒ¡¨Ω”°£

During handling of the above exception, another exception occurred:

Traceback (most recent call last):
  File "C:\Users\∞„∞„Àß\Desktop\mall\.venv\lib\site-packages\django\core\handlers\exception.py", line 55, in inner
    response = get_response(request)
  File "C:\Users\∞„∞„Àß\Desktop\mall\.venv\lib\site-packages\django\core\handlers\base.py", line 197, in _get_response
    response = wrapped_callback(request, *callback_args, **callback_kwargs)
  File "C:\Users\∞„∞„Àß\Desktop\mall\.venv\lib\site-packages\django\views\generic\base.py", line 105, in view
    return self.dispatch(request, *args, **kwargs)
  File "C:\Users\∞„∞„Àß\Desktop\mall\.venv\lib\site-packages\django\views\generic\base.py", line 144, in dispatch
    return handler(request, *args, **kwargs)
  File "C:\Users\∞„∞„Àß\Desktop\mall\mall\apps\verifications\views.py", line 17, in get
    redis_cli.setex(code, 100, text)
  File "C:\Users\∞„∞„Àß\Desktop\mall\.venv\lib\site-packages\redis\commands\core.py", line 2330, in setex
    return self.execute_command("SETEX", name, time, value)
  File "C:\Users\∞„∞„Àß\Desktop\mall\.venv\lib\site-packages\redis\client.py", line 623, in execute_command
    return self._execute_command(*args, **options)
  File "C:\Users\∞„∞„Àß\Desktop\mall\.venv\lib\site-packages\redis\client.py", line 629, in _execute_command
    conn = self.connection or pool.get_connection()
  File "C:\Users\∞„∞„Àß\Desktop\mall\.venv\lib\site-packages\redis\utils.py", line 191, in wrapper
    return func(*args, **kwargs)
  File "C:\Users\∞„∞„Àß\Desktop\mall\.venv\lib\site-packages\redis\connection.py", line 1530, in get_connection
    connection.connect()
  File "C:\Users\∞„∞„Àß\Desktop\mall\.venv\lib\site-packages\redis\connection.py", line 379, in connect
    self.connect_check_health(check_health=True)
  File "C:\Users\∞„∞„Àß\Desktop\mall\.venv\lib\site-packages\redis\connection.py", line 397, in connect_check_health
    self.on_connect_check_health(check_health=check_health)
  File "C:\Users\∞„∞„Àß\Desktop\mall\.venv\lib\site-packages\redis\connection.py", line 530, in on_connect_check_health
    self.read_response()
  File "C:\Users\∞„∞„Àß\Desktop\mall\.venv\lib\site-packages\redis\connection.py", line 652, in read_response
    raise ConnectionError(f"Error while reading from {host_error} : {e.args}")
redis.exceptions.ConnectionError: Error while reading from 192.168.31.128:6379 : (10054, '‘∂≥Ã÷˜ª˙«ø∆»πÿ±’¡À“ª∏ˆœ÷”–µƒ¡¨Ω”°£', None, 10054, None)
ERROR 2025-08-06 19:51:04,764 basehttp 212 "GET /verification/image/3fa85f64-5717-4562-b3fc-2c963f66afa6/ HTTP/1.1" 500 142410
INFO 2025-08-06 19:51:31,751 autoreload 265 C:\Users\∞„∞„Àß\Desktop\mall\mall\mall\settings.py changed, reloading.
INFO 2025-08-06 19:51:33,780 autoreload 667 Watching for file changes with StatReloader
ERROR 2025-08-06 19:51:38,097 log 246 Internal Server Error: /verification/image/3fa85f64-5717-4562-b3fc-2c963f66afa6/
Traceback (most recent call last):
  File "C:\Users\∞„∞„Àß\Desktop\mall\.venv\lib\site-packages\django\core\handlers\exception.py", line 55, in inner
    response = get_response(request)
  File "C:\Users\∞„∞„Àß\Desktop\mall\.venv\lib\site-packages\django\core\handlers\base.py", line 197, in _get_response
    response = wrapped_callback(request, *callback_args, **callback_kwargs)
  File "C:\Users\∞„∞„Àß\Desktop\mall\.venv\lib\site-packages\django\views\generic\base.py", line 105, in view
    return self.dispatch(request, *args, **kwargs)
  File "C:\Users\∞„∞„Àß\Desktop\mall\.venv\lib\site-packages\django\views\generic\base.py", line 144, in dispatch
    return handler(request, *args, **kwargs)
  File "C:\Users\∞„∞„Àß\Desktop\mall\mall\apps\verifications\views.py", line 17, in get
    redis_cli.setex(code, 100, text)
  File "C:\Users\∞„∞„Àß\Desktop\mall\.venv\lib\site-packages\redis\commands\core.py", line 2330, in setex
    return self.execute_command("SETEX", name, time, value)
  File "C:\Users\∞„∞„Àß\Desktop\mall\.venv\lib\site-packages\redis\client.py", line 623, in execute_command
    return self._execute_command(*args, **options)
  File "C:\Users\∞„∞„Àß\Desktop\mall\.venv\lib\site-packages\redis\client.py", line 629, in _execute_command
    conn = self.connection or pool.get_connection()
  File "C:\Users\∞„∞„Àß\Desktop\mall\.venv\lib\site-packages\redis\utils.py", line 191, in wrapper
    return func(*args, **kwargs)
  File "C:\Users\∞„∞„Àß\Desktop\mall\.venv\lib\site-packages\redis\connection.py", line 1530, in get_connection
    connection.connect()
  File "C:\Users\∞„∞„Àß\Desktop\mall\.venv\lib\site-packages\redis\connection.py", line 379, in connect
    self.connect_check_health(check_health=True)
  File "C:\Users\∞„∞„Àß\Desktop\mall\.venv\lib\site-packages\redis\connection.py", line 397, in connect_check_health
    self.on_connect_check_health(check_health=check_health)
  File "C:\Users\∞„∞„Àß\Desktop\mall\.venv\lib\site-packages\redis\connection.py", line 469, in on_connect_check_health
    auth_response = self.read_response()
  File "C:\Users\∞„∞„Àß\Desktop\mall\.venv\lib\site-packages\redis\connection.py", line 666, in read_response
    raise response
redis.exceptions.ResponseError: DENIED Redis is running in protected mode because protected mode is enabled, no bind address was specified, no authentication password is requested to clients. In this mode connections are only accepted from the loopback interface. If you want to connect from external computers to Redis you may adopt one of the following solutions: 1) Just disable protected mode sending the command 'CONFIG SET protected-mode no' from the loopback interface by connecting to Redis from the same host the server is running, however MAKE SURE Redis is not publicly accessible from internet if you do so. Use CONFIG REWRITE to make this change permanent. 2) Alternatively you can just disable the protected mode by editing the Redis configuration file, and setting the protected mode option to 'no', and then restarting the server. 3) If you started the server manually just for testing, restart it with the '--protected-mode no' option. 4) Setup a bind address or an authentication password. NOTE: You only need to do one of the above things in order for the server to start accepting connections from the outside.
ERROR 2025-08-06 19:51:38,125 basehttp 212 "GET /verification/image/3fa85f64-5717-4562-b3fc-2c963f66afa6/ HTTP/1.1" 500 125278
ERROR 2025-08-06 19:58:10,430 log 246 Internal Server Error: /verification/image/3fa85f64-5717-4562-b3fc-2c963f66afa6/
Traceback (most recent call last):
  File "C:\Users\∞„∞„Àß\Desktop\mall\.venv\lib\site-packages\redis\connection.py", line 644, in read_response
    response = self._parser.read_response(disable_decoding=disable_decoding)
  File "C:\Users\∞„∞„Àß\Desktop\mall\.venv\lib\site-packages\redis\_parsers\resp2.py", line 15, in read_response
    result = self._read_response(disable_decoding=disable_decoding)
  File "C:\Users\∞„∞„Àß\Desktop\mall\.venv\lib\site-packages\redis\_parsers\resp2.py", line 25, in _read_response
    raw = self._buffer.readline()
  File "C:\Users\∞„∞„Àß\Desktop\mall\.venv\lib\site-packages\redis\_parsers\socket.py", line 115, in readline
    self._read_from_socket()
  File "C:\Users\∞„∞„Àß\Desktop\mall\.venv\lib\site-packages\redis\_parsers\socket.py", line 65, in _read_from_socket
    data = self._sock.recv(socket_read_size)
ConnectionResetError: [WinError 10054] ‘∂≥Ã÷˜ª˙«ø∆»πÿ±’¡À“ª∏ˆœ÷”–µƒ¡¨Ω”°£

During handling of the above exception, another exception occurred:

Traceback (most recent call last):
  File "C:\Users\∞„∞„Àß\Desktop\mall\.venv\lib\site-packages\django\core\handlers\exception.py", line 55, in inner
    response = get_response(request)
  File "C:\Users\∞„∞„Àß\Desktop\mall\.venv\lib\site-packages\django\core\handlers\base.py", line 197, in _get_response
    response = wrapped_callback(request, *callback_args, **callback_kwargs)
  File "C:\Users\∞„∞„Àß\Desktop\mall\.venv\lib\site-packages\django\views\generic\base.py", line 105, in view
    return self.dispatch(request, *args, **kwargs)
  File "C:\Users\∞„∞„Àß\Desktop\mall\.venv\lib\site-packages\django\views\generic\base.py", line 144, in dispatch
    return handler(request, *args, **kwargs)
  File "C:\Users\∞„∞„Àß\Desktop\mall\mall\apps\verifications\views.py", line 17, in get
    redis_cli.setex(code, 100, text)
  File "C:\Users\∞„∞„Àß\Desktop\mall\.venv\lib\site-packages\redis\commands\core.py", line 2330, in setex
    return self.execute_command("SETEX", name, time, value)
  File "C:\Users\∞„∞„Àß\Desktop\mall\.venv\lib\site-packages\redis\client.py", line 623, in execute_command
    return self._execute_command(*args, **options)
  File "C:\Users\∞„∞„Àß\Desktop\mall\.venv\lib\site-packages\redis\client.py", line 629, in _execute_command
    conn = self.connection or pool.get_connection()
  File "C:\Users\∞„∞„Àß\Desktop\mall\.venv\lib\site-packages\redis\utils.py", line 191, in wrapper
    return func(*args, **kwargs)
  File "C:\Users\∞„∞„Àß\Desktop\mall\.venv\lib\site-packages\redis\connection.py", line 1530, in get_connection
    connection.connect()
  File "C:\Users\∞„∞„Àß\Desktop\mall\.venv\lib\site-packages\redis\connection.py", line 379, in connect
    self.connect_check_health(check_health=True)
  File "C:\Users\∞„∞„Àß\Desktop\mall\.venv\lib\site-packages\redis\connection.py", line 397, in connect_check_health
    self.on_connect_check_health(check_health=check_health)
  File "C:\Users\∞„∞„Àß\Desktop\mall\.venv\lib\site-packages\redis\connection.py", line 469, in on_connect_check_health
    auth_response = self.read_response()
  File "C:\Users\∞„∞„Àß\Desktop\mall\.venv\lib\site-packages\redis\connection.py", line 652, in read_response
    raise ConnectionError(f"Error while reading from {host_error} : {e.args}")
redis.exceptions.ConnectionError: Error while reading from 192.168.31.128:6379 : (10054, '‘∂≥Ã÷˜ª˙«ø∆»πÿ±’¡À“ª∏ˆœ÷”–µƒ¡¨Ω”°£', None, 10054, None)
ERROR 2025-08-06 19:58:10,487 basehttp 212 "GET /verification/image/3fa85f64-5717-4562-b3fc-2c963f66afa6/ HTTP/1.1" 500 142778
INFO 2025-08-06 19:58:23,947 autoreload 667 Watching for file changes with StatReloader
ERROR 2025-08-06 19:58:28,989 log 246 Internal Server Error: /verification/image/3fa85f64-5717-4562-b3fc-2c963f66afa6/
Traceback (most recent call last):
  File "C:\Users\∞„∞„Àß\Desktop\mall\.venv\lib\site-packages\django\core\handlers\exception.py", line 55, in inner
    response = get_response(request)
  File "C:\Users\∞„∞„Àß\Desktop\mall\.venv\lib\site-packages\django\core\handlers\base.py", line 197, in _get_response
    response = wrapped_callback(request, *callback_args, **callback_kwargs)
  File "C:\Users\∞„∞„Àß\Desktop\mall\.venv\lib\site-packages\django\views\generic\base.py", line 105, in view
    return self.dispatch(request, *args, **kwargs)
  File "C:\Users\∞„∞„Àß\Desktop\mall\.venv\lib\site-packages\django\views\generic\base.py", line 144, in dispatch
    return handler(request, *args, **kwargs)
  File "C:\Users\∞„∞„Àß\Desktop\mall\mall\apps\verifications\views.py", line 17, in get
    redis_cli.setex(code, 100, text)
  File "C:\Users\∞„∞„Àß\Desktop\mall\.venv\lib\site-packages\redis\commands\core.py", line 2330, in setex
    return self.execute_command("SETEX", name, time, value)
  File "C:\Users\∞„∞„Àß\Desktop\mall\.venv\lib\site-packages\redis\client.py", line 623, in execute_command
    return self._execute_command(*args, **options)
  File "C:\Users\∞„∞„Àß\Desktop\mall\.venv\lib\site-packages\redis\client.py", line 629, in _execute_command
    conn = self.connection or pool.get_connection()
  File "C:\Users\∞„∞„Àß\Desktop\mall\.venv\lib\site-packages\redis\utils.py", line 191, in wrapper
    return func(*args, **kwargs)
  File "C:\Users\∞„∞„Àß\Desktop\mall\.venv\lib\site-packages\redis\connection.py", line 1530, in get_connection
    connection.connect()
  File "C:\Users\∞„∞„Àß\Desktop\mall\.venv\lib\site-packages\redis\connection.py", line 379, in connect
    self.connect_check_health(check_health=True)
  File "C:\Users\∞„∞„Àß\Desktop\mall\.venv\lib\site-packages\redis\connection.py", line 397, in connect_check_health
    self.on_connect_check_health(check_health=check_health)
  File "C:\Users\∞„∞„Àß\Desktop\mall\.venv\lib\site-packages\redis\connection.py", line 469, in on_connect_check_health
    auth_response = self.read_response()
  File "C:\Users\∞„∞„Àß\Desktop\mall\.venv\lib\site-packages\redis\connection.py", line 666, in read_response
    raise response
redis.exceptions.ResponseError: DENIED Redis is running in protected mode because protected mode is enabled, no bind address was specified, no authentication password is requested to clients. In this mode connections are only accepted from the loopback interface. If you want to connect from external computers to Redis you may adopt one of the following solutions: 1) Just disable protected mode sending the command 'CONFIG SET protected-mode no' from the loopback interface by connecting to Redis from the same host the server is running, however MAKE SURE Redis is not publicly accessible from internet if you do so. Use CONFIG REWRITE to make this change permanent. 2) Alternatively you can just disable the protected mode by editing the Redis configuration file, and setting the protected mode option to 'no', and then restarting the server. 3) If you started the server manually just for testing, restart it with the '--protected-mode no' option. 4) Setup a bind address or an authentication password. NOTE: You only need to do one of the above things in order for the server to start accepting connections from the outside.
ERROR 2025-08-06 19:58:29,010 basehttp 212 "GET /verification/image/3fa85f64-5717-4562-b3fc-2c963f66afa6/ HTTP/1.1" 500 125399
ERROR 2025-08-06 20:01:38,370 log 246 Internal Server Error: /verification/image/3fa85f64-5717-4562-b3fc-2c963f66afa6/
Traceback (most recent call last):
  File "C:\Users\∞„∞„Àß\Desktop\mall\.venv\lib\site-packages\django\core\handlers\exception.py", line 55, in inner
    response = get_response(request)
  File "C:\Users\∞„∞„Àß\Desktop\mall\.venv\lib\site-packages\django\core\handlers\base.py", line 197, in _get_response
    response = wrapped_callback(request, *callback_args, **callback_kwargs)
  File "C:\Users\∞„∞„Àß\Desktop\mall\.venv\lib\site-packages\django\views\generic\base.py", line 105, in view
    return self.dispatch(request, *args, **kwargs)
  File "C:\Users\∞„∞„Àß\Desktop\mall\.venv\lib\site-packages\django\views\generic\base.py", line 144, in dispatch
    return handler(request, *args, **kwargs)
  File "C:\Users\∞„∞„Àß\Desktop\mall\mall\apps\verifications\views.py", line 17, in get
    redis_cli.setex(code, 100, text)
  File "C:\Users\∞„∞„Àß\Desktop\mall\.venv\lib\site-packages\redis\commands\core.py", line 2330, in setex
    return self.execute_command("SETEX", name, time, value)
  File "C:\Users\∞„∞„Àß\Desktop\mall\.venv\lib\site-packages\redis\client.py", line 623, in execute_command
    return self._execute_command(*args, **options)
  File "C:\Users\∞„∞„Àß\Desktop\mall\.venv\lib\site-packages\redis\client.py", line 629, in _execute_command
    conn = self.connection or pool.get_connection()
  File "C:\Users\∞„∞„Àß\Desktop\mall\.venv\lib\site-packages\redis\utils.py", line 191, in wrapper
    return func(*args, **kwargs)
  File "C:\Users\∞„∞„Àß\Desktop\mall\.venv\lib\site-packages\redis\connection.py", line 1530, in get_connection
    connection.connect()
  File "C:\Users\∞„∞„Àß\Desktop\mall\.venv\lib\site-packages\redis\connection.py", line 379, in connect
    self.connect_check_health(check_health=True)
  File "C:\Users\∞„∞„Àß\Desktop\mall\.venv\lib\site-packages\redis\connection.py", line 397, in connect_check_health
    self.on_connect_check_health(check_health=check_health)
  File "C:\Users\∞„∞„Àß\Desktop\mall\.venv\lib\site-packages\redis\connection.py", line 469, in on_connect_check_health
    auth_response = self.read_response()
  File "C:\Users\∞„∞„Àß\Desktop\mall\.venv\lib\site-packages\redis\connection.py", line 666, in read_response
    raise response
redis.exceptions.ResponseError: DENIED Redis is running in protected mode because protected mode is enabled, no bind address was specified, no authentication password is requested to clients. In this mode connections are only accepted from the loopback interface. If you want to connect from external computers to Redis you may adopt one of the following solutions: 1) Just disable protected mode sending the command 'CONFIG SET protected-mode no' from the loopback interface by connecting to Redis from the same host the server is running, however MAKE SURE Redis is not publicly accessible from internet if you do so. Use CONFIG REWRITE to make this change permanent. 2) Alternatively you can just disable the protected mode by editing the Redis configuration file, and setting the protected mode option to 'no', and then restarting the server. 3) If you started the server manually just for testing, restart it with the '--protected-mode no' option. 4) Setup a bind address or an authentication password. NOTE: You only need to do one of the above things in order for the server to start accepting connections from the outside.
ERROR 2025-08-06 20:01:38,399 basehttp 212 "GET /verification/image/3fa85f64-5717-4562-b3fc-2c963f66afa6/ HTTP/1.1" 500 124338
ERROR 2025-08-06 20:04:36,373 log 246 Internal Server Error: /verification/image/3fa85f64-5717-4562-b3fc-2c963f66afa6/
Traceback (most recent call last):
  File "C:\Users\∞„∞„Àß\Desktop\mall\.venv\lib\site-packages\django\core\handlers\exception.py", line 55, in inner
    response = get_response(request)
  File "C:\Users\∞„∞„Àß\Desktop\mall\.venv\lib\site-packages\django\core\handlers\base.py", line 197, in _get_response
    response = wrapped_callback(request, *callback_args, **callback_kwargs)
  File "C:\Users\∞„∞„Àß\Desktop\mall\.venv\lib\site-packages\django\views\generic\base.py", line 105, in view
    return self.dispatch(request, *args, **kwargs)
  File "C:\Users\∞„∞„Àß\Desktop\mall\.venv\lib\site-packages\django\views\generic\base.py", line 144, in dispatch
    return handler(request, *args, **kwargs)
  File "C:\Users\∞„∞„Àß\Desktop\mall\mall\apps\verifications\views.py", line 17, in get
    redis_cli.setex(code, 100, text)
  File "C:\Users\∞„∞„Àß\Desktop\mall\.venv\lib\site-packages\redis\commands\core.py", line 2330, in setex
    return self.execute_command("SETEX", name, time, value)
  File "C:\Users\∞„∞„Àß\Desktop\mall\.venv\lib\site-packages\redis\client.py", line 623, in execute_command
    return self._execute_command(*args, **options)
  File "C:\Users\∞„∞„Àß\Desktop\mall\.venv\lib\site-packages\redis\client.py", line 629, in _execute_command
    conn = self.connection or pool.get_connection()
  File "C:\Users\∞„∞„Àß\Desktop\mall\.venv\lib\site-packages\redis\utils.py", line 191, in wrapper
    return func(*args, **kwargs)
  File "C:\Users\∞„∞„Àß\Desktop\mall\.venv\lib\site-packages\redis\connection.py", line 1530, in get_connection
    connection.connect()
  File "C:\Users\∞„∞„Àß\Desktop\mall\.venv\lib\site-packages\redis\connection.py", line 379, in connect
    self.connect_check_health(check_health=True)
  File "C:\Users\∞„∞„Àß\Desktop\mall\.venv\lib\site-packages\redis\connection.py", line 397, in connect_check_health
    self.on_connect_check_health(check_health=check_health)
  File "C:\Users\∞„∞„Àß\Desktop\mall\.venv\lib\site-packages\redis\connection.py", line 469, in on_connect_check_health
    auth_response = self.read_response()
  File "C:\Users\∞„∞„Àß\Desktop\mall\.venv\lib\site-packages\redis\connection.py", line 666, in read_response
    raise response
redis.exceptions.ResponseError: DENIED Redis is running in protected mode because protected mode is enabled, no bind address was specified, no authentication password is requested to clients. In this mode connections are only accepted from the loopback interface. If you want to connect from external computers to Redis you may adopt one of the following solutions: 1) Just disable protected mode sending the command 'CONFIG SET protected-mode no' from the loopback interface by connecting to Redis from the same host the server is running, however MAKE SURE Redis is not publicly accessible from internet if you do so. Use CONFIG REWRITE to make this change permanent. 2) Alternatively you can just disable the protected mode by editing the Redis configuration file, and setting the protected mode option to 'no', and then restarting the server. 3) If you started the server manually just for testing, restart it with the '--protected-mode no' option. 4) Setup a bind address or an authentication password. NOTE: You only need to do one of the above things in order for the server to start accepting connections from the outside.
ERROR 2025-08-06 20:04:36,402 basehttp 212 "GET /verification/image/3fa85f64-5717-4562-b3fc-2c963f66afa6/ HTTP/1.1" 500 125422
INFO 2025-08-07 13:17:24,129 autoreload 667 Watching for file changes with StatReloader
ERROR 2025-08-07 13:22:55,090 log 246 Internal Server Error: /verification/image/3fa85f64-5717-4562-b3fc-2c963f66afa6/
Traceback (most recent call last):
  File "C:\Users\∞„∞„Àß\Desktop\mall\.venv\lib\site-packages\django\core\handlers\exception.py", line 55, in inner
    response = get_response(request)
  File "C:\Users\∞„∞„Àß\Desktop\mall\.venv\lib\site-packages\django\core\handlers\base.py", line 197, in _get_response
    response = wrapped_callback(request, *callback_args, **callback_kwargs)
  File "C:\Users\∞„∞„Àß\Desktop\mall\.venv\lib\site-packages\django\views\generic\base.py", line 105, in view
    return self.dispatch(request, *args, **kwargs)
  File "C:\Users\∞„∞„Àß\Desktop\mall\.venv\lib\site-packages\django\views\generic\base.py", line 144, in dispatch
    return handler(request, *args, **kwargs)
  File "C:\Users\∞„∞„Àß\Desktop\mall\mall\apps\verifications\views.py", line 17, in get
    redis_cli.setex(code, 100, text)
  File "C:\Users\∞„∞„Àß\Desktop\mall\.venv\lib\site-packages\redis\commands\core.py", line 2330, in setex
    return self.execute_command("SETEX", name, time, value)
  File "C:\Users\∞„∞„Àß\Desktop\mall\.venv\lib\site-packages\redis\client.py", line 623, in execute_command
    return self._execute_command(*args, **options)
  File "C:\Users\∞„∞„Àß\Desktop\mall\.venv\lib\site-packages\redis\client.py", line 629, in _execute_command
    conn = self.connection or pool.get_connection()
  File "C:\Users\∞„∞„Àß\Desktop\mall\.venv\lib\site-packages\redis\utils.py", line 191, in wrapper
    return func(*args, **kwargs)
  File "C:\Users\∞„∞„Àß\Desktop\mall\.venv\lib\site-packages\redis\connection.py", line 1530, in get_connection
    connection.connect()
  File "C:\Users\∞„∞„Àß\Desktop\mall\.venv\lib\site-packages\redis\connection.py", line 379, in connect
    self.connect_check_health(check_health=True)
  File "C:\Users\∞„∞„Àß\Desktop\mall\.venv\lib\site-packages\redis\connection.py", line 397, in connect_check_health
    self.on_connect_check_health(check_health=check_health)
  File "C:\Users\∞„∞„Àß\Desktop\mall\.venv\lib\site-packages\redis\connection.py", line 469, in on_connect_check_health
    auth_response = self.read_response()
  File "C:\Users\∞„∞„Àß\Desktop\mall\.venv\lib\site-packages\redis\connection.py", line 666, in read_response
    raise response
redis.exceptions.ResponseError: DENIED Redis is running in protected mode because protected mode is enabled, no bind address was specified, no authentication password is requested to clients. In this mode connections are only accepted from the loopback interface. If you want to connect from external computers to Redis you may adopt one of the following solutions: 1) Just disable protected mode sending the command 'CONFIG SET protected-mode no' from the loopback interface by connecting to Redis from the same host the server is running, however MAKE SURE Redis is not publicly accessible from internet if you do so. Use CONFIG REWRITE to make this change permanent. 2) Alternatively you can just disable the protected mode by editing the Redis configuration file, and setting the protected mode option to 'no', and then restarting the server. 3) If you started the server manually just for testing, restart it with the '--protected-mode no' option. 4) Setup a bind address or an authentication password. NOTE: You only need to do one of the above things in order for the server to start accepting connections from the outside.
ERROR 2025-08-07 13:22:55,115 basehttp 212 "GET /verification/image/3fa85f64-5717-4562-b3fc-2c963f66afa6/ HTTP/1.1" 500 124105
ERROR 2025-08-07 13:23:11,733 log 246 Internal Server Error: /verification/image/3fa85f64-5717-4562-b3fc-2c963f66afa6/
Traceback (most recent call last):
  File "C:\Users\∞„∞„Àß\Desktop\mall\.venv\lib\site-packages\django\core\handlers\exception.py", line 55, in inner
    response = get_response(request)
  File "C:\Users\∞„∞„Àß\Desktop\mall\.venv\lib\site-packages\django\core\handlers\base.py", line 197, in _get_response
    response = wrapped_callback(request, *callback_args, **callback_kwargs)
  File "C:\Users\∞„∞„Àß\Desktop\mall\.venv\lib\site-packages\django\views\generic\base.py", line 105, in view
    return self.dispatch(request, *args, **kwargs)
  File "C:\Users\∞„∞„Àß\Desktop\mall\.venv\lib\site-packages\django\views\generic\base.py", line 144, in dispatch
    return handler(request, *args, **kwargs)
  File "C:\Users\∞„∞„Àß\Desktop\mall\mall\apps\verifications\views.py", line 17, in get
    redis_cli.setex(code, 100, text)
  File "C:\Users\∞„∞„Àß\Desktop\mall\.venv\lib\site-packages\redis\commands\core.py", line 2330, in setex
    return self.execute_command("SETEX", name, time, value)
  File "C:\Users\∞„∞„Àß\Desktop\mall\.venv\lib\site-packages\redis\client.py", line 623, in execute_command
    return self._execute_command(*args, **options)
  File "C:\Users\∞„∞„Àß\Desktop\mall\.venv\lib\site-packages\redis\client.py", line 629, in _execute_command
    conn = self.connection or pool.get_connection()
  File "C:\Users\∞„∞„Àß\Desktop\mall\.venv\lib\site-packages\redis\utils.py", line 191, in wrapper
    return func(*args, **kwargs)
  File "C:\Users\∞„∞„Àß\Desktop\mall\.venv\lib\site-packages\redis\connection.py", line 1530, in get_connection
    connection.connect()
  File "C:\Users\∞„∞„Àß\Desktop\mall\.venv\lib\site-packages\redis\connection.py", line 379, in connect
    self.connect_check_health(check_health=True)
  File "C:\Users\∞„∞„Àß\Desktop\mall\.venv\lib\site-packages\redis\connection.py", line 397, in connect_check_health
    self.on_connect_check_health(check_health=check_health)
  File "C:\Users\∞„∞„Àß\Desktop\mall\.venv\lib\site-packages\redis\connection.py", line 469, in on_connect_check_health
    auth_response = self.read_response()
  File "C:\Users\∞„∞„Àß\Desktop\mall\.venv\lib\site-packages\redis\connection.py", line 666, in read_response
    raise response
redis.exceptions.ResponseError: DENIED Redis is running in protected mode because protected mode is enabled, no bind address was specified, no authentication password is requested to clients. In this mode connections are only accepted from the loopback interface. If you want to connect from external computers to Redis you may adopt one of the following solutions: 1) Just disable protected mode sending the command 'CONFIG SET protected-mode no' from the loopback interface by connecting to Redis from the same host the server is running, however MAKE SURE Redis is not publicly accessible from internet if you do so. Use CONFIG REWRITE to make this change permanent. 2) Alternatively you can just disable the protected mode by editing the Redis configuration file, and setting the protected mode option to 'no', and then restarting the server. 3) If you started the server manually just for testing, restart it with the '--protected-mode no' option. 4) Setup a bind address or an authentication password. NOTE: You only need to do one of the above things in order for the server to start accepting connections from the outside.
ERROR 2025-08-07 13:23:11,807 basehttp 212 "GET /verification/image/3fa85f64-5717-4562-b3fc-2c963f66afa6/ HTTP/1.1" 500 127631
WARNING 2025-08-07 13:23:13,389 log 246 Not Found: /favicon.ico
WARNING 2025-08-07 13:23:13,400 basehttp 212 "GET /favicon.ico HTTP/1.1" 404 2326
INFO 2025-08-07 13:49:09,131 autoreload 667 Watching for file changes with StatReloader
ERROR 2025-08-07 13:49:52,107 log 246 Internal Server Error: /verification/image/3fa85f64-5717-4562-b3fc-2c963f66afa6/
Traceback (most recent call last):
  File "C:\Users\∞„∞„Àß\Desktop\mall\.venv\lib\site-packages\django\core\handlers\exception.py", line 55, in inner
    response = get_response(request)
  File "C:\Users\∞„∞„Àß\Desktop\mall\.venv\lib\site-packages\django\core\handlers\base.py", line 197, in _get_response
    response = wrapped_callback(request, *callback_args, **callback_kwargs)
  File "C:\Users\∞„∞„Àß\Desktop\mall\.venv\lib\site-packages\django\views\generic\base.py", line 105, in view
    return self.dispatch(request, *args, **kwargs)
  File "C:\Users\∞„∞„Àß\Desktop\mall\.venv\lib\site-packages\django\views\generic\base.py", line 144, in dispatch
    return handler(request, *args, **kwargs)
  File "C:\Users\∞„∞„Àß\Desktop\mall\mall\apps\verifications\views.py", line 17, in get
    redis_cli.setex(code, 100, text)
  File "C:\Users\∞„∞„Àß\Desktop\mall\.venv\lib\site-packages\redis\commands\core.py", line 2330, in setex
    return self.execute_command("SETEX", name, time, value)
  File "C:\Users\∞„∞„Àß\Desktop\mall\.venv\lib\site-packages\redis\client.py", line 623, in execute_command
    return self._execute_command(*args, **options)
  File "C:\Users\∞„∞„Àß\Desktop\mall\.venv\lib\site-packages\redis\client.py", line 629, in _execute_command
    conn = self.connection or pool.get_connection()
  File "C:\Users\∞„∞„Àß\Desktop\mall\.venv\lib\site-packages\redis\utils.py", line 191, in wrapper
    return func(*args, **kwargs)
  File "C:\Users\∞„∞„Àß\Desktop\mall\.venv\lib\site-packages\redis\connection.py", line 1530, in get_connection
    connection.connect()
  File "C:\Users\∞„∞„Àß\Desktop\mall\.venv\lib\site-packages\redis\connection.py", line 379, in connect
    self.connect_check_health(check_health=True)
  File "C:\Users\∞„∞„Àß\Desktop\mall\.venv\lib\site-packages\redis\connection.py", line 397, in connect_check_health
    self.on_connect_check_health(check_health=check_health)
  File "C:\Users\∞„∞„Àß\Desktop\mall\.venv\lib\site-packages\redis\connection.py", line 469, in on_connect_check_health
    auth_response = self.read_response()
  File "C:\Users\∞„∞„Àß\Desktop\mall\.venv\lib\site-packages\redis\connection.py", line 644, in read_response
    response = self._parser.read_response(disable_decoding=disable_decoding)
  File "C:\Users\∞„∞„Àß\Desktop\mall\.venv\lib\site-packages\redis\_parsers\resp2.py", line 15, in read_response
    result = self._read_response(disable_decoding=disable_decoding)
  File "C:\Users\∞„∞„Àß\Desktop\mall\.venv\lib\site-packages\redis\_parsers\resp2.py", line 38, in _read_response
    raise error
redis.exceptions.AuthenticationError: Client sent AUTH, but no password is set
ERROR 2025-08-07 13:49:52,133 basehttp 212 "GET /verification/image/3fa85f64-5717-4562-b3fc-2c963f66afa6/ HTTP/1.1" 500 129665
ERROR 2025-08-07 13:54:39,501 log 246 Internal Server Error: /verification/image/3fa85f64-5717-4562-b3fc-2c963f66afa6/
Traceback (most recent call last):
  File "C:\Users\∞„∞„Àß\Desktop\mall\.venv\lib\site-packages\django\core\handlers\exception.py", line 55, in inner
    response = get_response(request)
  File "C:\Users\∞„∞„Àß\Desktop\mall\.venv\lib\site-packages\django\core\handlers\base.py", line 197, in _get_response
    response = wrapped_callback(request, *callback_args, **callback_kwargs)
  File "C:\Users\∞„∞„Àß\Desktop\mall\.venv\lib\site-packages\django\views\generic\base.py", line 105, in view
    return self.dispatch(request, *args, **kwargs)
  File "C:\Users\∞„∞„Àß\Desktop\mall\.venv\lib\site-packages\django\views\generic\base.py", line 144, in dispatch
    return handler(request, *args, **kwargs)
  File "C:\Users\∞„∞„Àß\Desktop\mall\mall\apps\verifications\views.py", line 17, in get
    redis_cli.setex(code, 100, text)
  File "C:\Users\∞„∞„Àß\Desktop\mall\.venv\lib\site-packages\redis\commands\core.py", line 2330, in setex
    return self.execute_command("SETEX", name, time, value)
  File "C:\Users\∞„∞„Àß\Desktop\mall\.venv\lib\site-packages\redis\client.py", line 623, in execute_command
    return self._execute_command(*args, **options)
  File "C:\Users\∞„∞„Àß\Desktop\mall\.venv\lib\site-packages\redis\client.py", line 634, in _execute_command
    return conn.retry.call_with_retry(
  File "C:\Users\∞„∞„Àß\Desktop\mall\.venv\lib\site-packages\redis\retry.py", line 87, in call_with_retry
    return do()
  File "C:\Users\∞„∞„Àß\Desktop\mall\.venv\lib\site-packages\redis\client.py", line 635, in <lambda>
    lambda: self._send_command_parse_response(
  File "C:\Users\∞„∞„Àß\Desktop\mall\.venv\lib\site-packages\redis\client.py", line 605, in _send_command_parse_response
    conn.send_command(*args, **options)
  File "C:\Users\∞„∞„Àß\Desktop\mall\.venv\lib\site-packages\redis\connection.py", line 609, in send_command
    self._command_packer.pack(*args),
  File "C:\Users\∞„∞„Àß\Desktop\mall\.venv\lib\site-packages\redis\connection.py", line 114, in pack
    for arg in map(self.encode, args):
  File "C:\Users\∞„∞„Àß\Desktop\mall\.venv\lib\site-packages\redis\_parsers\encoders.py", line 29, in encode
    raise DataError(
redis.exceptions.DataError: Invalid input of type: 'UUID'. Convert to a bytes, string, int or float first.
ERROR 2025-08-07 13:54:39,524 basehttp 212 "GET /verification/image/3fa85f64-5717-4562-b3fc-2c963f66afa6/ HTTP/1.1" 500 120928
INFO 2025-08-07 13:57:11,911 autoreload 667 Watching for file changes with StatReloader
INFO 2025-08-07 13:57:24,902 basehttp 212 "GET /verification/image/123/ HTTP/1.1" 200 1875
INFO 2025-08-07 14:05:50,870 autoreload 265 C:\Users\∞„∞„Àß\Desktop\mall\mall\apps\verifications\views.py changed, reloading.
INFO 2025-08-07 14:05:53,449 autoreload 667 Watching for file changes with StatReloader
INFO 2025-08-07 14:06:09,016 basehttp 212 "GET /verification/image/123/ HTTP/1.1" 200 2289
WARNING 2025-08-07 14:06:09,916 log 246 Not Found: /favicon.ico
WARNING 2025-08-07 14:06:09,919 basehttp 212 "GET /favicon.ico HTTP/1.1" 404 2326
INFO 2025-08-08 11:45:23,931 autoreload 667 Watching for file changes with StatReloader
ERROR 2025-08-08 11:46:28,659 log 246 Internal Server Error: /verification/image/123/
Traceback (most recent call last):
  File "C:\Users\∞„∞„Àß\Desktop\mall\.venv\lib\site-packages\redis\connection.py", line 385, in connect_check_health
    sock = self.retry.call_with_retry(
  File "C:\Users\∞„∞„Àß\Desktop\mall\.venv\lib\site-packages\redis\retry.py", line 87, in call_with_retry
    return do()
  File "C:\Users\∞„∞„Àß\Desktop\mall\.venv\lib\site-packages\redis\connection.py", line 386, in <lambda>
    lambda: self._connect(), lambda error: self.disconnect(error)
  File "C:\Users\∞„∞„Àß\Desktop\mall\.venv\lib\site-packages\redis\connection.py", line 797, in _connect
    raise err
  File "C:\Users\∞„∞„Àß\Desktop\mall\.venv\lib\site-packages\redis\connection.py", line 781, in _connect
    sock.connect(socket_address)
TimeoutError: [WinError 10060] ”…”⁄¡¨Ω”∑Ω‘⁄“ª∂Œ ±º‰∫Û√ª”–’˝»∑¥∏¥ªÚ¡¨Ω”µƒ÷˜ª˙√ª”–∑¥”¶£¨¡¨Ω”≥¢ ‘ ß∞‹°£

During handling of the above exception, another exception occurred:

Traceback (most recent call last):
  File "C:\Users\∞„∞„Àß\Desktop\mall\.venv\lib\site-packages\django\core\handlers\exception.py", line 55, in inner
    response = get_response(request)
  File "C:\Users\∞„∞„Àß\Desktop\mall\.venv\lib\site-packages\django\core\handlers\base.py", line 197, in _get_response
    response = wrapped_callback(request, *callback_args, **callback_kwargs)
  File "C:\Users\∞„∞„Àß\Desktop\mall\.venv\lib\site-packages\django\views\generic\base.py", line 105, in view
    return self.dispatch(request, *args, **kwargs)
  File "C:\Users\∞„∞„Àß\Desktop\mall\.venv\lib\site-packages\django\views\generic\base.py", line 144, in dispatch
    return handler(request, *args, **kwargs)
  File "C:\Users\∞„∞„Àß\Desktop\mall\mall\apps\verifications\views.py", line 17, in get
    redis_cli.setex(code, 100, text)
  File "C:\Users\∞„∞„Àß\Desktop\mall\.venv\lib\site-packages\redis\commands\core.py", line 2330, in setex
    return self.execute_command("SETEX", name, time, value)
  File "C:\Users\∞„∞„Àß\Desktop\mall\.venv\lib\site-packages\redis\client.py", line 623, in execute_command
    return self._execute_command(*args, **options)
  File "C:\Users\∞„∞„Àß\Desktop\mall\.venv\lib\site-packages\redis\client.py", line 629, in _execute_command
    conn = self.connection or pool.get_connection()
  File "C:\Users\∞„∞„Àß\Desktop\mall\.venv\lib\site-packages\redis\utils.py", line 191, in wrapper
    return func(*args, **kwargs)
  File "C:\Users\∞„∞„Àß\Desktop\mall\.venv\lib\site-packages\redis\connection.py", line 1530, in get_connection
    connection.connect()
  File "C:\Users\∞„∞„Àß\Desktop\mall\.venv\lib\site-packages\redis\connection.py", line 379, in connect
    self.connect_check_health(check_health=True)
  File "C:\Users\∞„∞„Àß\Desktop\mall\.venv\lib\site-packages\redis\connection.py", line 391, in connect_check_health
    raise ConnectionError(self._error_message(e))
redis.exceptions.ConnectionError: Error 10060 connecting to 192.168.31.128:6379. ”…”⁄¡¨Ω”∑Ω‘⁄“ª∂Œ ±º‰∫Û√ª”–’˝»∑¥∏¥ªÚ¡¨Ω”µƒ÷˜ª˙√ª”–∑¥”¶£¨¡¨Ω”≥¢ ‘ ß∞‹°£.
ERROR 2025-08-08 11:46:28,679 basehttp 212 "GET /verification/image/123/ HTTP/1.1" 500 133544
INFO 2025-08-08 11:48:10,204 basehttp 212 "GET /verification/image/123/ HTTP/1.1" 200 1033
INFO 2025-08-12 18:55:02,339 autoreload 667 Watching for file changes with StatReloader
ERROR 2025-08-12 18:55:54,657 log 246 Internal Server Error: /verification/image/123/
Traceback (most recent call last):
  File "C:\Users\∞„∞„Àß\Desktop\mall\.venv\lib\site-packages\redis\connection.py", line 385, in connect_check_health
    sock = self.retry.call_with_retry(
  File "C:\Users\∞„∞„Àß\Desktop\mall\.venv\lib\site-packages\redis\retry.py", line 87, in call_with_retry
    return do()
  File "C:\Users\∞„∞„Àß\Desktop\mall\.venv\lib\site-packages\redis\connection.py", line 386, in <lambda>
    lambda: self._connect(), lambda error: self.disconnect(error)
  File "C:\Users\∞„∞„Àß\Desktop\mall\.venv\lib\site-packages\redis\connection.py", line 797, in _connect
    raise err
  File "C:\Users\∞„∞„Àß\Desktop\mall\.venv\lib\site-packages\redis\connection.py", line 781, in _connect
    sock.connect(socket_address)
TimeoutError: [WinError 10060] ”…”⁄¡¨Ω”∑Ω‘⁄“ª∂Œ ±º‰∫Û√ª”–’˝»∑¥∏¥ªÚ¡¨Ω”µƒ÷˜ª˙√ª”–∑¥”¶£¨¡¨Ω”≥¢ ‘ ß∞‹°£

During handling of the above exception, another exception occurred:

Traceback (most recent call last):
  File "C:\Users\∞„∞„Àß\Desktop\mall\.venv\lib\site-packages\django\core\handlers\exception.py", line 55, in inner
    response = get_response(request)
  File "C:\Users\∞„∞„Àß\Desktop\mall\.venv\lib\site-packages\django\core\handlers\base.py", line 197, in _get_response
    response = wrapped_callback(request, *callback_args, **callback_kwargs)
  File "C:\Users\∞„∞„Àß\Desktop\mall\.venv\lib\site-packages\django\views\generic\base.py", line 105, in view
    return self.dispatch(request, *args, **kwargs)
  File "C:\Users\∞„∞„Àß\Desktop\mall\.venv\lib\site-packages\django\views\generic\base.py", line 144, in dispatch
    return handler(request, *args, **kwargs)
  File "C:\Users\∞„∞„Àß\Desktop\mall\mall\apps\verifications\views.py", line 17, in get
    redis_cli.setex(code, 100, text)
  File "C:\Users\∞„∞„Àß\Desktop\mall\.venv\lib\site-packages\redis\commands\core.py", line 2330, in setex
    return self.execute_command("SETEX", name, time, value)
  File "C:\Users\∞„∞„Àß\Desktop\mall\.venv\lib\site-packages\redis\client.py", line 623, in execute_command
    return self._execute_command(*args, **options)
  File "C:\Users\∞„∞„Àß\Desktop\mall\.venv\lib\site-packages\redis\client.py", line 629, in _execute_command
    conn = self.connection or pool.get_connection()
  File "C:\Users\∞„∞„Àß\Desktop\mall\.venv\lib\site-packages\redis\utils.py", line 191, in wrapper
    return func(*args, **kwargs)
  File "C:\Users\∞„∞„Àß\Desktop\mall\.venv\lib\site-packages\redis\connection.py", line 1530, in get_connection
    connection.connect()
  File "C:\Users\∞„∞„Àß\Desktop\mall\.venv\lib\site-packages\redis\connection.py", line 379, in connect
    self.connect_check_health(check_health=True)
  File "C:\Users\∞„∞„Àß\Desktop\mall\.venv\lib\site-packages\redis\connection.py", line 391, in connect_check_health
    raise ConnectionError(self._error_message(e))
redis.exceptions.ConnectionError: Error 10060 connecting to 192.168.31.128:6379. ”…”⁄¡¨Ω”∑Ω‘⁄“ª∂Œ ±º‰∫Û√ª”–’˝»∑¥∏¥ªÚ¡¨Ω”µƒ÷˜ª˙√ª”–∑¥”¶£¨¡¨Ω”≥¢ ‘ ß∞‹°£.
ERROR 2025-08-12 18:55:54,677 basehttp 212 "GET /verification/image/123/ HTTP/1.1" 500 134398
INFO 2025-08-12 19:06:38,122 basehttp 212 "POST /user/register/ HTTP/1.1" 200 57
ERROR 2025-08-12 19:51:46,470 log 246 Internal Server Error: /verification/image/123/
Traceback (most recent call last):
  File "C:\Users\∞„∞„Àß\Desktop\mall\.venv\lib\site-packages\redis\connection.py", line 385, in connect_check_health
    sock = self.retry.call_with_retry(
  File "C:\Users\∞„∞„Àß\Desktop\mall\.venv\lib\site-packages\redis\retry.py", line 87, in call_with_retry
    return do()
  File "C:\Users\∞„∞„Àß\Desktop\mall\.venv\lib\site-packages\redis\connection.py", line 386, in <lambda>
    lambda: self._connect(), lambda error: self.disconnect(error)
  File "C:\Users\∞„∞„Àß\Desktop\mall\.venv\lib\site-packages\redis\connection.py", line 797, in _connect
    raise err
  File "C:\Users\∞„∞„Àß\Desktop\mall\.venv\lib\site-packages\redis\connection.py", line 781, in _connect
    sock.connect(socket_address)
TimeoutError: [WinError 10060] ”…”⁄¡¨Ω”∑Ω‘⁄“ª∂Œ ±º‰∫Û√ª”–’˝»∑¥∏¥ªÚ¡¨Ω”µƒ÷˜ª˙√ª”–∑¥”¶£¨¡¨Ω”≥¢ ‘ ß∞‹°£

During handling of the above exception, another exception occurred:

Traceback (most recent call last):
  File "C:\Users\∞„∞„Àß\Desktop\mall\.venv\lib\site-packages\django\core\handlers\exception.py", line 55, in inner
    response = get_response(request)
  File "C:\Users\∞„∞„Àß\Desktop\mall\.venv\lib\site-packages\django\core\handlers\base.py", line 197, in _get_response
    response = wrapped_callback(request, *callback_args, **callback_kwargs)
  File "C:\Users\∞„∞„Àß\Desktop\mall\.venv\lib\site-packages\django\views\generic\base.py", line 105, in view
    return self.dispatch(request, *args, **kwargs)
  File "C:\Users\∞„∞„Àß\Desktop\mall\.venv\lib\site-packages\django\views\generic\base.py", line 144, in dispatch
    return handler(request, *args, **kwargs)
  File "C:\Users\∞„∞„Àß\Desktop\mall\mall\apps\verifications\views.py", line 17, in get
    redis_cli.setex(code, 100, text)
  File "C:\Users\∞„∞„Àß\Desktop\mall\.venv\lib\site-packages\redis\commands\core.py", line 2330, in setex
    return self.execute_command("SETEX", name, time, value)
  File "C:\Users\∞„∞„Àß\Desktop\mall\.venv\lib\site-packages\redis\client.py", line 623, in execute_command
    return self._execute_command(*args, **options)
  File "C:\Users\∞„∞„Àß\Desktop\mall\.venv\lib\site-packages\redis\client.py", line 629, in _execute_command
    conn = self.connection or pool.get_connection()
  File "C:\Users\∞„∞„Àß\Desktop\mall\.venv\lib\site-packages\redis\utils.py", line 191, in wrapper
    return func(*args, **kwargs)
  File "C:\Users\∞„∞„Àß\Desktop\mall\.venv\lib\site-packages\redis\connection.py", line 1530, in get_connection
    connection.connect()
  File "C:\Users\∞„∞„Àß\Desktop\mall\.venv\lib\site-packages\redis\connection.py", line 379, in connect
    self.connect_check_health(check_health=True)
  File "C:\Users\∞„∞„Àß\Desktop\mall\.venv\lib\site-packages\redis\connection.py", line 391, in connect_check_health
    raise ConnectionError(self._error_message(e))
redis.exceptions.ConnectionError: Error 10060 connecting to 192.168.31.128:6379. ”…”⁄¡¨Ω”∑Ω‘⁄“ª∂Œ ±º‰∫Û√ª”–’˝»∑¥∏¥ªÚ¡¨Ω”µƒ÷˜ª˙√ª”–∑¥”¶£¨¡¨Ω”≥¢ ‘ ß∞‹°£.
ERROR 2025-08-12 19:51:46,502 basehttp 212 "GET /verification/image/123/ HTTP/1.1" 500 134458
INFO 2025-08-12 19:52:33,086 autoreload 265 C:\Users\∞„∞„Àß\Desktop\mall\mall\mall\settings.py changed, reloading.
INFO 2025-08-12 19:52:37,796 autoreload 667 Watching for file changes with StatReloader
INFO 2025-08-12 19:52:57,951 autoreload 265 C:\Users\∞„∞„Àß\Desktop\mall\mall\mall\settings.py changed, reloading.
INFO 2025-08-12 19:53:01,091 autoreload 667 Watching for file changes with StatReloader
INFO 2025-08-12 19:53:07,344 basehttp 212 "GET /verification/image/123/ HTTP/1.1" 200 1365
INFO 2025-08-13 18:46:07,366 autoreload 667 Watching for file changes with StatReloader
INFO 2025-08-13 18:46:15,687 basehttp 212 "GET /image_codes/123/ HTTP/1.1" 200 1787
WARNING 2025-08-13 18:46:40,488 log 246 Not Found: /sms_codes/18126106878
WARNING 2025-08-13 18:46:40,489 basehttp 212 "GET /sms_codes/18126106878?image_code=OHJ6&image_code_id=123 HTTP/1.1" 404 2686
WARNING 2025-08-13 18:59:48,951 log 246 Not Found: /sms_codes/18126106878
WARNING 2025-08-13 18:59:48,955 basehttp 212 "GET /sms_codes/18126106878?image_code=OHJ6&image_code_id=123 HTTP/1.1" 404 2686
INFO 2025-08-13 19:01:02,141 autoreload 265 C:\Users\∞„∞„Àß\Desktop\mall\mall\mall\urls.py changed, reloading.
INFO 2025-08-13 19:01:04,566 autoreload 667 Watching for file changes with StatReloader
WARNING 2025-08-13 19:01:06,577 log 246 Not Found: /sms_codes/18126106878
WARNING 2025-08-13 19:01:06,579 basehttp 212 "GET /sms_codes/18126106878?image_code=OHJ6&image_code_id=123 HTTP/1.1" 404 2382
INFO 2025-08-13 19:01:28,037 autoreload 265 C:\Users\∞„∞„Àß\Desktop\mall\mall\mall\urls.py changed, reloading.
INFO 2025-08-13 19:01:29,779 autoreload 667 Watching for file changes with StatReloader
INFO 2025-08-13 19:01:33,903 basehttp 212 "GET /image_codes/123/ HTTP/1.1" 200 1440
INFO 2025-08-13 19:02:48,648 autoreload 265 C:\Users\∞„∞„Àß\Desktop\mall\mall\apps\verifications\urls.py changed, reloading.
INFO 2025-08-13 19:02:50,206 autoreload 667 Watching for file changes with StatReloader
WARNING 2025-08-13 19:03:06,359 log 246 Not Found: /sms_codes/18126106878
WARNING 2025-08-13 19:03:06,362 basehttp 212 "GET /sms_codes/18126106878?image_code=JNYA&image_code_id=123 HTTP/1.1" 404 2646
INFO 2025-08-13 19:05:52,006 autoreload 265 C:\Users\∞„∞„Àß\Desktop\mall\mall\apps\verifications\converters.py changed, reloading.
INFO 2025-08-13 19:05:54,186 autoreload 667 Watching for file changes with StatReloader
INFO 2025-08-13 19:06:03,796 basehttp 212 "GET /sms_codes/18126106878?image_code=JNYA&image_code_id=123 HTTP/1.1" 301 0
INFO 2025-08-13 19:06:03,901 basehttp 212 "GET /sms_codes/18126106878/?image_code=JNYA&image_code_id=123 HTTP/1.1" 200 75
INFO 2025-08-13 19:06:11,088 basehttp 212 "GET /image_codes/123/ HTTP/1.1" 200 1398
INFO 2025-08-13 19:06:19,666 basehttp 212 "GET /sms_codes/18126106878?image_code=XPHP&image_code_id=123 HTTP/1.1" 301 0
INFO 2025-08-13 19:06:19,677 basehttp 212 "GET /sms_codes/18126106878/?image_code=XPHP&image_code_id=123 HTTP/1.1" 200 69
INFO 2025-08-13 19:06:31,498 basehttp 212 "GET /image_codes/123/ HTTP/1.1" 200 1453
INFO 2025-08-13 19:06:35,533 basehttp 212 "GET /sms_codes/18126106878?image_code=XPHP&image_code_id=123 HTTP/1.1" 301 0
INFO 2025-08-13 19:06:35,544 basehttp 212 "GET /sms_codes/18126106878/?image_code=XPHP&image_code_id=123 HTTP/1.1" 200 69
INFO 2025-08-13 19:06:48,148 basehttp 212 "GET /sms_codes/18126106878?image_code=Z25H&image_code_id=123 HTTP/1.1" 301 0
INFO 2025-08-13 19:06:48,159 basehttp 212 "GET /sms_codes/18126106878/?image_code=Z25H&image_code_id=123 HTTP/1.1" 200 69
INFO 2025-08-13 19:08:17,944 basehttp 212 "GET /sms_codes/18126106878?image_code=Z25H&image_code_id=123 HTTP/1.1" 301 0
INFO 2025-08-13 19:08:17,981 basehttp 212 "GET /sms_codes/18126106878/?image_code=Z25H&image_code_id=123 HTTP/1.1" 200 75
INFO 2025-08-13 19:10:36,861 autoreload 265 C:\Users\∞„∞„Àß\Desktop\mall\mall\apps\verifications\views.py changed, reloading.
INFO 2025-08-13 19:10:39,522 autoreload 667 Watching for file changes with StatReloader
INFO 2025-08-13 19:10:46,719 basehttp 212 "GET /image_codes/123/ HTTP/1.1" 200 1787
WARNING 2025-08-13 19:11:01,787 log 246 Not Found: /sms_codes/18126106878
WARNING 2025-08-13 19:11:01,800 basehttp 212 "GET /sms_codes/18126106878?image_code=XKVE&image_code_id=123 HTTP/1.1" 404 2646
INFO 2025-08-13 19:13:49,409 autoreload 265 C:\Users\∞„∞„Àß\Desktop\mall\mall\apps\verifications\converters.py changed, reloading.
INFO 2025-08-13 19:13:51,907 autoreload 667 Watching for file changes with StatReloader
WARNING 2025-08-13 19:13:57,317 log 246 Not Found: /sms_codes/18126106878
WARNING 2025-08-13 19:13:57,319 basehttp 212 "GET /sms_codes/18126106878?image_code=XKVE&image_code_id=123 HTTP/1.1" 404 2646
INFO 2025-08-13 19:14:40,502 autoreload 265 C:\Users\∞„∞„Àß\Desktop\mall\mall\apps\verifications\converters.py changed, reloading.
INFO 2025-08-13 19:14:44,348 autoreload 667 Watching for file changes with StatReloader
WARNING 2025-08-13 19:14:48,559 log 246 Not Found: /sms_codes/18126106878
WARNING 2025-08-13 19:14:48,561 basehttp 212 "GET /sms_codes/18126106878?image_code=XKVE&image_code_id=123 HTTP/1.1" 404 2646
INFO 2025-08-13 19:15:02,381 autoreload 265 C:\Users\∞„∞„Àß\Desktop\mall\mall\apps\verifications\converters.py changed, reloading.
INFO 2025-08-13 19:15:04,701 autoreload 667 Watching for file changes with StatReloader
INFO 2025-08-13 19:15:08,335 basehttp 212 "GET /sms_codes/18126106878?image_code=XKVE&image_code_id=123 HTTP/1.1" 301 0
INFO 2025-08-13 19:15:08,504 basehttp 212 "GET /sms_codes/18126106878/?image_code=XKVE&image_code_id=123 HTTP/1.1" 200 75
INFO 2025-08-13 19:15:27,190 autoreload 265 C:\Users\∞„∞„Àß\Desktop\mall\mall\apps\verifications\converters.py changed, reloading.
INFO 2025-08-13 19:15:29,005 autoreload 667 Watching for file changes with StatReloader
INFO 2025-08-13 19:15:34,259 basehttp 212 "GET /image_codes/123/ HTTP/1.1" 200 1734
INFO 2025-08-13 19:15:54,751 basehttp 212 "GET /sms_codes/18126106878?image_code=S78S&image_code_id=123 HTTP/1.1" 301 0
INFO 2025-08-13 19:15:54,769 basehttp 212 "GET /sms_codes/18126106878/?image_code=S78S&image_code_id=123 HTTP/1.1" 200 69
INFO 2025-08-13 19:17:43,491 autoreload 265 C:\Users\∞„∞„Àß\Desktop\mall\mall\apps\verifications\views.py changed, reloading.
INFO 2025-08-13 19:17:46,289 autoreload 667 Watching for file changes with StatReloader
INFO 2025-08-13 19:17:52,987 basehttp 212 "GET /image_codes/123/ HTTP/1.1" 200 1495
INFO 2025-08-13 19:18:02,609 basehttp 212 "GET /sms_codes/18126106878?image_code=5b7p&image_code_id=123 HTTP/1.1" 301 0
INFO 2025-08-13 19:18:03,079 basehttp 212 "GET /sms_codes/18126106878/?image_code=5b7p&image_code_id=123 HTTP/1.1" 200 27
INFO 2025-08-14 19:00:50,339 autoreload 667 Watching for file changes with StatReloader
INFO 2025-08-14 19:01:26,677 basehttp 212 "GET /image_codes/123/ HTTP/1.1" 200 1353
INFO 2025-08-14 19:01:41,516 basehttp 212 "GET /sms_codes/18126106878?image_code=p2tb&image_code_id=123 HTTP/1.1" 301 0
INFO 2025-08-14 19:01:41,876 basehttp 212 "GET /sms_codes/18126106878/?image_code=p2tb&image_code_id=123 HTTP/1.1" 200 27
INFO 2025-08-14 19:01:50,736 basehttp 212 "GET /sms_codes/18126106878?image_code=p2tk&image_code_id=123 HTTP/1.1" 301 0
INFO 2025-08-14 19:01:50,747 basehttp 212 "GET /sms_codes/18126106878/?image_code=p2tk&image_code_id=123 HTTP/1.1" 200 69
INFO 2025-08-14 19:02:06,207 basehttp 212 "GET /sms_codes/18126106878?image_code=p2tb&image_code_id=123 HTTP/1.1" 301 0
INFO 2025-08-14 19:02:06,225 basehttp 212 "GET /sms_codes/18126106878/?image_code=p2tb&image_code_id=123 HTTP/1.1" 200 63
INFO 2025-08-14 19:02:47,230 autoreload 265 C:\Users\∞„∞„Àß\Desktop\mall\mall\apps\verifications\views.py changed, reloading.
INFO 2025-08-14 19:02:50,515 autoreload 667 Watching for file changes with StatReloader
INFO 2025-08-15 14:37:44,842 autoreload 667 Watching for file changes with StatReloader
INFO 2025-08-15 14:51:21,458 basehttp 212 "POST /user/register/ HTTP/1.1" 200 65
INFO 2025-08-15 14:52:06,419 autoreload 265 C:\Users\∞„∞„Àß\Desktop\mall\mall\apps\users\models.py changed, reloading.
INFO 2025-08-15 14:52:30,325 autoreload 667 Watching for file changes with StatReloader
ERROR 2025-08-15 14:52:56,775 log 246 Internal Server Error: /user/register/
Traceback (most recent call last):
  File "C:\Users\∞„∞„Àß\Desktop\mall\.venv\lib\site-packages\django_redis\cache.py", line 29, in _decorator
    return method(self, *args, **kwargs)
  File "C:\Users\∞„∞„Àß\Desktop\mall\.venv\lib\site-packages\django_redis\cache.py", line 138, in has_key
    return self.client.has_key(*args, **kwargs)
  File "C:\Users\∞„∞„Àß\Desktop\mall\.venv\lib\site-packages\django_redis\client\default.py", line 740, in has_key
    raise ConnectionInterrupted(connection=client) from e
django_redis.exceptions.ConnectionInterrupted: Redis ConnectionError: Error 10060 connecting to 192.168.234.128:6379. ”…”⁄¡¨Ω”∑Ω‘⁄“ª∂Œ ±º‰∫Û√ª”–’˝»∑¥∏¥ªÚ¡¨Ω”µƒ÷˜ª˙√ª”–∑¥”¶£¨¡¨Ω”≥¢ ‘ ß∞‹°£.

During handling of the above exception, another exception occurred:

Traceback (most recent call last):
  File "C:\Users\∞„∞„Àß\Desktop\mall\.venv\lib\site-packages\django\core\handlers\exception.py", line 55, in inner
    response = get_response(request)
  File "C:\Users\∞„∞„Àß\Desktop\mall\.venv\lib\site-packages\django\core\handlers\base.py", line 197, in _get_response
    response = wrapped_callback(request, *callback_args, **callback_kwargs)
  File "C:\Users\∞„∞„Àß\Desktop\mall\.venv\lib\site-packages\django\views\generic\base.py", line 105, in view
    return self.dispatch(request, *args, **kwargs)
  File "C:\Users\∞„∞„Àß\Desktop\mall\.venv\lib\site-packages\django\views\generic\base.py", line 144, in dispatch
    return handler(request, *args, **kwargs)
  File "C:\Users\∞„∞„Àß\Desktop\mall\mall\apps\users\views.py", line 49, in post
    login(request, user)
  File "C:\Users\∞„∞„Àß\Desktop\mall\.venv\lib\site-packages\django\contrib\auth\__init__.py", line 118, in login
    request.session.cycle_key()
  File "C:\Users\∞„∞„Àß\Desktop\mall\.venv\lib\site-packages\django\contrib\sessions\backends\base.py", line 304, in cycle_key
    self.create()
  File "C:\Users\∞„∞„Àß\Desktop\mall\.venv\lib\site-packages\django\contrib\sessions\backends\cache.py", line 42, in create
    self._session_key = self._get_new_session_key()
  File "C:\Users\∞„∞„Àß\Desktop\mall\.venv\lib\site-packages\django\contrib\sessions\backends\base.py", line 150, in _get_new_session_key
    if not self.exists(session_key):
  File "C:\Users\∞„∞„Àß\Desktop\mall\.venv\lib\site-packages\django\contrib\sessions\backends\cache.py", line 73, in exists
    bool(session_key) and (self.cache_key_prefix + session_key) in self._cache
  File "C:\Users\∞„∞„Àß\Desktop\mall\.venv\lib\site-packages\django\core\cache\backends\base.py", line 299, in __contains__
    return self.has_key(key)
  File "C:\Users\∞„∞„Àß\Desktop\mall\.venv\lib\site-packages\django_redis\cache.py", line 36, in _decorator
    raise e.__cause__  # noqa: B904
  File "C:\Users\∞„∞„Àß\Desktop\mall\.venv\lib\site-packages\django_redis\client\default.py", line 738, in has_key
    return client.exists(key) == 1
  File "C:\Users\∞„∞„Àß\Desktop\mall\.venv\lib\site-packages\redis\commands\core.py", line 1736, in exists
    return self.execute_command("EXISTS", *names, keys=names)
  File "C:\Users\∞„∞„Àß\Desktop\mall\.venv\lib\site-packages\redis\client.py", line 623, in execute_command
    return self._execute_command(*args, **options)
  File "C:\Users\∞„∞„Àß\Desktop\mall\.venv\lib\site-packages\redis\client.py", line 629, in _execute_command
    conn = self.connection or pool.get_connection()
  File "C:\Users\∞„∞„Àß\Desktop\mall\.venv\lib\site-packages\redis\utils.py", line 191, in wrapper
    return func(*args, **kwargs)
  File "C:\Users\∞„∞„Àß\Desktop\mall\.venv\lib\site-packages\redis\connection.py", line 1530, in get_connection
    connection.connect()
  File "C:\Users\∞„∞„Àß\Desktop\mall\.venv\lib\site-packages\redis\connection.py", line 379, in connect
    self.connect_check_health(check_health=True)
  File "C:\Users\∞„∞„Àß\Desktop\mall\.venv\lib\site-packages\redis\connection.py", line 391, in connect_check_health
    raise ConnectionError(self._error_message(e))
redis.exceptions.ConnectionError: Error 10060 connecting to 192.168.234.128:6379. ”…”⁄¡¨Ω”∑Ω‘⁄“ª∂Œ ±º‰∫Û√ª”–’˝»∑¥∏¥ªÚ¡¨Ω”µƒ÷˜ª˙√ª”–∑¥”¶£¨¡¨Ω”≥¢ ‘ ß∞‹°£.
ERROR 2025-08-15 14:52:56,795 basehttp 212 "POST /user/register/ HTTP/1.1" 500 153147
INFO 2025-08-15 15:07:46,944 basehttp 212 "POST /user/register/ HTTP/1.1" 200 57
INFO 2025-08-15 15:10:16,580 autoreload 265 C:\Users\∞„∞„Àß\Desktop\mall\mall\apps\users\views.py changed, reloading.
INFO 2025-08-15 15:10:19,223 autoreload 667 Watching for file changes with StatReloader
INFO 2025-08-15 15:10:33,392 autoreload 265 C:\Users\∞„∞„Àß\Desktop\mall\mall\apps\users\views.py changed, reloading.
INFO 2025-08-15 15:10:38,120 autoreload 667 Watching for file changes with StatReloader
INFO 2025-08-15 15:11:07,553 autoreload 265 C:\Users\∞„∞„Àß\Desktop\mall\mall\apps\users\views.py changed, reloading.
INFO 2025-08-15 15:11:09,485 autoreload 667 Watching for file changes with StatReloader
INFO 2025-08-15 15:11:51,397 autoreload 265 C:\Users\∞„∞„Àß\Desktop\mall\mall\apps\users\views.py changed, reloading.
INFO 2025-08-15 15:11:54,527 autoreload 667 Watching for file changes with StatReloader
INFO 2025-08-15 15:13:11,298 autoreload 265 C:\Users\∞„∞„Àß\Desktop\mall\mall\apps\users\views.py changed, reloading.
INFO 2025-08-15 15:13:13,951 autoreload 667 Watching for file changes with StatReloader
INFO 2025-08-15 15:13:32,664 autoreload 265 C:\Users\∞„∞„Àß\Desktop\mall\mall\apps\users\views.py changed, reloading.
INFO 2025-08-15 15:13:34,631 autoreload 667 Watching for file changes with StatReloader
INFO 2025-08-15 15:14:14,846 autoreload 265 C:\Users\∞„∞„Àß\Desktop\mall\mall\apps\users\views.py changed, reloading.
INFO 2025-08-15 15:14:17,413 autoreload 667 Watching for file changes with StatReloader
INFO 2025-08-15 15:14:39,165 autoreload 265 C:\Users\∞„∞„Àß\Desktop\mall\mall\apps\users\views.py changed, reloading.
INFO 2025-08-15 15:14:41,277 autoreload 667 Watching for file changes with StatReloader
INFO 2025-08-15 15:14:59,059 autoreload 265 C:\Users\∞„∞„Àß\Desktop\mall\mall\apps\users\views.py changed, reloading.
INFO 2025-08-15 15:15:00,774 autoreload 667 Watching for file changes with StatReloader
INFO 2025-08-15 15:15:56,212 autoreload 265 C:\Users\∞„∞„Àß\Desktop\mall\mall\apps\users\views.py changed, reloading.
INFO 2025-08-15 15:15:58,414 autoreload 667 Watching for file changes with StatReloader
INFO 2025-08-15 15:16:58,232 autoreload 265 C:\Users\∞„∞„Àß\Desktop\mall\mall\apps\users\views.py changed, reloading.
INFO 2025-08-15 15:17:00,965 autoreload 667 Watching for file changes with StatReloader
INFO 2025-08-15 15:17:07,215 autoreload 265 C:\Users\∞„∞„Àß\Desktop\mall\mall\apps\users\views.py changed, reloading.
INFO 2025-08-15 15:17:09,097 autoreload 667 Watching for file changes with StatReloader
INFO 2025-08-15 15:24:42,802 basehttp 212 "GET /image_codes/123/ HTTP/1.1" 200 1842
INFO 2025-08-15 15:24:59,871 basehttp 212 "GET /sms_codes/18126106878?image_code=b7x8&image_code_id=123 HTTP/1.1" 301 0
ERROR 2025-08-15 15:25:04,679 log 246 Internal Server Error: /sms_codes/18126106878/
Traceback (most recent call last):
  File "C:\Users\∞„∞„Àß\Desktop\mall\.venv\lib\site-packages\kombu\utils\functional.py", line 32, in __call__
    return self.__value__
AttributeError: 'ChannelPromise' object has no attribute '__value__'

During handling of the above exception, another exception occurred:

Traceback (most recent call last):
  File "C:\Users\∞„∞„Àß\Desktop\mall\.venv\lib\site-packages\kombu\transport\virtual\base.py", line 951, in create_channel
    return self._avail_channels.pop()
IndexError: pop from empty list

During handling of the above exception, another exception occurred:

Traceback (most recent call last):
  File "C:\Users\∞„∞„Àß\Desktop\mall\.venv\lib\site-packages\redis\connection.py", line 385, in connect_check_health
    sock = self.retry.call_with_retry(
  File "C:\Users\∞„∞„Àß\Desktop\mall\.venv\lib\site-packages\redis\retry.py", line 87, in call_with_retry
    return do()
  File "C:\Users\∞„∞„Àß\Desktop\mall\.venv\lib\site-packages\redis\connection.py", line 386, in <lambda>
    lambda: self._connect(), lambda error: self.disconnect(error)
  File "C:\Users\∞„∞„Àß\Desktop\mall\.venv\lib\site-packages\redis\connection.py", line 797, in _connect
    raise err
  File "C:\Users\∞„∞„Àß\Desktop\mall\.venv\lib\site-packages\redis\connection.py", line 781, in _connect
    sock.connect(socket_address)
ConnectionRefusedError: [WinError 10061] ”…”⁄ƒø±Íº∆À„ª˙ª˝º´æ‹æ¯£¨Œﬁ∑®¡¨Ω”°£

During handling of the above exception, another exception occurred:

Traceback (most recent call last):
  File "C:\Users\∞„∞„Àß\Desktop\mall\.venv\lib\site-packages\kombu\connection.py", line 472, in _reraise_as_library_errors
    yield
  File "C:\Users\∞„∞„Àß\Desktop\mall\.venv\lib\site-packages\kombu\connection.py", line 459, in _ensure_connection
    return retry_over_time(
  File "C:\Users\∞„∞„Àß\Desktop\mall\.venv\lib\site-packages\kombu\utils\functional.py", line 318, in retry_over_time
    return fun(*args, **kwargs)
  File "C:\Users\∞„∞„Àß\Desktop\mall\.venv\lib\site-packages\kombu\connection.py", line 938, in _connection_factory
    self._connection = self._establish_connection()
  File "C:\Users\∞„∞„Àß\Desktop\mall\.venv\lib\site-packages\kombu\connection.py", line 860, in _establish_connection
    conn = self.transport.establish_connection()
  File "C:\Users\∞„∞„Àß\Desktop\mall\.venv\lib\site-packages\kombu\transport\virtual\base.py", line 975, in establish_connection
    self._avail_channels.append(self.create_channel(self))
  File "C:\Users\∞„∞„Àß\Desktop\mall\.venv\lib\site-packages\kombu\transport\virtual\base.py", line 953, in create_channel
    channel = self.Channel(connection)
  File "C:\Users\∞„∞„Àß\Desktop\mall\.venv\lib\site-packages\kombu\transport\redis.py", line 751, in __init__
    self.client.ping()
  File "C:\Users\∞„∞„Àß\Desktop\mall\.venv\lib\site-packages\redis\commands\core.py", line 1219, in ping
    return self.execute_command("PING", **kwargs)
  File "C:\Users\∞„∞„Àß\Desktop\mall\.venv\lib\site-packages\redis\client.py", line 623, in execute_command
    return self._execute_command(*args, **options)
  File "C:\Users\∞„∞„Àß\Desktop\mall\.venv\lib\site-packages\redis\client.py", line 629, in _execute_command
    conn = self.connection or pool.get_connection()
  File "C:\Users\∞„∞„Àß\Desktop\mall\.venv\lib\site-packages\redis\utils.py", line 191, in wrapper
    return func(*args, **kwargs)
  File "C:\Users\∞„∞„Àß\Desktop\mall\.venv\lib\site-packages\redis\connection.py", line 1530, in get_connection
    connection.connect()
  File "C:\Users\∞„∞„Àß\Desktop\mall\.venv\lib\site-packages\redis\connection.py", line 379, in connect
    self.connect_check_health(check_health=True)
  File "C:\Users\∞„∞„Àß\Desktop\mall\.venv\lib\site-packages\redis\connection.py", line 391, in connect_check_health
    raise ConnectionError(self._error_message(e))
redis.exceptions.ConnectionError: Error 10061 connecting to localhost:6379. ”…”⁄ƒø±Íº∆À„ª˙ª˝º´æ‹æ¯£¨Œﬁ∑®¡¨Ω”°£.

The above exception was the direct cause of the following exception:

Traceback (most recent call last):
  File "C:\Users\∞„∞„Àß\Desktop\mall\.venv\lib\site-packages\django\core\handlers\exception.py", line 55, in inner
    response = get_response(request)
  File "C:\Users\∞„∞„Àß\Desktop\mall\.venv\lib\site-packages\django\core\handlers\base.py", line 197, in _get_response
    response = wrapped_callback(request, *callback_args, **callback_kwargs)
  File "C:\Users\∞„∞„Àß\Desktop\mall\.venv\lib\site-packages\django\views\generic\base.py", line 105, in view
    return self.dispatch(request, *args, **kwargs)
  File "C:\Users\∞„∞„Àß\Desktop\mall\.venv\lib\site-packages\django\views\generic\base.py", line 144, in dispatch
    return handler(request, *args, **kwargs)
  File "C:\Users\∞„∞„Àß\Desktop\mall\mall\apps\verifications\views.py", line 51, in get
    celery_send_sms_code.delay(mobile, sms_code)
  File "C:\Users\∞„∞„Àß\Desktop\mall\.venv\lib\site-packages\celery\app\task.py", line 444, in delay
    return self.apply_async(args, kwargs)
  File "C:\Users\∞„∞„Àß\Desktop\mall\.venv\lib\site-packages\celery\app\task.py", line 601, in apply_async
    return app.send_task(
  File "C:\Users\∞„∞„Àß\Desktop\mall\.venv\lib\site-packages\celery\app\base.py", line 930, in send_task
    amqp.send_task_message(P, name, message, **options)
  File "C:\Users\∞„∞„Àß\Desktop\mall\.venv\lib\site-packages\celery\app\amqp.py", line 523, in send_task_message
    ret = producer.publish(
  File "C:\Users\∞„∞„Àß\Desktop\mall\.venv\lib\site-packages\kombu\messaging.py", line 190, in publish
    return _publish(
  File "C:\Users\∞„∞„Àß\Desktop\mall\.venv\lib\site-packages\kombu\connection.py", line 556, in _ensured
    return fun(*args, **kwargs)
  File "C:\Users\∞„∞„Àß\Desktop\mall\.venv\lib\site-packages\kombu\messaging.py", line 200, in _publish
    channel = self.channel
  File "C:\Users\∞„∞„Àß\Desktop\mall\.venv\lib\site-packages\kombu\messaging.py", line 224, in _get_channel
    channel = self._channel = channel()
  File "C:\Users\∞„∞„Àß\Desktop\mall\.venv\lib\site-packages\kombu\utils\functional.py", line 34, in __call__
    value = self.__value__ = self.__contract__()
  File "C:\Users\∞„∞„Àß\Desktop\mall\.venv\lib\site-packages\kombu\messaging.py", line 240, in <lambda>
    channel = ChannelPromise(lambda: connection.default_channel)
  File "C:\Users\∞„∞„Àß\Desktop\mall\.venv\lib\site-packages\kombu\connection.py", line 957, in default_channel
    self._ensure_connection(**conn_opts)
  File "C:\Users\∞„∞„Àß\Desktop\mall\.venv\lib\site-packages\kombu\connection.py", line 459, in _ensure_connection
    return retry_over_time(
  File "C:\Users\∞„∞„Àß\AppData\Local\Programs\Python\Python39\lib\contextlib.py", line 137, in __exit__
    self.gen.throw(typ, value, traceback)
  File "C:\Users\∞„∞„Àß\Desktop\mall\.venv\lib\site-packages\kombu\connection.py", line 476, in _reraise_as_library_errors
    raise ConnectionError(str(exc)) from exc
kombu.exceptions.OperationalError: Error 10061 connecting to localhost:6379. ”…”⁄ƒø±Íº∆À„ª˙ª˝º´æ‹æ¯£¨Œﬁ∑®¡¨Ω”°£.
ERROR 2025-08-15 15:25:04,714 basehttp 212 "GET /sms_codes/18126106878/?image_code=b7x8&image_code_id=123 HTTP/1.1" 500 268987
INFO 2025-08-15 15:26:00,923 basehttp 212 "GET /image_codes/123/ HTTP/1.1" 200 1787
INFO 2025-08-15 15:26:13,089 basehttp 212 "GET /sms_codes/18126106878?image_code=a25k&image_code_id=123 HTTP/1.1" 301 0
INFO 2025-08-15 15:26:13,103 basehttp 212 "GET /sms_codes/18126106878/?image_code=a25k&image_code_id=123 HTTP/1.1" 200 63
INFO 2025-08-15 15:26:22,584 basehttp 212 "GET /sms_codes/18126106878?image_code=a25k&image_code_id=123 HTTP/1.1" 301 0
INFO 2025-08-15 15:26:22,595 basehttp 212 "GET /sms_codes/18126106878/?image_code=a25k&image_code_id=123 HTTP/1.1" 200 63
INFO 2025-08-15 15:29:25,522 autoreload 265 C:\Users\∞„∞„Àß\Desktop\mall\mall\apps\verifications\views.py changed, reloading.
INFO 2025-08-15 15:29:27,481 autoreload 667 Watching for file changes with StatReloader
INFO 2025-08-15 15:29:49,674 basehttp 212 "GET /image_codes/123/ HTTP/1.1" 200 2042
INFO 2025-08-15 15:29:58,851 basehttp 212 "GET /sms_codes/18126106878?image_code=xwt9&image_code_id=123 HTTP/1.1" 301 0
INFO 2025-08-15 15:29:58,863 basehttp 212 "GET /sms_codes/18126106878/?image_code=xwt9&image_code_id=123 HTTP/1.1" 200 63
INFO 2025-08-15 15:31:27,179 basehttp 212 "GET /sms_codes/18126106878?image_code=xwt9&image_code_id=123 HTTP/1.1" 301 0
INFO 2025-08-15 15:31:27,190 basehttp 212 "GET /sms_codes/18126106878/?image_code=xwt9&image_code_id=123 HTTP/1.1" 200 75
INFO 2025-08-15 15:31:35,389 basehttp 212 "GET /image_codes/123/ HTTP/1.1" 200 1109
INFO 2025-08-15 15:31:44,305 basehttp 212 "GET /sms_codes/18126106878?image_code=zlmt&image_code_id=123 HTTP/1.1" 301 0
ERROR 2025-08-15 15:31:49,059 log 246 Internal Server Error: /sms_codes/18126106878/
Traceback (most recent call last):
  File "C:\Users\∞„∞„Àß\Desktop\mall\.venv\lib\site-packages\kombu\utils\functional.py", line 32, in __call__
    return self.__value__
AttributeError: 'ChannelPromise' object has no attribute '__value__'

During handling of the above exception, another exception occurred:

Traceback (most recent call last):
  File "C:\Users\∞„∞„Àß\Desktop\mall\.venv\lib\site-packages\kombu\transport\virtual\base.py", line 951, in create_channel
    return self._avail_channels.pop()
IndexError: pop from empty list

During handling of the above exception, another exception occurred:

Traceback (most recent call last):
  File "C:\Users\∞„∞„Àß\Desktop\mall\.venv\lib\site-packages\redis\connection.py", line 385, in connect_check_health
    sock = self.retry.call_with_retry(
  File "C:\Users\∞„∞„Àß\Desktop\mall\.venv\lib\site-packages\redis\retry.py", line 87, in call_with_retry
    return do()
  File "C:\Users\∞„∞„Àß\Desktop\mall\.venv\lib\site-packages\redis\connection.py", line 386, in <lambda>
    lambda: self._connect(), lambda error: self.disconnect(error)
  File "C:\Users\∞„∞„Àß\Desktop\mall\.venv\lib\site-packages\redis\connection.py", line 797, in _connect
    raise err
  File "C:\Users\∞„∞„Àß\Desktop\mall\.venv\lib\site-packages\redis\connection.py", line 781, in _connect
    sock.connect(socket_address)
ConnectionRefusedError: [WinError 10061] ”…”⁄ƒø±Íº∆À„ª˙ª˝º´æ‹æ¯£¨Œﬁ∑®¡¨Ω”°£

During handling of the above exception, another exception occurred:

Traceback (most recent call last):
  File "C:\Users\∞„∞„Àß\Desktop\mall\.venv\lib\site-packages\kombu\connection.py", line 472, in _reraise_as_library_errors
    yield
  File "C:\Users\∞„∞„Àß\Desktop\mall\.venv\lib\site-packages\kombu\connection.py", line 459, in _ensure_connection
    return retry_over_time(
  File "C:\Users\∞„∞„Àß\Desktop\mall\.venv\lib\site-packages\kombu\utils\functional.py", line 318, in retry_over_time
    return fun(*args, **kwargs)
  File "C:\Users\∞„∞„Àß\Desktop\mall\.venv\lib\site-packages\kombu\connection.py", line 938, in _connection_factory
    self._connection = self._establish_connection()
  File "C:\Users\∞„∞„Àß\Desktop\mall\.venv\lib\site-packages\kombu\connection.py", line 860, in _establish_connection
    conn = self.transport.establish_connection()
  File "C:\Users\∞„∞„Àß\Desktop\mall\.venv\lib\site-packages\kombu\transport\virtual\base.py", line 975, in establish_connection
    self._avail_channels.append(self.create_channel(self))
  File "C:\Users\∞„∞„Àß\Desktop\mall\.venv\lib\site-packages\kombu\transport\virtual\base.py", line 953, in create_channel
    channel = self.Channel(connection)
  File "C:\Users\∞„∞„Àß\Desktop\mall\.venv\lib\site-packages\kombu\transport\redis.py", line 751, in __init__
    self.client.ping()
  File "C:\Users\∞„∞„Àß\Desktop\mall\.venv\lib\site-packages\redis\commands\core.py", line 1219, in ping
    return self.execute_command("PING", **kwargs)
  File "C:\Users\∞„∞„Àß\Desktop\mall\.venv\lib\site-packages\redis\client.py", line 623, in execute_command
    return self._execute_command(*args, **options)
  File "C:\Users\∞„∞„Àß\Desktop\mall\.venv\lib\site-packages\redis\client.py", line 629, in _execute_command
    conn = self.connection or pool.get_connection()
  File "C:\Users\∞„∞„Àß\Desktop\mall\.venv\lib\site-packages\redis\utils.py", line 191, in wrapper
    return func(*args, **kwargs)
  File "C:\Users\∞„∞„Àß\Desktop\mall\.venv\lib\site-packages\redis\connection.py", line 1530, in get_connection
    connection.connect()
  File "C:\Users\∞„∞„Àß\Desktop\mall\.venv\lib\site-packages\redis\connection.py", line 379, in connect
    self.connect_check_health(check_health=True)
  File "C:\Users\∞„∞„Àß\Desktop\mall\.venv\lib\site-packages\redis\connection.py", line 391, in connect_check_health
    raise ConnectionError(self._error_message(e))
redis.exceptions.ConnectionError: Error 10061 connecting to localhost:6379. ”…”⁄ƒø±Íº∆À„ª˙ª˝º´æ‹æ¯£¨Œﬁ∑®¡¨Ω”°£.

The above exception was the direct cause of the following exception:

Traceback (most recent call last):
  File "C:\Users\∞„∞„Àß\Desktop\mall\.venv\lib\site-packages\django\core\handlers\exception.py", line 55, in inner
    response = get_response(request)
  File "C:\Users\∞„∞„Àß\Desktop\mall\.venv\lib\site-packages\django\core\handlers\base.py", line 197, in _get_response
    response = wrapped_callback(request, *callback_args, **callback_kwargs)
  File "C:\Users\∞„∞„Àß\Desktop\mall\.venv\lib\site-packages\django\views\generic\base.py", line 105, in view
    return self.dispatch(request, *args, **kwargs)
  File "C:\Users\∞„∞„Àß\Desktop\mall\.venv\lib\site-packages\django\views\generic\base.py", line 144, in dispatch
    return handler(request, *args, **kwargs)
  File "C:\Users\∞„∞„Àß\Desktop\mall\mall\apps\verifications\views.py", line 51, in get
    celery_send_sms_code.delay(mobile, sms_code)
  File "C:\Users\∞„∞„Àß\Desktop\mall\.venv\lib\site-packages\celery\app\task.py", line 444, in delay
    return self.apply_async(args, kwargs)
  File "C:\Users\∞„∞„Àß\Desktop\mall\.venv\lib\site-packages\celery\app\task.py", line 601, in apply_async
    return app.send_task(
  File "C:\Users\∞„∞„Àß\Desktop\mall\.venv\lib\site-packages\celery\app\base.py", line 930, in send_task
    amqp.send_task_message(P, name, message, **options)
  File "C:\Users\∞„∞„Àß\Desktop\mall\.venv\lib\site-packages\celery\app\amqp.py", line 523, in send_task_message
    ret = producer.publish(
  File "C:\Users\∞„∞„Àß\Desktop\mall\.venv\lib\site-packages\kombu\messaging.py", line 190, in publish
    return _publish(
  File "C:\Users\∞„∞„Àß\Desktop\mall\.venv\lib\site-packages\kombu\connection.py", line 556, in _ensured
    return fun(*args, **kwargs)
  File "C:\Users\∞„∞„Àß\Desktop\mall\.venv\lib\site-packages\kombu\messaging.py", line 200, in _publish
    channel = self.channel
  File "C:\Users\∞„∞„Àß\Desktop\mall\.venv\lib\site-packages\kombu\messaging.py", line 224, in _get_channel
    channel = self._channel = channel()
  File "C:\Users\∞„∞„Àß\Desktop\mall\.venv\lib\site-packages\kombu\utils\functional.py", line 34, in __call__
    value = self.__value__ = self.__contract__()
  File "C:\Users\∞„∞„Àß\Desktop\mall\.venv\lib\site-packages\kombu\messaging.py", line 240, in <lambda>
    channel = ChannelPromise(lambda: connection.default_channel)
  File "C:\Users\∞„∞„Àß\Desktop\mall\.venv\lib\site-packages\kombu\connection.py", line 957, in default_channel
    self._ensure_connection(**conn_opts)
  File "C:\Users\∞„∞„Àß\Desktop\mall\.venv\lib\site-packages\kombu\connection.py", line 459, in _ensure_connection
    return retry_over_time(
  File "C:\Users\∞„∞„Àß\AppData\Local\Programs\Python\Python39\lib\contextlib.py", line 137, in __exit__
    self.gen.throw(typ, value, traceback)
  File "C:\Users\∞„∞„Àß\Desktop\mall\.venv\lib\site-packages\kombu\connection.py", line 476, in _reraise_as_library_errors
    raise ConnectionError(str(exc)) from exc
kombu.exceptions.OperationalError: Error 10061 connecting to localhost:6379. ”…”⁄ƒø±Íº∆À„ª˙ª˝º´æ‹æ¯£¨Œﬁ∑®¡¨Ω”°£.
ERROR 2025-08-15 15:31:49,108 basehttp 212 "GET /sms_codes/18126106878/?image_code=zlmt&image_code_id=123 HTTP/1.1" 500 268981
INFO 2025-08-15 15:33:25,837 autoreload 265 C:\Users\∞„∞„Àß\Desktop\mall\mall\celery_tasks\config.py changed, reloading.
INFO 2025-08-15 15:33:27,984 autoreload 667 Watching for file changes with StatReloader
INFO 2025-08-15 15:33:51,174 basehttp 212 "GET /image_codes/123/ HTTP/1.1" 200 1348
INFO 2025-08-15 15:34:00,065 basehttp 212 "GET /sms_codes/18126106878?image_code=6hfp&image_code_id=123 HTTP/1.1" 301 0
ERROR 2025-08-15 15:34:01,397 log 246 Internal Server Error: /sms_codes/18126106878/
Traceback (most recent call last):
  File "C:\Users\∞„∞„Àß\Desktop\mall\.venv\lib\site-packages\kombu\utils\functional.py", line 32, in __call__
    return self.__value__
AttributeError: 'ChannelPromise' object has no attribute '__value__'

During handling of the above exception, another exception occurred:

Traceback (most recent call last):
  File "C:\Users\∞„∞„Àß\Desktop\mall\.venv\lib\site-packages\kombu\transport\virtual\base.py", line 951, in create_channel
    return self._avail_channels.pop()
IndexError: pop from empty list

During handling of the above exception, another exception occurred:

Traceback (most recent call last):
  File "C:\Users\∞„∞„Àß\Desktop\mall\.venv\lib\site-packages\kombu\connection.py", line 472, in _reraise_as_library_errors
    yield
  File "C:\Users\∞„∞„Àß\Desktop\mall\.venv\lib\site-packages\kombu\connection.py", line 459, in _ensure_connection
    return retry_over_time(
  File "C:\Users\∞„∞„Àß\Desktop\mall\.venv\lib\site-packages\kombu\utils\functional.py", line 318, in retry_over_time
    return fun(*args, **kwargs)
  File "C:\Users\∞„∞„Àß\Desktop\mall\.venv\lib\site-packages\kombu\connection.py", line 938, in _connection_factory
    self._connection = self._establish_connection()
  File "C:\Users\∞„∞„Àß\Desktop\mall\.venv\lib\site-packages\kombu\connection.py", line 860, in _establish_connection
    conn = self.transport.establish_connection()
  File "C:\Users\∞„∞„Àß\Desktop\mall\.venv\lib\site-packages\kombu\transport\virtual\base.py", line 975, in establish_connection
    self._avail_channels.append(self.create_channel(self))
  File "C:\Users\∞„∞„Àß\Desktop\mall\.venv\lib\site-packages\kombu\transport\virtual\base.py", line 953, in create_channel
    channel = self.Channel(connection)
  File "C:\Users\∞„∞„Àß\Desktop\mall\.venv\lib\site-packages\kombu\transport\redis.py", line 751, in __init__
    self.client.ping()
  File "C:\Users\∞„∞„Àß\Desktop\mall\.venv\lib\site-packages\redis\commands\core.py", line 1219, in ping
    return self.execute_command("PING", **kwargs)
  File "C:\Users\∞„∞„Àß\Desktop\mall\.venv\lib\site-packages\redis\client.py", line 623, in execute_command
    return self._execute_command(*args, **options)
  File "C:\Users\∞„∞„Àß\Desktop\mall\.venv\lib\site-packages\redis\client.py", line 629, in _execute_command
    conn = self.connection or pool.get_connection()
  File "C:\Users\∞„∞„Àß\Desktop\mall\.venv\lib\site-packages\redis\utils.py", line 191, in wrapper
    return func(*args, **kwargs)
  File "C:\Users\∞„∞„Àß\Desktop\mall\.venv\lib\site-packages\redis\connection.py", line 1530, in get_connection
    connection.connect()
  File "C:\Users\∞„∞„Àß\Desktop\mall\.venv\lib\site-packages\redis\connection.py", line 379, in connect
    self.connect_check_health(check_health=True)
  File "C:\Users\∞„∞„Àß\Desktop\mall\.venv\lib\site-packages\redis\connection.py", line 397, in connect_check_health
    self.on_connect_check_health(check_health=check_health)
  File "C:\Users\∞„∞„Àß\Desktop\mall\.venv\lib\site-packages\redis\connection.py", line 510, in on_connect_check_health
    self.send_command(
  File "C:\Users\∞„∞„Àß\Desktop\mall\.venv\lib\site-packages\redis\connection.py", line 608, in send_command
    self.send_packed_command(
  File "C:\Users\∞„∞„Àß\Desktop\mall\.venv\lib\site-packages\redis\connection.py", line 581, in send_packed_command
    self.check_health()
  File "C:\Users\∞„∞„Àß\Desktop\mall\.venv\lib\site-packages\redis\connection.py", line 573, in check_health
    self.retry.call_with_retry(self._send_ping, self._ping_failed)
  File "C:\Users\∞„∞„Àß\Desktop\mall\.venv\lib\site-packages\redis\retry.py", line 92, in call_with_retry
    raise error
  File "C:\Users\∞„∞„Àß\Desktop\mall\.venv\lib\site-packages\redis\retry.py", line 87, in call_with_retry
    return do()
  File "C:\Users\∞„∞„Àß\Desktop\mall\.venv\lib\site-packages\redis\connection.py", line 563, in _send_ping
    if str_if_bytes(self.read_response()) != "PONG":
  File "C:\Users\∞„∞„Àß\Desktop\mall\.venv\lib\site-packages\redis\connection.py", line 644, in read_response
    response = self._parser.read_response(disable_decoding=disable_decoding)
  File "C:\Users\∞„∞„Àß\Desktop\mall\.venv\lib\site-packages\redis\_parsers\resp2.py", line 15, in read_response
    result = self._read_response(disable_decoding=disable_decoding)
  File "C:\Users\∞„∞„Àß\Desktop\mall\.venv\lib\site-packages\redis\_parsers\resp2.py", line 38, in _read_response
    raise error
redis.exceptions.AuthenticationError: Authentication required.

The above exception was the direct cause of the following exception:

Traceback (most recent call last):
  File "C:\Users\∞„∞„Àß\Desktop\mall\.venv\lib\site-packages\django\core\handlers\exception.py", line 55, in inner
    response = get_response(request)
  File "C:\Users\∞„∞„Àß\Desktop\mall\.venv\lib\site-packages\django\core\handlers\base.py", line 197, in _get_response
    response = wrapped_callback(request, *callback_args, **callback_kwargs)
  File "C:\Users\∞„∞„Àß\Desktop\mall\.venv\lib\site-packages\django\views\generic\base.py", line 105, in view
    return self.dispatch(request, *args, **kwargs)
  File "C:\Users\∞„∞„Àß\Desktop\mall\.venv\lib\site-packages\django\views\generic\base.py", line 144, in dispatch
    return handler(request, *args, **kwargs)
  File "C:\Users\∞„∞„Àß\Desktop\mall\mall\apps\verifications\views.py", line 51, in get
    celery_send_sms_code.delay(mobile, sms_code)
  File "C:\Users\∞„∞„Àß\Desktop\mall\.venv\lib\site-packages\celery\app\task.py", line 444, in delay
    return self.apply_async(args, kwargs)
  File "C:\Users\∞„∞„Àß\Desktop\mall\.venv\lib\site-packages\celery\app\task.py", line 601, in apply_async
    return app.send_task(
  File "C:\Users\∞„∞„Àß\Desktop\mall\.venv\lib\site-packages\celery\app\base.py", line 930, in send_task
    amqp.send_task_message(P, name, message, **options)
  File "C:\Users\∞„∞„Àß\Desktop\mall\.venv\lib\site-packages\celery\app\amqp.py", line 523, in send_task_message
    ret = producer.publish(
  File "C:\Users\∞„∞„Àß\Desktop\mall\.venv\lib\site-packages\kombu\messaging.py", line 190, in publish
    return _publish(
  File "C:\Users\∞„∞„Àß\Desktop\mall\.venv\lib\site-packages\kombu\connection.py", line 556, in _ensured
    return fun(*args, **kwargs)
  File "C:\Users\∞„∞„Àß\Desktop\mall\.venv\lib\site-packages\kombu\messaging.py", line 200, in _publish
    channel = self.channel
  File "C:\Users\∞„∞„Àß\Desktop\mall\.venv\lib\site-packages\kombu\messaging.py", line 224, in _get_channel
    channel = self._channel = channel()
  File "C:\Users\∞„∞„Àß\Desktop\mall\.venv\lib\site-packages\kombu\utils\functional.py", line 34, in __call__
    value = self.__value__ = self.__contract__()
  File "C:\Users\∞„∞„Àß\Desktop\mall\.venv\lib\site-packages\kombu\messaging.py", line 240, in <lambda>
    channel = ChannelPromise(lambda: connection.default_channel)
  File "C:\Users\∞„∞„Àß\Desktop\mall\.venv\lib\site-packages\kombu\connection.py", line 957, in default_channel
    self._ensure_connection(**conn_opts)
  File "C:\Users\∞„∞„Àß\Desktop\mall\.venv\lib\site-packages\kombu\connection.py", line 459, in _ensure_connection
    return retry_over_time(
  File "C:\Users\∞„∞„Àß\AppData\Local\Programs\Python\Python39\lib\contextlib.py", line 137, in __exit__
    self.gen.throw(typ, value, traceback)
  File "C:\Users\∞„∞„Àß\Desktop\mall\.venv\lib\site-packages\kombu\connection.py", line 476, in _reraise_as_library_errors
    raise ConnectionError(str(exc)) from exc
kombu.exceptions.OperationalError: Authentication required.
ERROR 2025-08-15 15:34:01,430 basehttp 212 "GET /sms_codes/18126106878/?image_code=6hfp&image_code_id=123 HTTP/1.1" 500 287612
INFO 2025-08-15 15:38:55,179 autoreload 265 C:\Users\∞„∞„Àß\Desktop\mall\mall\celery_tasks\config.py changed, reloading.
INFO 2025-08-15 15:38:57,241 autoreload 667 Watching for file changes with StatReloader
INFO 2025-08-15 15:39:08,509 basehttp 212 "GET /image_codes/123/ HTTP/1.1" 200 1292
INFO 2025-08-15 15:39:16,368 basehttp 212 "GET /sms_codes/18126106878?image_code=feyg&image_code_id=123 HTTP/1.1" 301 0
INFO 2025-08-15 15:39:16,886 basehttp 212 "GET /sms_codes/18126106878/?image_code=feyg&image_code_id=123 HTTP/1.1" 200 27
INFO 2025-08-15 15:48:24,508 autoreload 265 C:\Users\∞„∞„Àß\Desktop\mall\mall\apps\users\views.py changed, reloading.
INFO 2025-08-15 15:48:27,336 autoreload 667 Watching for file changes with StatReloader
INFO 2025-08-15 15:48:59,843 autoreload 265 C:\Users\∞„∞„Àß\Desktop\mall\mall\apps\users\views.py changed, reloading.
INFO 2025-08-15 15:49:01,867 autoreload 667 Watching for file changes with StatReloader
INFO 2025-08-15 15:52:27,204 basehttp 212 "POST /user/login/ HTTP/1.1" 200 27
INFO 2025-08-15 15:52:37,287 basehttp 212 "POST /user/login/ HTTP/1.1" 200 27
INFO 2025-08-15 15:52:42,792 basehttp 212 "POST /user/login/ HTTP/1.1" 200 69
WARNING 2025-08-15 15:53:41,432 log 246 Method Not Allowed (GET): /user/login/
WARNING 2025-08-15 15:53:41,434 basehttp 212 "GET /user/login/ HTTP/1.1" 405 0
INFO 2025-08-15 15:53:46,997 basehttp 212 "POST /user/login/ HTTP/1.1" 200 27
WARNING 2025-08-15 18:30:48,309 log 246 Not Found: /
WARNING 2025-08-15 18:30:48,319 basehttp 212 "GET / HTTP/1.1" 404 2527
WARNING 2025-08-15 18:30:49,119 log 246 Not Found: /favicon.ico
WARNING 2025-08-15 18:30:49,123 basehttp 212 "GET /favicon.ico HTTP/1.1" 404 2578
WARNING 2025-08-15 18:32:33,725 log 246 Not Found: /login/
WARNING 2025-08-15 18:32:33,727 basehttp 212 "OPTIONS /login/ HTTP/1.1" 404 2567
WARNING 2025-08-15 18:32:35,909 log 246 Not Found: /login/
WARNING 2025-08-15 18:32:35,912 basehttp 212 "OPTIONS /login/ HTTP/1.1" 404 2567
WARNING 2025-08-15 18:40:52,185 log 246 Not Found: /
WARNING 2025-08-15 18:40:52,192 basehttp 212 "GET / HTTP/1.1" 404 2527
INFO 2025-08-15 18:42:19,599 autoreload 667 Watching for file changes with StatReloader
WARNING 2025-08-15 18:42:23,726 basehttp 212 "GET /static/images/logo.png HTTP/1.1" 404 1804
WARNING 2025-08-15 18:43:23,690 log 246 Not Found: /register.html
WARNING 2025-08-15 18:43:23,692 basehttp 212 "GET /register.html HTTP/1.1" 404 2584
INFO 2025-08-15 18:46:09,316 autoreload 265 C:\Users\∞„∞„Àß\Desktop\mall\mall\apps\users\views.py changed, reloading.
INFO 2025-08-15 18:46:11,508 autoreload 667 Watching for file changes with StatReloader
INFO 2025-08-15 18:46:22,108 autoreload 265 C:\Users\∞„∞„Àß\Desktop\mall\mall\apps\users\views.py changed, reloading.
INFO 2025-08-15 18:46:23,959 autoreload 667 Watching for file changes with StatReloader
INFO 2025-08-15 18:47:12,624 autoreload 265 C:\Users\∞„∞„Àß\Desktop\mall\mall\apps\users\views.py changed, reloading.
INFO 2025-08-15 18:47:14,229 autoreload 667 Watching for file changes with StatReloader
WARNING 2025-08-15 18:47:55,180 log 246 Not Found: /login.html
WARNING 2025-08-15 18:47:55,182 basehttp 212 "GET /login.html HTTP/1.1" 404 2575
INFO 2025-08-15 18:48:26,198 autoreload 265 C:\Users\∞„∞„Àß\Desktop\mall\mall\mall\urls.py changed, reloading.
INFO 2025-08-15 18:48:28,163 autoreload 667 Watching for file changes with StatReloader
INFO 2025-08-15 18:48:54,003 basehttp 212 "POST /register/ HTTP/1.1" 200 57
ERROR 2025-08-15 18:49:40,900 log 246 Internal Server Error: /login/
Traceback (most recent call last):
  File "C:\Users\∞„∞„Àß\Desktop\mall\.venv\lib\site-packages\django_redis\cache.py", line 29, in _decorator
    return method(self, *args, **kwargs)
  File "C:\Users\∞„∞„Àß\Desktop\mall\.venv\lib\site-packages\django_redis\cache.py", line 138, in has_key
    return self.client.has_key(*args, **kwargs)
  File "C:\Users\∞„∞„Àß\Desktop\mall\.venv\lib\site-packages\django_redis\client\default.py", line 740, in has_key
    raise ConnectionInterrupted(connection=client) from e
django_redis.exceptions.ConnectionInterrupted: Redis ConnectionError: Error 10060 connecting to 192.168.234.128:6379. ”…”⁄¡¨Ω”∑Ω‘⁄“ª∂Œ ±º‰∫Û√ª”–’˝»∑¥∏¥ªÚ¡¨Ω”µƒ÷˜ª˙√ª”–∑¥”¶£¨¡¨Ω”≥¢ ‘ ß∞‹°£.

During handling of the above exception, another exception occurred:

Traceback (most recent call last):
  File "C:\Users\∞„∞„Àß\Desktop\mall\.venv\lib\site-packages\django\core\handlers\exception.py", line 55, in inner
    response = get_response(request)
  File "C:\Users\∞„∞„Àß\Desktop\mall\.venv\lib\site-packages\django\core\handlers\base.py", line 197, in _get_response
    response = wrapped_callback(request, *callback_args, **callback_kwargs)
  File "C:\Users\∞„∞„Àß\Desktop\mall\.venv\lib\site-packages\django\views\generic\base.py", line 105, in view
    return self.dispatch(request, *args, **kwargs)
  File "C:\Users\∞„∞„Àß\Desktop\mall\.venv\lib\site-packages\django\views\generic\base.py", line 144, in dispatch
    return handler(request, *args, **kwargs)
  File "C:\Users\∞„∞„Àß\Desktop\mall\mall\apps\users\views.py", line 75, in post
    login(request, user)
  File "C:\Users\∞„∞„Àß\Desktop\mall\.venv\lib\site-packages\django\contrib\auth\__init__.py", line 118, in login
    request.session.cycle_key()
  File "C:\Users\∞„∞„Àß\Desktop\mall\.venv\lib\site-packages\django\contrib\sessions\backends\base.py", line 304, in cycle_key
    self.create()
  File "C:\Users\∞„∞„Àß\Desktop\mall\.venv\lib\site-packages\django\contrib\sessions\backends\cache.py", line 42, in create
    self._session_key = self._get_new_session_key()
  File "C:\Users\∞„∞„Àß\Desktop\mall\.venv\lib\site-packages\django\contrib\sessions\backends\base.py", line 150, in _get_new_session_key
    if not self.exists(session_key):
  File "C:\Users\∞„∞„Àß\Desktop\mall\.venv\lib\site-packages\django\contrib\sessions\backends\cache.py", line 73, in exists
    bool(session_key) and (self.cache_key_prefix + session_key) in self._cache
  File "C:\Users\∞„∞„Àß\Desktop\mall\.venv\lib\site-packages\django\core\cache\backends\base.py", line 299, in __contains__
    return self.has_key(key)
  File "C:\Users\∞„∞„Àß\Desktop\mall\.venv\lib\site-packages\django_redis\cache.py", line 36, in _decorator
    raise e.__cause__  # noqa: B904
  File "C:\Users\∞„∞„Àß\Desktop\mall\.venv\lib\site-packages\django_redis\client\default.py", line 738, in has_key
    return client.exists(key) == 1
  File "C:\Users\∞„∞„Àß\Desktop\mall\.venv\lib\site-packages\redis\commands\core.py", line 1736, in exists
    return self.execute_command("EXISTS", *names, keys=names)
  File "C:\Users\∞„∞„Àß\Desktop\mall\.venv\lib\site-packages\redis\client.py", line 623, in execute_command
    return self._execute_command(*args, **options)
  File "C:\Users\∞„∞„Àß\Desktop\mall\.venv\lib\site-packages\redis\client.py", line 629, in _execute_command
    conn = self.connection or pool.get_connection()
  File "C:\Users\∞„∞„Àß\Desktop\mall\.venv\lib\site-packages\redis\utils.py", line 191, in wrapper
    return func(*args, **kwargs)
  File "C:\Users\∞„∞„Àß\Desktop\mall\.venv\lib\site-packages\redis\connection.py", line 1530, in get_connection
    connection.connect()
  File "C:\Users\∞„∞„Àß\Desktop\mall\.venv\lib\site-packages\redis\connection.py", line 379, in connect
    self.connect_check_health(check_health=True)
  File "C:\Users\∞„∞„Àß\Desktop\mall\.venv\lib\site-packages\redis\connection.py", line 391, in connect_check_health
    raise ConnectionError(self._error_message(e))
redis.exceptions.ConnectionError: Error 10060 connecting to 192.168.234.128:6379. ”…”⁄¡¨Ω”∑Ω‘⁄“ª∂Œ ±º‰∫Û√ª”–’˝»∑¥∏¥ªÚ¡¨Ω”µƒ÷˜ª˙√ª”–∑¥”¶£¨¡¨Ω”≥¢ ‘ ß∞‹°£.
ERROR 2025-08-15 18:49:40,928 basehttp 212 "POST /login/ HTTP/1.1" 500 152290
ERROR 2025-08-15 18:52:37,202 log 246 Internal Server Error: /login/
Traceback (most recent call last):
  File "C:\Users\∞„∞„Àß\Desktop\mall\.venv\lib\site-packages\django_redis\cache.py", line 29, in _decorator
    return method(self, *args, **kwargs)
  File "C:\Users\∞„∞„Àß\Desktop\mall\.venv\lib\site-packages\django_redis\cache.py", line 138, in has_key
    return self.client.has_key(*args, **kwargs)
  File "C:\Users\∞„∞„Àß\Desktop\mall\.venv\lib\site-packages\django_redis\client\default.py", line 740, in has_key
    raise ConnectionInterrupted(connection=client) from e
django_redis.exceptions.ConnectionInterrupted: Redis ConnectionError: Error 10060 connecting to 192.168.234.128:6379. ”…”⁄¡¨Ω”∑Ω‘⁄“ª∂Œ ±º‰∫Û√ª”–’˝»∑¥∏¥ªÚ¡¨Ω”µƒ÷˜ª˙√ª”–∑¥”¶£¨¡¨Ω”≥¢ ‘ ß∞‹°£.

During handling of the above exception, another exception occurred:

Traceback (most recent call last):
  File "C:\Users\∞„∞„Àß\Desktop\mall\.venv\lib\site-packages\django\core\handlers\exception.py", line 55, in inner
    response = get_response(request)
  File "C:\Users\∞„∞„Àß\Desktop\mall\.venv\lib\site-packages\django\core\handlers\base.py", line 197, in _get_response
    response = wrapped_callback(request, *callback_args, **callback_kwargs)
  File "C:\Users\∞„∞„Àß\Desktop\mall\.venv\lib\site-packages\django\views\generic\base.py", line 105, in view
    return self.dispatch(request, *args, **kwargs)
  File "C:\Users\∞„∞„Àß\Desktop\mall\.venv\lib\site-packages\django\views\generic\base.py", line 144, in dispatch
    return handler(request, *args, **kwargs)
  File "C:\Users\∞„∞„Àß\Desktop\mall\mall\apps\users\views.py", line 75, in post
    login(request, user)
  File "C:\Users\∞„∞„Àß\Desktop\mall\.venv\lib\site-packages\django\contrib\auth\__init__.py", line 118, in login
    request.session.cycle_key()
  File "C:\Users\∞„∞„Àß\Desktop\mall\.venv\lib\site-packages\django\contrib\sessions\backends\base.py", line 304, in cycle_key
    self.create()
  File "C:\Users\∞„∞„Àß\Desktop\mall\.venv\lib\site-packages\django\contrib\sessions\backends\cache.py", line 42, in create
    self._session_key = self._get_new_session_key()
  File "C:\Users\∞„∞„Àß\Desktop\mall\.venv\lib\site-packages\django\contrib\sessions\backends\base.py", line 150, in _get_new_session_key
    if not self.exists(session_key):
  File "C:\Users\∞„∞„Àß\Desktop\mall\.venv\lib\site-packages\django\contrib\sessions\backends\cache.py", line 73, in exists
    bool(session_key) and (self.cache_key_prefix + session_key) in self._cache
  File "C:\Users\∞„∞„Àß\Desktop\mall\.venv\lib\site-packages\django\core\cache\backends\base.py", line 299, in __contains__
    return self.has_key(key)
  File "C:\Users\∞„∞„Àß\Desktop\mall\.venv\lib\site-packages\django_redis\cache.py", line 36, in _decorator
    raise e.__cause__  # noqa: B904
  File "C:\Users\∞„∞„Àß\Desktop\mall\.venv\lib\site-packages\django_redis\client\default.py", line 738, in has_key
    return client.exists(key) == 1
  File "C:\Users\∞„∞„Àß\Desktop\mall\.venv\lib\site-packages\redis\commands\core.py", line 1736, in exists
    return self.execute_command("EXISTS", *names, keys=names)
  File "C:\Users\∞„∞„Àß\Desktop\mall\.venv\lib\site-packages\redis\client.py", line 623, in execute_command
    return self._execute_command(*args, **options)
  File "C:\Users\∞„∞„Àß\Desktop\mall\.venv\lib\site-packages\redis\client.py", line 629, in _execute_command
    conn = self.connection or pool.get_connection()
  File "C:\Users\∞„∞„Àß\Desktop\mall\.venv\lib\site-packages\redis\utils.py", line 191, in wrapper
    return func(*args, **kwargs)
  File "C:\Users\∞„∞„Àß\Desktop\mall\.venv\lib\site-packages\redis\connection.py", line 1530, in get_connection
    connection.connect()
  File "C:\Users\∞„∞„Àß\Desktop\mall\.venv\lib\site-packages\redis\connection.py", line 379, in connect
    self.connect_check_health(check_health=True)
  File "C:\Users\∞„∞„Àß\Desktop\mall\.venv\lib\site-packages\redis\connection.py", line 391, in connect_check_health
    raise ConnectionError(self._error_message(e))
redis.exceptions.ConnectionError: Error 10060 connecting to 192.168.234.128:6379. ”…”⁄¡¨Ω”∑Ω‘⁄“ª∂Œ ±º‰∫Û√ª”–’˝»∑¥∏¥ªÚ¡¨Ω”µƒ÷˜ª˙√ª”–∑¥”¶£¨¡¨Ω”≥¢ ‘ ß∞‹°£.
ERROR 2025-08-15 18:52:37,236 basehttp 212 "POST /login/ HTTP/1.1" 500 151842
INFO 2025-08-15 18:53:22,700 basehttp 212 "POST /login/ HTTP/1.1" 200 27
INFO 2025-08-15 18:58:02,360 autoreload 265 C:\Users\∞„∞„Àß\Desktop\mall\mall\apps\users\views.py changed, reloading.
INFO 2025-08-15 18:58:04,501 autoreload 667 Watching for file changes with StatReloader
INFO 2025-08-15 18:58:50,999 autoreload 265 C:\Users\∞„∞„Àß\Desktop\mall\mall\apps\users\views.py changed, reloading.
INFO 2025-08-15 18:58:53,127 autoreload 667 Watching for file changes with StatReloader
INFO 2025-08-15 19:02:00,835 autoreload 667 Watching for file changes with StatReloader
WARNING 2025-08-15 19:02:06,534 basehttp 212 "GET /static/images/logo.png HTTP/1.1" 404 1804
WARNING 2025-08-15 19:02:39,187 log 246 Not Found: /register.html
WARNING 2025-08-15 19:02:39,189 basehttp 212 "GET /register.html HTTP/1.1" 404 2988
INFO 2025-08-15 19:04:40,441 basehttp 212 "GET /register HTTP/1.1" 301 0
WARNING 2025-08-15 19:04:40,457 log 246 Method Not Allowed (GET): /register/
WARNING 2025-08-15 19:04:40,458 basehttp 212 "GET /register/ HTTP/1.1" 405 0
INFO 2025-08-15 19:26:35,501 autoreload 667 Watching for file changes with StatReloader
INFO 2025-08-15 19:28:03,004 basehttp 212 "GET /center/ HTTP/1.1" 200 27
INFO 2025-08-15 19:29:54,005 basehttp 212 "GET /center/ HTTP/1.1" 200 27
INFO 2025-08-15 19:30:12,513 basehttp 212 "GET /center/ HTTP/1.1" 200 27
INFO 2025-08-15 19:33:35,166 basehttp 212 "GET /center/ HTTP/1.1" 200 27
INFO 2025-08-15 19:33:39,703 basehttp 212 "DELETE /logout HTTP/1.1" 301 0
WARNING 2025-08-15 19:33:39,721 log 246 Method Not Allowed (GET): /logout/
WARNING 2025-08-15 19:33:39,723 basehttp 212 "GET /logout/ HTTP/1.1" 405 0
INFO 2025-08-15 19:34:36,902 basehttp 212 "DELETE /logout HTTP/1.1" 301 0
WARNING 2025-08-15 19:34:36,914 log 246 Method Not Allowed (GET): /logout/
WARNING 2025-08-15 19:34:36,916 basehttp 212 "GET /logout/ HTTP/1.1" 405 0
INFO 2025-08-15 19:35:31,402 basehttp 212 "DELETE /logout HTTP/1.1" 301 0
WARNING 2025-08-15 19:35:31,409 log 246 Method Not Allowed (GET): /logout/
WARNING 2025-08-15 19:35:31,413 basehttp 212 "GET /logout/ HTTP/1.1" 405 0
INFO 2025-08-15 19:38:59,921 autoreload 265 C:\Users\∞„∞„Àß\Desktop\mall\mall\apps\users\views.py changed, reloading.
INFO 2025-08-15 19:39:03,352 autoreload 667 Watching for file changes with StatReloader
INFO 2025-08-15 19:39:08,269 basehttp 212 "DELETE /logout HTTP/1.1" 301 0
INFO 2025-08-15 19:39:08,340 basehttp 212 "GET /logout/ HTTP/1.1" 200 27
INFO 2025-08-15 19:39:15,622 basehttp 212 "GET /center/ HTTP/1.1" 200 45
INFO 2025-08-15 19:39:49,911 autoreload 265 C:\Users\∞„∞„Àß\Desktop\mall\mall\apps\users\views.py changed, reloading.
INFO 2025-08-15 19:39:51,522 autoreload 667 Watching for file changes with StatReloader
INFO 2025-08-17 16:23:50,963 autoreload 667 Watching for file changes with StatReloader
INFO 2025-08-17 16:26:18,196 autoreload 667 Watching for file changes with StatReloader
ERROR 2025-08-17 16:28:02,905 log 246 Internal Server Error: /emails
Traceback (most recent call last):
  File "C:\Users\∞„∞„Àß\Desktop\mall\.venv\lib\site-packages\django\core\handlers\exception.py", line 55, in inner
    response = get_response(request)
  File "C:\Users\∞„∞„Àß\Desktop\mall\.venv\lib\site-packages\django\utils\deprecation.py", line 136, in __call__
    response = self.process_response(request, response)
  File "C:\Users\∞„∞„Àß\Desktop\mall\.venv\lib\site-packages\django\middleware\common.py", line 108, in process_response
    return self.response_redirect_class(self.get_full_path_with_slash(request))
  File "C:\Users\∞„∞„Àß\Desktop\mall\.venv\lib\site-packages\django\middleware\common.py", line 87, in get_full_path_with_slash
    raise RuntimeError(
RuntimeError: You called this URL via PUT, but the URL doesn't end in a slash and you have APPEND_SLASH set. Django can't redirect to the slash URL while maintaining PUT data. Change your form to point to 127.0.0.1:8000/emails/ (note the trailing slash), or set APPEND_SLASH=False in your Django settings.
ERROR 2025-08-17 16:28:02,928 basehttp 212 "PUT /emails HTTP/1.1" 500 70858
INFO 2025-08-17 16:28:59,899 basehttp 212 "PUT /emails/ HTTP/1.1" 200 45
INFO 2025-08-17 16:29:10,191 basehttp 212 "POST /login/ HTTP/1.1" 200 27
ERROR 2025-08-17 16:29:14,701 log 246 Internal Server Error: /emails/
Traceback (most recent call last):
  File "C:\Users\∞„∞„Àß\Desktop\mall\.venv\lib\site-packages\django\core\handlers\exception.py", line 55, in inner
    response = get_response(request)
  File "C:\Users\∞„∞„Àß\Desktop\mall\.venv\lib\site-packages\django\core\handlers\base.py", line 197, in _get_response
    response = wrapped_callback(request, *callback_args, **callback_kwargs)
  File "C:\Users\∞„∞„Àß\Desktop\mall\.venv\lib\site-packages\django\views\generic\base.py", line 105, in view
    return self.dispatch(request, *args, **kwargs)
  File "C:\Users\∞„∞„Àß\Desktop\mall\.venv\lib\site-packages\django\contrib\auth\mixins.py", line 73, in dispatch
    return super().dispatch(request, *args, **kwargs)
  File "C:\Users\∞„∞„Àß\Desktop\mall\.venv\lib\site-packages\django\views\generic\base.py", line 144, in dispatch
    return handler(request, *args, **kwargs)
  File "C:\Users\∞„∞„Àß\Desktop\mall\mall\apps\users\views.py", line 125, in put
    send_mail(
TypeError: send_mail() missing 1 required positional argument: 'from_email'
ERROR 2025-08-17 16:29:14,711 basehttp 212 "PUT /emails/ HTTP/1.1" 500 80441
INFO 2025-08-17 16:30:09,389 autoreload 265 C:\Users\∞„∞„Àß\Desktop\mall\mall\apps\users\views.py changed, reloading.
INFO 2025-08-17 16:30:11,440 autoreload 667 Watching for file changes with StatReloader
INFO 2025-08-17 16:30:22,803 basehttp 212 "PUT /emails/ HTTP/1.1" 200 27
INFO 2025-08-17 16:33:20,314 autoreload 265 C:\Users\∞„∞„Àß\Desktop\mall\mall\mall\settings.py changed, reloading.
INFO 2025-08-17 16:33:22,334 autoreload 667 Watching for file changes with StatReloader
INFO 2025-08-17 16:35:02,252 autoreload 265 C:\Users\∞„∞„Àß\Desktop\mall\mall\mall\settings.py changed, reloading.
INFO 2025-08-17 16:35:04,991 autoreload 667 Watching for file changes with StatReloader
INFO 2025-08-17 16:35:13,188 basehttp 212 "PUT /emails/ HTTP/1.1" 200 27
INFO 2025-08-17 16:35:42,868 autoreload 265 C:\Users\∞„∞„Àß\Desktop\mall\mall\apps\users\views.py changed, reloading.
INFO 2025-08-17 16:35:44,513 autoreload 667 Watching for file changes with StatReloader
ERROR 2025-08-17 16:35:56,602 log 246 Internal Server Error: /emails/
Traceback (most recent call last):
  File "C:\Users\∞„∞„Àß\Desktop\mall\.venv\lib\site-packages\django\core\handlers\exception.py", line 55, in inner
    response = get_response(request)
  File "C:\Users\∞„∞„Àß\Desktop\mall\.venv\lib\site-packages\django\core\handlers\base.py", line 197, in _get_response
    response = wrapped_callback(request, *callback_args, **callback_kwargs)
  File "C:\Users\∞„∞„Àß\Desktop\mall\.venv\lib\site-packages\django\views\generic\base.py", line 105, in view
    return self.dispatch(request, *args, **kwargs)
  File "C:\Users\∞„∞„Àß\Desktop\mall\.venv\lib\site-packages\django\contrib\auth\mixins.py", line 73, in dispatch
    return super().dispatch(request, *args, **kwargs)
  File "C:\Users\∞„∞„Àß\Desktop\mall\.venv\lib\site-packages\django\views\generic\base.py", line 144, in dispatch
    return handler(request, *args, **kwargs)
  File "C:\Users\∞„∞„Àß\Desktop\mall\mall\apps\users\views.py", line 125, in put
    send_mail(
TypeError: send_mail() missing 1 required positional argument: 'from_email'
ERROR 2025-08-17 16:35:56,612 basehttp 212 "PUT /emails/ HTTP/1.1" 500 80424
INFO 2025-08-17 16:39:09,748 autoreload 265 C:\Users\∞„∞„Àß\Desktop\mall\mall\apps\users\views.py changed, reloading.
INFO 2025-08-17 16:39:11,653 autoreload 667 Watching for file changes with StatReloader
ERROR 2025-08-17 16:39:16,091 log 246 Internal Server Error: /emails/
Traceback (most recent call last):
  File "C:\Users\∞„∞„Àß\Desktop\mall\.venv\lib\site-packages\django\core\handlers\exception.py", line 55, in inner
    response = get_response(request)
  File "C:\Users\∞„∞„Àß\Desktop\mall\.venv\lib\site-packages\django\core\handlers\base.py", line 197, in _get_response
    response = wrapped_callback(request, *callback_args, **callback_kwargs)
  File "C:\Users\∞„∞„Àß\Desktop\mall\.venv\lib\site-packages\django\views\generic\base.py", line 105, in view
    return self.dispatch(request, *args, **kwargs)
  File "C:\Users\∞„∞„Àß\Desktop\mall\.venv\lib\site-packages\django\contrib\auth\mixins.py", line 73, in dispatch
    return super().dispatch(request, *args, **kwargs)
  File "C:\Users\∞„∞„Àß\Desktop\mall\.venv\lib\site-packages\django\views\generic\base.py", line 144, in dispatch
    return handler(request, *args, **kwargs)
  File "C:\Users\∞„∞„Àß\Desktop\mall\mall\apps\users\views.py", line 125, in put
    email = EmailMessage(
TypeError: __init__() got an unexpected keyword argument 'message'
ERROR 2025-08-17 16:39:16,100 basehttp 212 "PUT /emails/ HTTP/1.1" 500 80334
INFO 2025-08-17 16:39:50,930 autoreload 265 C:\Users\∞„∞„Àß\Desktop\mall\mall\apps\users\views.py changed, reloading.
INFO 2025-08-17 16:39:52,507 autoreload 667 Watching for file changes with StatReloader
INFO 2025-08-17 16:39:57,625 basehttp 212 "PUT /emails/ HTTP/1.1" 200 27
INFO 2025-08-17 16:41:14,513 autoreload 265 C:\Users\∞„∞„Àß\Desktop\mall\mall\mall\settings.py changed, reloading.
INFO 2025-08-17 16:41:16,639 autoreload 667 Watching for file changes with StatReloader
INFO 2025-08-17 16:41:22,127 basehttp 212 "PUT /emails/ HTTP/1.1" 200 27
INFO 2025-08-17 16:42:12,306 autoreload 265 C:\Users\∞„∞„Àß\Desktop\mall\mall\mall\settings.py changed, reloading.
INFO 2025-08-17 16:42:13,867 autoreload 667 Watching for file changes with StatReloader
INFO 2025-08-17 16:42:18,110 basehttp 212 "PUT /emails/ HTTP/1.1" 200 27
INFO 2025-08-17 16:45:07,260 basehttp 212 "PUT /emails/ HTTP/1.1" 200 27
INFO 2025-08-17 16:56:54,668 autoreload 265 C:\Users\∞„∞„Àß\Desktop\mall\mall\apps\users\views.py changed, reloading.
INFO 2025-08-17 16:56:57,471 autoreload 667 Watching for file changes with StatReloader
INFO 2025-08-17 17:05:07,453 autoreload 265 C:\Users\∞„∞„Àß\Desktop\mall\mall\apps\users\views.py changed, reloading.
INFO 2025-08-17 17:05:09,982 autoreload 667 Watching for file changes with StatReloader
INFO 2025-08-17 17:12:34,810 autoreload 265 C:\Users\∞„∞„Àß\Desktop\mall\mall\apps\users\utils.py changed, reloading.
INFO 2025-08-17 17:12:37,242 autoreload 667 Watching for file changes with StatReloader
INFO 2025-08-17 17:13:19,033 autoreload 265 C:\Users\∞„∞„Àß\Desktop\mall\mall\apps\users\utils.py changed, reloading.
INFO 2025-08-17 17:13:20,608 autoreload 667 Watching for file changes with StatReloader
INFO 2025-08-17 17:16:47,673 autoreload 265 C:\Users\∞„∞„Àß\Desktop\mall\mall\apps\users\utils.py changed, reloading.
INFO 2025-08-17 17:16:50,175 autoreload 667 Watching for file changes with StatReloader
INFO 2025-08-17 17:17:31,085 autoreload 265 C:\Users\∞„∞„Àß\Desktop\mall\mall\apps\users\views.py changed, reloading.
INFO 2025-08-17 17:17:32,855 autoreload 667 Watching for file changes with StatReloader
INFO 2025-08-17 17:17:36,585 basehttp 212 "PUT /emails/ HTTP/1.1" 200 45
INFO 2025-08-17 17:17:43,222 basehttp 212 "POST /login/ HTTP/1.1" 200 27
ERROR 2025-08-17 17:17:47,449 log 246 Internal Server Error: /emails/
Traceback (most recent call last):
  File "C:\Users\∞„∞„Àß\Desktop\mall\.venv\lib\site-packages\django\core\handlers\exception.py", line 55, in inner
    response = get_response(request)
  File "C:\Users\∞„∞„Àß\Desktop\mall\.venv\lib\site-packages\django\core\handlers\base.py", line 197, in _get_response
    response = wrapped_callback(request, *callback_args, **callback_kwargs)
  File "C:\Users\∞„∞„Àß\Desktop\mall\.venv\lib\site-packages\django\views\generic\base.py", line 105, in view
    return self.dispatch(request, *args, **kwargs)
  File "C:\Users\∞„∞„Àß\Desktop\mall\.venv\lib\site-packages\django\contrib\auth\mixins.py", line 73, in dispatch
    return super().dispatch(request, *args, **kwargs)
  File "C:\Users\∞„∞„Àß\Desktop\mall\.venv\lib\site-packages\django\views\generic\base.py", line 144, in dispatch
    return handler(request, *args, **kwargs)
  File "C:\Users\∞„∞„Àß\Desktop\mall\mall\apps\users\views.py", line 126, in put
    token=generic_email_verify_token(request.user.id)
  File "C:\Users\∞„∞„Àß\Desktop\mall\mall\apps\users\utils.py", line 6, in generic_email_verify_token
    data = serializer.dumps({'user_id': user_id}, expires_in=1800)
TypeError: dumps() got an unexpected keyword argument 'expires_in'
ERROR 2025-08-17 17:17:47,459 basehttp 212 "PUT /emails/ HTTP/1.1" 500 83851
INFO 2025-08-17 19:31:09,769 autoreload 667 Watching for file changes with StatReloader
ERROR 2025-08-17 19:31:17,274 log 246 Internal Server Error: /emails/
Traceback (most recent call last):
  File "C:\Users\∞„∞„Àß\Desktop\mall\.venv\lib\site-packages\django\core\handlers\exception.py", line 55, in inner
    response = get_response(request)
  File "C:\Users\∞„∞„Àß\Desktop\mall\.venv\lib\site-packages\django\core\handlers\base.py", line 197, in _get_response
    response = wrapped_callback(request, *callback_args, **callback_kwargs)
  File "C:\Users\∞„∞„Àß\Desktop\mall\.venv\lib\site-packages\django\views\generic\base.py", line 105, in view
    return self.dispatch(request, *args, **kwargs)
  File "C:\Users\∞„∞„Àß\Desktop\mall\.venv\lib\site-packages\django\contrib\auth\mixins.py", line 73, in dispatch
    return super().dispatch(request, *args, **kwargs)
  File "C:\Users\∞„∞„Àß\Desktop\mall\.venv\lib\site-packages\django\views\generic\base.py", line 144, in dispatch
    return handler(request, *args, **kwargs)
  File "C:\Users\∞„∞„Àß\Desktop\mall\mall\apps\users\views.py", line 128, in put
    email = EmailMessage(
TypeError: __init__() got an unexpected keyword argument 'html'
ERROR 2025-08-17 19:31:17,292 basehttp 212 "PUT /emails/ HTTP/1.1" 500 80939
INFO 2025-08-17 19:34:31,637 autoreload 265 C:\Users\∞„∞„Àß\Desktop\mall\mall\apps\users\views.py changed, reloading.
INFO 2025-08-17 19:34:33,715 autoreload 667 Watching for file changes with StatReloader
INFO 2025-08-17 19:34:39,890 basehttp 212 "PUT /emails/ HTTP/1.1" 200 27
INFO 2025-08-17 19:44:25,072 autoreload 265 C:\Users\∞„∞„Àß\Desktop\mall\mall\apps\users\views.py changed, reloading.
INFO 2025-08-17 19:44:27,124 autoreload 667 Watching for file changes with StatReloader
INFO 2025-08-17 19:44:29,981 basehttp 212 "PUT /emails/ HTTP/1.1" 200 27
INFO 2025-08-17 19:47:29,019 autoreload 265 C:\Users\∞„∞„Àß\Desktop\mall\mall\apps\users\views.py changed, reloading.
INFO 2025-08-17 19:47:31,807 autoreload 667 Watching for file changes with StatReloader
INFO 2025-08-17 19:48:28,434 autoreload 265 C:\Users\∞„∞„Àß\Desktop\mall\mall\apps\users\views.py changed, reloading.
INFO 2025-08-17 19:48:30,089 autoreload 667 Watching for file changes with StatReloader
ERROR 2025-08-17 19:48:35,398 log 246 Internal Server Error: /emails/
Traceback (most recent call last):
  File "C:\Users\∞„∞„Àß\Desktop\mall\.venv\lib\site-packages\django\core\handlers\exception.py", line 55, in inner
    response = get_response(request)
  File "C:\Users\∞„∞„Àß\Desktop\mall\.venv\lib\site-packages\django\core\handlers\base.py", line 197, in _get_response
    response = wrapped_callback(request, *callback_args, **callback_kwargs)
  File "C:\Users\∞„∞„Àß\Desktop\mall\.venv\lib\site-packages\django\views\generic\base.py", line 105, in view
    return self.dispatch(request, *args, **kwargs)
  File "C:\Users\∞„∞„Àß\Desktop\mall\.venv\lib\site-packages\django\contrib\auth\mixins.py", line 73, in dispatch
    return super().dispatch(request, *args, **kwargs)
  File "C:\Users\∞„∞„Àß\Desktop\mall\.venv\lib\site-packages\django\views\generic\base.py", line 144, in dispatch
    return handler(request, *args, **kwargs)
  File "C:\Users\∞„∞„Àß\Desktop\mall\mall\apps\users\views.py", line 130, in put
    send_mail(
TypeError: send_mail() missing 1 required positional argument: 'message'
ERROR 2025-08-17 19:48:35,408 basehttp 212 "PUT /emails/ HTTP/1.1" 500 81637
INFO 2025-08-17 19:50:00,257 autoreload 265 C:\Users\∞„∞„Àß\Desktop\mall\mall\apps\users\views.py changed, reloading.
INFO 2025-08-17 19:50:02,586 autoreload 667 Watching for file changes with StatReloader
INFO 2025-08-17 19:50:05,650 basehttp 212 "PUT /emails/ HTTP/1.1" 200 27
INFO 2025-08-17 19:52:09,311 autoreload 265 C:\Users\∞„∞„Àß\Desktop\mall\mall\apps\users\views.py changed, reloading.
INFO 2025-08-17 19:52:11,393 autoreload 667 Watching for file changes with StatReloader
INFO 2025-08-17 19:52:22,435 autoreload 265 C:\Users\∞„∞„Àß\Desktop\mall\mall\apps\users\views.py changed, reloading.
INFO 2025-08-17 19:52:23,868 autoreload 667 Watching for file changes with StatReloader
INFO 2025-08-17 19:52:28,849 basehttp 212 "PUT /emails/ HTTP/1.1" 200 27
INFO 2025-08-17 19:53:23,784 autoreload 265 C:\Users\∞„∞„Àß\Desktop\mall\mall\apps\users\views.py changed, reloading.
INFO 2025-08-17 19:53:25,728 autoreload 667 Watching for file changes with StatReloader
INFO 2025-08-17 19:53:30,311 basehttp 212 "PUT /emails/ HTTP/1.1" 200 27
